2022-02-12 16:21:32 [ERROR] : 获取 [360 网络安全响应中心] 威胁情报异常
Traceback (most recent call last):
  File "/Users/skill/Desktop/threat-broadcast/src/crawler/_base_crawler.py", line 62, in cves
    new_cves = self.get_cves()
  File "/Users/skill/Desktop/threat-broadcast/src/crawler/cert360.py", line 55, in get_cves
    exit()
  File "/Applications/Xcode.app/Contents/Developer/Library/Frameworks/Python3.framework/Versions/3.8/lib/python3.8/_sitebuiltins.py", line 26, in __call__
    raise SystemExit(code)
SystemExit: None
2022-02-12 16:21:32 [ERROR] : Traceback (most recent call last):
  File "/Users/skill/Desktop/threat-broadcast/src/crawler/_base_crawler.py", line 62, in cves
    new_cves = self.get_cves()
  File "/Users/skill/Desktop/threat-broadcast/src/crawler/cert360.py", line 55, in get_cves
    exit()
  File "/Applications/Xcode.app/Contents/Developer/Library/Frameworks/Python3.framework/Versions/3.8/lib/python3.8/_sitebuiltins.py", line 26, in __call__
    raise SystemExit(code)
SystemExit: None
Traceback (most recent call last):
  File "/Users/skill/Desktop/threat-broadcast/src/crawler/_base_crawler.py", line 62, in cves
    new_cves = self.get_cves()
  File "/Users/skill/Desktop/threat-broadcast/src/crawler/cert360.py", line 55, in get_cves
    exit()
  File "/Applications/Xcode.app/Contents/Developer/Library/Frameworks/Python3.framework/Versions/3.8/lib/python3.8/_sitebuiltins.py", line 26, in __call__
    raise SystemExit(code)
SystemExit: None
2022-02-12 16:26:15 [ERROR] : 获取 [Tenable (Nessus)] 威胁情报异常
Traceback (most recent call last):
  File "/Users/skill/Desktop/threat-broadcast/src/crawler/_base_crawler.py", line 62, in cves
    new_cves = self.get_cves()
  File "/Users/skill/Desktop/threat-broadcast/src/crawler/tenable.py", line 42, in get_cves
    response = requests.get(
  File "/Users/skill/Desktop/threat-broadcast/venv/lib/python3.8/site-packages/requests/api.py", line 75, in get
    return request('get', url, params=params, **kwargs)
  File "/Users/skill/Desktop/threat-broadcast/venv/lib/python3.8/site-packages/requests/api.py", line 60, in request
    return session.request(method=method, url=url, **kwargs)
  File "/Users/skill/Desktop/threat-broadcast/venv/lib/python3.8/site-packages/requests/sessions.py", line 533, in request
    resp = self.send(prep, **send_kwargs)
  File "/Users/skill/Desktop/threat-broadcast/venv/lib/python3.8/site-packages/requests/sessions.py", line 646, in send
    r = adapter.send(request, **kwargs)
  File "/Users/skill/Desktop/threat-broadcast/venv/lib/python3.8/site-packages/requests/adapters.py", line 439, in send
    resp = conn.urlopen(
  File "/Users/skill/Desktop/threat-broadcast/venv/lib/python3.8/site-packages/urllib3/connectionpool.py", line 670, in urlopen
    httplib_response = self._make_request(
  File "/Users/skill/Desktop/threat-broadcast/venv/lib/python3.8/site-packages/urllib3/connectionpool.py", line 426, in _make_request
    six.raise_from(e, None)
  File "<string>", line 3, in raise_from
  File "/Users/skill/Desktop/threat-broadcast/venv/lib/python3.8/site-packages/urllib3/connectionpool.py", line 421, in _make_request
    httplib_response = conn.getresponse()
  File "/Applications/Xcode.app/Contents/Developer/Library/Frameworks/Python3.framework/Versions/3.8/lib/python3.8/http/client.py", line 1344, in getresponse
    response.begin()
  File "/Applications/Xcode.app/Contents/Developer/Library/Frameworks/Python3.framework/Versions/3.8/lib/python3.8/http/client.py", line 307, in begin
    version, status, reason = self._read_status()
  File "/Applications/Xcode.app/Contents/Developer/Library/Frameworks/Python3.framework/Versions/3.8/lib/python3.8/http/client.py", line 268, in _read_status
    line = str(self.fp.readline(_MAXLINE + 1), "iso-8859-1")
  File "/Applications/Xcode.app/Contents/Developer/Library/Frameworks/Python3.framework/Versions/3.8/lib/python3.8/socket.py", line 669, in readinto
    return self._sock.recv_into(b)
  File "/Applications/Xcode.app/Contents/Developer/Library/Frameworks/Python3.framework/Versions/3.8/lib/python3.8/ssl.py", line 1241, in recv_into
    return self.read(nbytes, buffer)
  File "/Applications/Xcode.app/Contents/Developer/Library/Frameworks/Python3.framework/Versions/3.8/lib/python3.8/ssl.py", line 1099, in read
    return self._sslobj.read(len, buffer)
KeyboardInterrupt
2022-02-12 16:26:15 [ERROR] : Traceback (most recent call last):
  File "/Users/skill/Desktop/threat-broadcast/src/crawler/_base_crawler.py", line 62, in cves
    new_cves = self.get_cves()
  File "/Users/skill/Desktop/threat-broadcast/src/crawler/tenable.py", line 42, in get_cves
    response = requests.get(
  File "/Users/skill/Desktop/threat-broadcast/venv/lib/python3.8/site-packages/requests/api.py", line 75, in get
    return request('get', url, params=params, **kwargs)
  File "/Users/skill/Desktop/threat-broadcast/venv/lib/python3.8/site-packages/requests/api.py", line 60, in request
    return session.request(method=method, url=url, **kwargs)
  File "/Users/skill/Desktop/threat-broadcast/venv/lib/python3.8/site-packages/requests/sessions.py", line 533, in request
    resp = self.send(prep, **send_kwargs)
  File "/Users/skill/Desktop/threat-broadcast/venv/lib/python3.8/site-packages/requests/sessions.py", line 646, in send
    r = adapter.send(request, **kwargs)
  File "/Users/skill/Desktop/threat-broadcast/venv/lib/python3.8/site-packages/requests/adapters.py", line 439, in send
    resp = conn.urlopen(
  File "/Users/skill/Desktop/threat-broadcast/venv/lib/python3.8/site-packages/urllib3/connectionpool.py", line 670, in urlopen
    httplib_response = self._make_request(
  File "/Users/skill/Desktop/threat-broadcast/venv/lib/python3.8/site-packages/urllib3/connectionpool.py", line 426, in _make_request
    six.raise_from(e, None)
  File "<string>", line 3, in raise_from
  File "/Users/skill/Desktop/threat-broadcast/venv/lib/python3.8/site-packages/urllib3/connectionpool.py", line 421, in _make_request
    httplib_response = conn.getresponse()
  File "/Applications/Xcode.app/Contents/Developer/Library/Frameworks/Python3.framework/Versions/3.8/lib/python3.8/http/client.py", line 1344, in getresponse
    response.begin()
  File "/Applications/Xcode.app/Contents/Developer/Library/Frameworks/Python3.framework/Versions/3.8/lib/python3.8/http/client.py", line 307, in begin
    version, status, reason = self._read_status()
  File "/Applications/Xcode.app/Contents/Developer/Library/Frameworks/Python3.framework/Versions/3.8/lib/python3.8/http/client.py", line 268, in _read_status
    line = str(self.fp.readline(_MAXLINE + 1), "iso-8859-1")
  File "/Applications/Xcode.app/Contents/Developer/Library/Frameworks/Python3.framework/Versions/3.8/lib/python3.8/socket.py", line 669, in readinto
    return self._sock.recv_into(b)
  File "/Applications/Xcode.app/Contents/Developer/Library/Frameworks/Python3.framework/Versions/3.8/lib/python3.8/ssl.py", line 1241, in recv_into
    return self.read(nbytes, buffer)
  File "/Applications/Xcode.app/Contents/Developer/Library/Frameworks/Python3.framework/Versions/3.8/lib/python3.8/ssl.py", line 1099, in read
    return self._sslobj.read(len, buffer)
KeyboardInterrupt
Traceback (most recent call last):
  File "/Users/skill/Desktop/threat-broadcast/src/crawler/_base_crawler.py", line 62, in cves
    new_cves = self.get_cves()
  File "/Users/skill/Desktop/threat-broadcast/src/crawler/tenable.py", line 42, in get_cves
    response = requests.get(
  File "/Users/skill/Desktop/threat-broadcast/venv/lib/python3.8/site-packages/requests/api.py", line 75, in get
    return request('get', url, params=params, **kwargs)
  File "/Users/skill/Desktop/threat-broadcast/venv/lib/python3.8/site-packages/requests/api.py", line 60, in request
    return session.request(method=method, url=url, **kwargs)
  File "/Users/skill/Desktop/threat-broadcast/venv/lib/python3.8/site-packages/requests/sessions.py", line 533, in request
    resp = self.send(prep, **send_kwargs)
  File "/Users/skill/Desktop/threat-broadcast/venv/lib/python3.8/site-packages/requests/sessions.py", line 646, in send
    r = adapter.send(request, **kwargs)
  File "/Users/skill/Desktop/threat-broadcast/venv/lib/python3.8/site-packages/requests/adapters.py", line 439, in send
    resp = conn.urlopen(
  File "/Users/skill/Desktop/threat-broadcast/venv/lib/python3.8/site-packages/urllib3/connectionpool.py", line 670, in urlopen
    httplib_response = self._make_request(
  File "/Users/skill/Desktop/threat-broadcast/venv/lib/python3.8/site-packages/urllib3/connectionpool.py", line 426, in _make_request
    six.raise_from(e, None)
  File "<string>", line 3, in raise_from
  File "/Users/skill/Desktop/threat-broadcast/venv/lib/python3.8/site-packages/urllib3/connectionpool.py", line 421, in _make_request
    httplib_response = conn.getresponse()
  File "/Applications/Xcode.app/Contents/Developer/Library/Frameworks/Python3.framework/Versions/3.8/lib/python3.8/http/client.py", line 1344, in getresponse
    response.begin()
  File "/Applications/Xcode.app/Contents/Developer/Library/Frameworks/Python3.framework/Versions/3.8/lib/python3.8/http/client.py", line 307, in begin
    version, status, reason = self._read_status()
  File "/Applications/Xcode.app/Contents/Developer/Library/Frameworks/Python3.framework/Versions/3.8/lib/python3.8/http/client.py", line 268, in _read_status
    line = str(self.fp.readline(_MAXLINE + 1), "iso-8859-1")
  File "/Applications/Xcode.app/Contents/Developer/Library/Frameworks/Python3.framework/Versions/3.8/lib/python3.8/socket.py", line 669, in readinto
    return self._sock.recv_into(b)
  File "/Applications/Xcode.app/Contents/Developer/Library/Frameworks/Python3.framework/Versions/3.8/lib/python3.8/ssl.py", line 1241, in recv_into
    return self.read(nbytes, buffer)
  File "/Applications/Xcode.app/Contents/Developer/Library/Frameworks/Python3.framework/Versions/3.8/lib/python3.8/ssl.py", line 1099, in read
    return self._sslobj.read(len, buffer)
KeyboardInterrupt
2022-02-12 16:33:31 [ERROR] : [邮件] 推送威胁情报失败
Traceback (most recent call last):
  File "/Users/skill/Desktop/threat-broadcast/src/notice/mail.py", line 46, in to_mail
    smtpObj.login(sender, password)
  File "/Applications/Xcode.app/Contents/Developer/Library/Frameworks/Python3.framework/Versions/3.8/lib/python3.8/smtplib.py", line 732, in login
    (code, resp) = self.auth(
  File "/Applications/Xcode.app/Contents/Developer/Library/Frameworks/Python3.framework/Versions/3.8/lib/python3.8/smtplib.py", line 645, in auth
    authobject(challenge).encode('ascii'), eol='')
AttributeError: 'NoneType' object has no attribute 'encode'
2022-02-12 16:33:31 [ERROR] : Traceback (most recent call last):
  File "/Users/skill/Desktop/threat-broadcast/src/notice/mail.py", line 46, in to_mail
    smtpObj.login(sender, password)
  File "/Applications/Xcode.app/Contents/Developer/Library/Frameworks/Python3.framework/Versions/3.8/lib/python3.8/smtplib.py", line 732, in login
    (code, resp) = self.auth(
  File "/Applications/Xcode.app/Contents/Developer/Library/Frameworks/Python3.framework/Versions/3.8/lib/python3.8/smtplib.py", line 645, in auth
    authobject(challenge).encode('ascii'), eol='')
AttributeError: 'NoneType' object has no attribute 'encode'
Traceback (most recent call last):
  File "/Users/skill/Desktop/threat-broadcast/src/notice/mail.py", line 46, in to_mail
    smtpObj.login(sender, password)
  File "/Applications/Xcode.app/Contents/Developer/Library/Frameworks/Python3.framework/Versions/3.8/lib/python3.8/smtplib.py", line 732, in login
    (code, resp) = self.auth(
  File "/Applications/Xcode.app/Contents/Developer/Library/Frameworks/Python3.framework/Versions/3.8/lib/python3.8/smtplib.py", line 645, in auth
    authobject(challenge).encode('ascii'), eol='')
AttributeError: 'NoneType' object has no attribute 'encode'
2022-02-12 16:34:53 [ERROR] : [邮件] 推送威胁情报失败
Traceback (most recent call last):
  File "/Users/skill/Desktop/threat-broadcast/src/notice/mail.py", line 46, in to_mail
    smtpObj.login(sender, password)
  File "/Applications/Xcode.app/Contents/Developer/Library/Frameworks/Python3.framework/Versions/3.8/lib/python3.8/smtplib.py", line 732, in login
    (code, resp) = self.auth(
  File "/Applications/Xcode.app/Contents/Developer/Library/Frameworks/Python3.framework/Versions/3.8/lib/python3.8/smtplib.py", line 645, in auth
    authobject(challenge).encode('ascii'), eol='')
AttributeError: 'NoneType' object has no attribute 'encode'
2022-02-12 16:34:53 [ERROR] : Traceback (most recent call last):
  File "/Users/skill/Desktop/threat-broadcast/src/notice/mail.py", line 46, in to_mail
    smtpObj.login(sender, password)
  File "/Applications/Xcode.app/Contents/Developer/Library/Frameworks/Python3.framework/Versions/3.8/lib/python3.8/smtplib.py", line 732, in login
    (code, resp) = self.auth(
  File "/Applications/Xcode.app/Contents/Developer/Library/Frameworks/Python3.framework/Versions/3.8/lib/python3.8/smtplib.py", line 645, in auth
    authobject(challenge).encode('ascii'), eol='')
AttributeError: 'NoneType' object has no attribute 'encode'
Traceback (most recent call last):
  File "/Users/skill/Desktop/threat-broadcast/src/notice/mail.py", line 46, in to_mail
    smtpObj.login(sender, password)
  File "/Applications/Xcode.app/Contents/Developer/Library/Frameworks/Python3.framework/Versions/3.8/lib/python3.8/smtplib.py", line 732, in login
    (code, resp) = self.auth(
  File "/Applications/Xcode.app/Contents/Developer/Library/Frameworks/Python3.framework/Versions/3.8/lib/python3.8/smtplib.py", line 645, in auth
    authobject(challenge).encode('ascii'), eol='')
AttributeError: 'NoneType' object has no attribute 'encode'
2022-02-12 16:36:44 [ERROR] : [邮件] 推送威胁情报失败
Traceback (most recent call last):
  File "/Users/skill/Desktop/threat-broadcast/src/notice/mail.py", line 46, in to_mail
    smtpObj.login(sender, password)
  File "/Applications/Xcode.app/Contents/Developer/Library/Frameworks/Python3.framework/Versions/3.8/lib/python3.8/smtplib.py", line 732, in login
    (code, resp) = self.auth(
  File "/Applications/Xcode.app/Contents/Developer/Library/Frameworks/Python3.framework/Versions/3.8/lib/python3.8/smtplib.py", line 645, in auth
    authobject(challenge).encode('ascii'), eol='')
AttributeError: 'NoneType' object has no attribute 'encode'
2022-02-12 16:36:44 [ERROR] : Traceback (most recent call last):
  File "/Users/skill/Desktop/threat-broadcast/src/notice/mail.py", line 46, in to_mail
    smtpObj.login(sender, password)
  File "/Applications/Xcode.app/Contents/Developer/Library/Frameworks/Python3.framework/Versions/3.8/lib/python3.8/smtplib.py", line 732, in login
    (code, resp) = self.auth(
  File "/Applications/Xcode.app/Contents/Developer/Library/Frameworks/Python3.framework/Versions/3.8/lib/python3.8/smtplib.py", line 645, in auth
    authobject(challenge).encode('ascii'), eol='')
AttributeError: 'NoneType' object has no attribute 'encode'
Traceback (most recent call last):
  File "/Users/skill/Desktop/threat-broadcast/src/notice/mail.py", line 46, in to_mail
    smtpObj.login(sender, password)
  File "/Applications/Xcode.app/Contents/Developer/Library/Frameworks/Python3.framework/Versions/3.8/lib/python3.8/smtplib.py", line 732, in login
    (code, resp) = self.auth(
  File "/Applications/Xcode.app/Contents/Developer/Library/Frameworks/Python3.framework/Versions/3.8/lib/python3.8/smtplib.py", line 645, in auth
    authobject(challenge).encode('ascii'), eol='')
AttributeError: 'NoneType' object has no attribute 'encode'
2022-02-12 16:38:11 [ERROR] : [邮件] 推送威胁情报失败
Traceback (most recent call last):
  File "/Users/skill/Desktop/threat-broadcast/src/notice/mail.py", line 46, in to_mail
    smtpObj.login(sender, password)
  File "/Applications/Xcode.app/Contents/Developer/Library/Frameworks/Python3.framework/Versions/3.8/lib/python3.8/smtplib.py", line 732, in login
    (code, resp) = self.auth(
  File "/Applications/Xcode.app/Contents/Developer/Library/Frameworks/Python3.framework/Versions/3.8/lib/python3.8/smtplib.py", line 645, in auth
    authobject(challenge).encode('ascii'), eol='')
AttributeError: 'NoneType' object has no attribute 'encode'
2022-02-12 16:38:11 [ERROR] : Traceback (most recent call last):
  File "/Users/skill/Desktop/threat-broadcast/src/notice/mail.py", line 46, in to_mail
    smtpObj.login(sender, password)
  File "/Applications/Xcode.app/Contents/Developer/Library/Frameworks/Python3.framework/Versions/3.8/lib/python3.8/smtplib.py", line 732, in login
    (code, resp) = self.auth(
  File "/Applications/Xcode.app/Contents/Developer/Library/Frameworks/Python3.framework/Versions/3.8/lib/python3.8/smtplib.py", line 645, in auth
    authobject(challenge).encode('ascii'), eol='')
AttributeError: 'NoneType' object has no attribute 'encode'
Traceback (most recent call last):
  File "/Users/skill/Desktop/threat-broadcast/src/notice/mail.py", line 46, in to_mail
    smtpObj.login(sender, password)
  File "/Applications/Xcode.app/Contents/Developer/Library/Frameworks/Python3.framework/Versions/3.8/lib/python3.8/smtplib.py", line 732, in login
    (code, resp) = self.auth(
  File "/Applications/Xcode.app/Contents/Developer/Library/Frameworks/Python3.framework/Versions/3.8/lib/python3.8/smtplib.py", line 645, in auth
    authobject(challenge).encode('ascii'), eol='')
AttributeError: 'NoneType' object has no attribute 'encode'
2022-02-12 16:40:17 [ERROR] : [邮件] 推送威胁情报失败
Traceback (most recent call last):
  File "/Users/skill/Desktop/threat-broadcast/src/notice/mail.py", line 46, in to_mail
    smtpObj.login(sender, password)
  File "/Applications/Xcode.app/Contents/Developer/Library/Frameworks/Python3.framework/Versions/3.8/lib/python3.8/smtplib.py", line 732, in login
    (code, resp) = self.auth(
  File "/Applications/Xcode.app/Contents/Developer/Library/Frameworks/Python3.framework/Versions/3.8/lib/python3.8/smtplib.py", line 645, in auth
    authobject(challenge).encode('ascii'), eol='')
AttributeError: 'NoneType' object has no attribute 'encode'
2022-02-12 16:40:17 [ERROR] : Traceback (most recent call last):
  File "/Users/skill/Desktop/threat-broadcast/src/notice/mail.py", line 46, in to_mail
    smtpObj.login(sender, password)
  File "/Applications/Xcode.app/Contents/Developer/Library/Frameworks/Python3.framework/Versions/3.8/lib/python3.8/smtplib.py", line 732, in login
    (code, resp) = self.auth(
  File "/Applications/Xcode.app/Contents/Developer/Library/Frameworks/Python3.framework/Versions/3.8/lib/python3.8/smtplib.py", line 645, in auth
    authobject(challenge).encode('ascii'), eol='')
AttributeError: 'NoneType' object has no attribute 'encode'
Traceback (most recent call last):
  File "/Users/skill/Desktop/threat-broadcast/src/notice/mail.py", line 46, in to_mail
    smtpObj.login(sender, password)
  File "/Applications/Xcode.app/Contents/Developer/Library/Frameworks/Python3.framework/Versions/3.8/lib/python3.8/smtplib.py", line 732, in login
    (code, resp) = self.auth(
  File "/Applications/Xcode.app/Contents/Developer/Library/Frameworks/Python3.framework/Versions/3.8/lib/python3.8/smtplib.py", line 645, in auth
    authobject(challenge).encode('ascii'), eol='')
AttributeError: 'NoneType' object has no attribute 'encode'
2022-02-12 16:40:44 [ERROR] : [邮件] 推送威胁情报失败
Traceback (most recent call last):
  File "/Users/skill/Desktop/threat-broadcast/src/notice/mail.py", line 46, in to_mail
    smtpObj.login(sender, password)
  File "/Applications/Xcode.app/Contents/Developer/Library/Frameworks/Python3.framework/Versions/3.8/lib/python3.8/smtplib.py", line 732, in login
    (code, resp) = self.auth(
  File "/Applications/Xcode.app/Contents/Developer/Library/Frameworks/Python3.framework/Versions/3.8/lib/python3.8/smtplib.py", line 645, in auth
    authobject(challenge).encode('ascii'), eol='')
AttributeError: 'NoneType' object has no attribute 'encode'
2022-02-12 16:40:44 [ERROR] : Traceback (most recent call last):
  File "/Users/skill/Desktop/threat-broadcast/src/notice/mail.py", line 46, in to_mail
    smtpObj.login(sender, password)
  File "/Applications/Xcode.app/Contents/Developer/Library/Frameworks/Python3.framework/Versions/3.8/lib/python3.8/smtplib.py", line 732, in login
    (code, resp) = self.auth(
  File "/Applications/Xcode.app/Contents/Developer/Library/Frameworks/Python3.framework/Versions/3.8/lib/python3.8/smtplib.py", line 645, in auth
    authobject(challenge).encode('ascii'), eol='')
AttributeError: 'NoneType' object has no attribute 'encode'
Traceback (most recent call last):
  File "/Users/skill/Desktop/threat-broadcast/src/notice/mail.py", line 46, in to_mail
    smtpObj.login(sender, password)
  File "/Applications/Xcode.app/Contents/Developer/Library/Frameworks/Python3.framework/Versions/3.8/lib/python3.8/smtplib.py", line 732, in login
    (code, resp) = self.auth(
  File "/Applications/Xcode.app/Contents/Developer/Library/Frameworks/Python3.framework/Versions/3.8/lib/python3.8/smtplib.py", line 645, in auth
    authobject(challenge).encode('ascii'), eol='')
AttributeError: 'NoneType' object has no attribute 'encode'
2022-02-12 17:31:56 [ERROR] : [邮件] 推送威胁情报失败
Traceback (most recent call last):
  File "/Users/skill/Desktop/threat-broadcast/src/notice/mail.py", line 46, in to_mail
    smtpObj.login(sender, password)
  File "/Applications/Xcode.app/Contents/Developer/Library/Frameworks/Python3.framework/Versions/3.8/lib/python3.8/smtplib.py", line 732, in login
    (code, resp) = self.auth(
  File "/Applications/Xcode.app/Contents/Developer/Library/Frameworks/Python3.framework/Versions/3.8/lib/python3.8/smtplib.py", line 645, in auth
    authobject(challenge).encode('ascii'), eol='')
AttributeError: 'NoneType' object has no attribute 'encode'
2022-02-12 17:31:56 [ERROR] : Traceback (most recent call last):
  File "/Users/skill/Desktop/threat-broadcast/src/notice/mail.py", line 46, in to_mail
    smtpObj.login(sender, password)
  File "/Applications/Xcode.app/Contents/Developer/Library/Frameworks/Python3.framework/Versions/3.8/lib/python3.8/smtplib.py", line 732, in login
    (code, resp) = self.auth(
  File "/Applications/Xcode.app/Contents/Developer/Library/Frameworks/Python3.framework/Versions/3.8/lib/python3.8/smtplib.py", line 645, in auth
    authobject(challenge).encode('ascii'), eol='')
AttributeError: 'NoneType' object has no attribute 'encode'
Traceback (most recent call last):
  File "/Users/skill/Desktop/threat-broadcast/src/notice/mail.py", line 46, in to_mail
    smtpObj.login(sender, password)
  File "/Applications/Xcode.app/Contents/Developer/Library/Frameworks/Python3.framework/Versions/3.8/lib/python3.8/smtplib.py", line 732, in login
    (code, resp) = self.auth(
  File "/Applications/Xcode.app/Contents/Developer/Library/Frameworks/Python3.framework/Versions/3.8/lib/python3.8/smtplib.py", line 645, in auth
    authobject(challenge).encode('ascii'), eol='')
AttributeError: 'NoneType' object has no attribute 'encode'
2022-02-12 17:32:11 [ERROR] : [邮件] 推送威胁情报失败
Traceback (most recent call last):
  File "/Users/skill/Desktop/threat-broadcast/src/notice/mail.py", line 46, in to_mail
    smtpObj.login(sender, password)
  File "/Applications/Xcode.app/Contents/Developer/Library/Frameworks/Python3.framework/Versions/3.8/lib/python3.8/smtplib.py", line 732, in login
    (code, resp) = self.auth(
  File "/Applications/Xcode.app/Contents/Developer/Library/Frameworks/Python3.framework/Versions/3.8/lib/python3.8/smtplib.py", line 645, in auth
    authobject(challenge).encode('ascii'), eol='')
AttributeError: 'NoneType' object has no attribute 'encode'
2022-02-12 17:32:11 [ERROR] : Traceback (most recent call last):
  File "/Users/skill/Desktop/threat-broadcast/src/notice/mail.py", line 46, in to_mail
    smtpObj.login(sender, password)
  File "/Applications/Xcode.app/Contents/Developer/Library/Frameworks/Python3.framework/Versions/3.8/lib/python3.8/smtplib.py", line 732, in login
    (code, resp) = self.auth(
  File "/Applications/Xcode.app/Contents/Developer/Library/Frameworks/Python3.framework/Versions/3.8/lib/python3.8/smtplib.py", line 645, in auth
    authobject(challenge).encode('ascii'), eol='')
AttributeError: 'NoneType' object has no attribute 'encode'
Traceback (most recent call last):
  File "/Users/skill/Desktop/threat-broadcast/src/notice/mail.py", line 46, in to_mail
    smtpObj.login(sender, password)
  File "/Applications/Xcode.app/Contents/Developer/Library/Frameworks/Python3.framework/Versions/3.8/lib/python3.8/smtplib.py", line 732, in login
    (code, resp) = self.auth(
  File "/Applications/Xcode.app/Contents/Developer/Library/Frameworks/Python3.framework/Versions/3.8/lib/python3.8/smtplib.py", line 645, in auth
    authobject(challenge).encode('ascii'), eol='')
AttributeError: 'NoneType' object has no attribute 'encode'
2022-02-12 17:51:43 [ERROR] : 获取 [阿里云] 威胁情报异常
Traceback (most recent call last):
  File "/Users/skill/Desktop/threat-broadcast/src/crawler/_base_crawler.py", line 62, in cves
    new_cves = self.get_cves()
  File "/Users/skill/Desktop/threat-broadcast/src/crawler/alicloud.py", line 54, in get_cves
    exit()
  File "/Applications/Xcode.app/Contents/Developer/Library/Frameworks/Python3.framework/Versions/3.8/lib/python3.8/_sitebuiltins.py", line 26, in __call__
    raise SystemExit(code)
SystemExit: None
2022-02-12 17:51:43 [ERROR] : Traceback (most recent call last):
  File "/Users/skill/Desktop/threat-broadcast/src/crawler/_base_crawler.py", line 62, in cves
    new_cves = self.get_cves()
  File "/Users/skill/Desktop/threat-broadcast/src/crawler/alicloud.py", line 54, in get_cves
    exit()
  File "/Applications/Xcode.app/Contents/Developer/Library/Frameworks/Python3.framework/Versions/3.8/lib/python3.8/_sitebuiltins.py", line 26, in __call__
    raise SystemExit(code)
SystemExit: None
Traceback (most recent call last):
  File "/Users/skill/Desktop/threat-broadcast/src/crawler/_base_crawler.py", line 62, in cves
    new_cves = self.get_cves()
  File "/Users/skill/Desktop/threat-broadcast/src/crawler/alicloud.py", line 54, in get_cves
    exit()
  File "/Applications/Xcode.app/Contents/Developer/Library/Frameworks/Python3.framework/Versions/3.8/lib/python3.8/_sitebuiltins.py", line 26, in __call__
    raise SystemExit(code)
SystemExit: None
2022-02-12 17:54:00 [ERROR] : [邮件] 推送威胁情报失败
Traceback (most recent call last):
  File "/Users/skill/Desktop/threat-broadcast/src/notice/mail.py", line 46, in to_mail
    smtpObj.login(sender, password)
  File "/Applications/Xcode.app/Contents/Developer/Library/Frameworks/Python3.framework/Versions/3.8/lib/python3.8/smtplib.py", line 732, in login
    (code, resp) = self.auth(
  File "/Applications/Xcode.app/Contents/Developer/Library/Frameworks/Python3.framework/Versions/3.8/lib/python3.8/smtplib.py", line 645, in auth
    authobject(challenge).encode('ascii'), eol='')
AttributeError: 'NoneType' object has no attribute 'encode'
2022-02-12 17:54:00 [ERROR] : Traceback (most recent call last):
  File "/Users/skill/Desktop/threat-broadcast/src/notice/mail.py", line 46, in to_mail
    smtpObj.login(sender, password)
  File "/Applications/Xcode.app/Contents/Developer/Library/Frameworks/Python3.framework/Versions/3.8/lib/python3.8/smtplib.py", line 732, in login
    (code, resp) = self.auth(
  File "/Applications/Xcode.app/Contents/Developer/Library/Frameworks/Python3.framework/Versions/3.8/lib/python3.8/smtplib.py", line 645, in auth
    authobject(challenge).encode('ascii'), eol='')
AttributeError: 'NoneType' object has no attribute 'encode'
Traceback (most recent call last):
  File "/Users/skill/Desktop/threat-broadcast/src/notice/mail.py", line 46, in to_mail
    smtpObj.login(sender, password)
  File "/Applications/Xcode.app/Contents/Developer/Library/Frameworks/Python3.framework/Versions/3.8/lib/python3.8/smtplib.py", line 732, in login
    (code, resp) = self.auth(
  File "/Applications/Xcode.app/Contents/Developer/Library/Frameworks/Python3.framework/Versions/3.8/lib/python3.8/smtplib.py", line 645, in auth
    authobject(challenge).encode('ascii'), eol='')
AttributeError: 'NoneType' object has no attribute 'encode'
2022-02-12 17:54:29 [ERROR] : 获取 [阿里云] 威胁情报异常
Traceback (most recent call last):
  File "/Users/skill/Desktop/threat-broadcast/src/crawler/_base_crawler.py", line 62, in cves
    new_cves = self.get_cves()
  File "/Users/skill/Desktop/threat-broadcast/src/crawler/alicloud.py", line 54, in get_cves
    cve = self.to_cve(vul)
  File "/Users/skill/Desktop/threat-broadcast/src/crawler/alicloud.py", line 68, in to_cve
    cve.url = self.url + rst[0]
TypeError: can only concatenate str (not "tuple") to str
2022-02-12 17:54:29 [ERROR] : Traceback (most recent call last):
  File "/Users/skill/Desktop/threat-broadcast/src/crawler/_base_crawler.py", line 62, in cves
    new_cves = self.get_cves()
  File "/Users/skill/Desktop/threat-broadcast/src/crawler/alicloud.py", line 54, in get_cves
    cve = self.to_cve(vul)
  File "/Users/skill/Desktop/threat-broadcast/src/crawler/alicloud.py", line 68, in to_cve
    cve.url = self.url + rst[0]
TypeError: can only concatenate str (not "tuple") to str
Traceback (most recent call last):
  File "/Users/skill/Desktop/threat-broadcast/src/crawler/_base_crawler.py", line 62, in cves
    new_cves = self.get_cves()
  File "/Users/skill/Desktop/threat-broadcast/src/crawler/alicloud.py", line 54, in get_cves
    cve = self.to_cve(vul)
  File "/Users/skill/Desktop/threat-broadcast/src/crawler/alicloud.py", line 68, in to_cve
    cve.url = self.url + rst[0]
TypeError: can only concatenate str (not "tuple") to str
2022-02-12 17:54:41 [ERROR] : 获取 [阿里云] 威胁情报异常
Traceback (most recent call last):
  File "/Users/skill/Desktop/threat-broadcast/src/crawler/_base_crawler.py", line 62, in cves
    new_cves = self.get_cves()
  File "/Users/skill/Desktop/threat-broadcast/src/crawler/alicloud.py", line 54, in get_cves
    cve = self.to_cve(vul)
  File "/Users/skill/Desktop/threat-broadcast/src/crawler/alicloud.py", line 68, in to_cve
    cve.url = self.url + rst[0]
TypeError: can only concatenate str (not "tuple") to str
2022-02-12 17:54:41 [ERROR] : Traceback (most recent call last):
  File "/Users/skill/Desktop/threat-broadcast/src/crawler/_base_crawler.py", line 62, in cves
    new_cves = self.get_cves()
  File "/Users/skill/Desktop/threat-broadcast/src/crawler/alicloud.py", line 54, in get_cves
    cve = self.to_cve(vul)
  File "/Users/skill/Desktop/threat-broadcast/src/crawler/alicloud.py", line 68, in to_cve
    cve.url = self.url + rst[0]
TypeError: can only concatenate str (not "tuple") to str
Traceback (most recent call last):
  File "/Users/skill/Desktop/threat-broadcast/src/crawler/_base_crawler.py", line 62, in cves
    new_cves = self.get_cves()
  File "/Users/skill/Desktop/threat-broadcast/src/crawler/alicloud.py", line 54, in get_cves
    cve = self.to_cve(vul)
  File "/Users/skill/Desktop/threat-broadcast/src/crawler/alicloud.py", line 68, in to_cve
    cve.url = self.url + rst[0]
TypeError: can only concatenate str (not "tuple") to str
2022-02-12 17:54:52 [ERROR] : 获取 [阿里云] 威胁情报异常
Traceback (most recent call last):
  File "/Users/skill/Desktop/threat-broadcast/src/crawler/_base_crawler.py", line 62, in cves
    new_cves = self.get_cves()
  File "/Users/skill/Desktop/threat-broadcast/src/crawler/alicloud.py", line 54, in get_cves
    cve = self.to_cve(vul)
  File "/Users/skill/Desktop/threat-broadcast/src/crawler/alicloud.py", line 68, in to_cve
    cve.url = self.url + rst[0]
TypeError: can only concatenate str (not "tuple") to str
2022-02-12 17:54:52 [ERROR] : Traceback (most recent call last):
  File "/Users/skill/Desktop/threat-broadcast/src/crawler/_base_crawler.py", line 62, in cves
    new_cves = self.get_cves()
  File "/Users/skill/Desktop/threat-broadcast/src/crawler/alicloud.py", line 54, in get_cves
    cve = self.to_cve(vul)
  File "/Users/skill/Desktop/threat-broadcast/src/crawler/alicloud.py", line 68, in to_cve
    cve.url = self.url + rst[0]
TypeError: can only concatenate str (not "tuple") to str
Traceback (most recent call last):
  File "/Users/skill/Desktop/threat-broadcast/src/crawler/_base_crawler.py", line 62, in cves
    new_cves = self.get_cves()
  File "/Users/skill/Desktop/threat-broadcast/src/crawler/alicloud.py", line 54, in get_cves
    cve = self.to_cve(vul)
  File "/Users/skill/Desktop/threat-broadcast/src/crawler/alicloud.py", line 68, in to_cve
    cve.url = self.url + rst[0]
TypeError: can only concatenate str (not "tuple") to str
2022-02-12 17:55:15 [ERROR] : 获取 [阿里云] 威胁情报异常
Traceback (most recent call last):
  File "/Users/skill/Desktop/threat-broadcast/src/crawler/_base_crawler.py", line 62, in cves
    new_cves = self.get_cves()
  File "/Users/skill/Desktop/threat-broadcast/src/crawler/alicloud.py", line 53, in get_cves
    cve = self.to_cve(vul)
  File "/Users/skill/Desktop/threat-broadcast/src/crawler/alicloud.py", line 68, in to_cve
    cve.url = self.url + rst[0]
TypeError: can only concatenate str (not "tuple") to str
2022-02-12 17:55:15 [ERROR] : Traceback (most recent call last):
  File "/Users/skill/Desktop/threat-broadcast/src/crawler/_base_crawler.py", line 62, in cves
    new_cves = self.get_cves()
  File "/Users/skill/Desktop/threat-broadcast/src/crawler/alicloud.py", line 53, in get_cves
    cve = self.to_cve(vul)
  File "/Users/skill/Desktop/threat-broadcast/src/crawler/alicloud.py", line 68, in to_cve
    cve.url = self.url + rst[0]
TypeError: can only concatenate str (not "tuple") to str
Traceback (most recent call last):
  File "/Users/skill/Desktop/threat-broadcast/src/crawler/_base_crawler.py", line 62, in cves
    new_cves = self.get_cves()
  File "/Users/skill/Desktop/threat-broadcast/src/crawler/alicloud.py", line 53, in get_cves
    cve = self.to_cve(vul)
  File "/Users/skill/Desktop/threat-broadcast/src/crawler/alicloud.py", line 68, in to_cve
    cve.url = self.url + rst[0]
TypeError: can only concatenate str (not "tuple") to str
2022-02-12 17:56:56 [ERROR] : 获取 [阿里云] 威胁情报异常
Traceback (most recent call last):
  File "/Users/skill/Desktop/threat-broadcast/src/crawler/_base_crawler.py", line 62, in cves
    new_cves = self.get_cves()
  File "/Users/skill/Desktop/threat-broadcast/src/crawler/alicloud.py", line 53, in get_cves
    cve = self.to_cve(vul)
  File "/Users/skill/Desktop/threat-broadcast/src/crawler/alicloud.py", line 68, in to_cve
    cve.url = "{}/detail?id={}".format(self.home_pagerst[0][0])
AttributeError: 'AliCloud' object has no attribute 'home_pagerst'
2022-02-12 17:56:56 [ERROR] : Traceback (most recent call last):
  File "/Users/skill/Desktop/threat-broadcast/src/crawler/_base_crawler.py", line 62, in cves
    new_cves = self.get_cves()
  File "/Users/skill/Desktop/threat-broadcast/src/crawler/alicloud.py", line 53, in get_cves
    cve = self.to_cve(vul)
  File "/Users/skill/Desktop/threat-broadcast/src/crawler/alicloud.py", line 68, in to_cve
    cve.url = "{}/detail?id={}".format(self.home_pagerst[0][0])
AttributeError: 'AliCloud' object has no attribute 'home_pagerst'
Traceback (most recent call last):
  File "/Users/skill/Desktop/threat-broadcast/src/crawler/_base_crawler.py", line 62, in cves
    new_cves = self.get_cves()
  File "/Users/skill/Desktop/threat-broadcast/src/crawler/alicloud.py", line 53, in get_cves
    cve = self.to_cve(vul)
  File "/Users/skill/Desktop/threat-broadcast/src/crawler/alicloud.py", line 68, in to_cve
    cve.url = "{}/detail?id={}".format(self.home_pagerst[0][0])
AttributeError: 'AliCloud' object has no attribute 'home_pagerst'
2022-02-12 17:57:10 [ERROR] : 获取 [阿里云] 威胁情报异常
Traceback (most recent call last):
  File "/Users/skill/Desktop/threat-broadcast/src/crawler/_base_crawler.py", line 62, in cves
    new_cves = self.get_cves()
  File "/Users/skill/Desktop/threat-broadcast/src/crawler/alicloud.py", line 53, in get_cves
    cve = self.to_cve(vul)
  File "/Users/skill/Desktop/threat-broadcast/src/crawler/alicloud.py", line 67, in to_cve
    cve.url = "{}/detail?id={}".format(self.home_pagerst[0][0])
AttributeError: 'AliCloud' object has no attribute 'home_pagerst'
2022-02-12 17:57:10 [ERROR] : Traceback (most recent call last):
  File "/Users/skill/Desktop/threat-broadcast/src/crawler/_base_crawler.py", line 62, in cves
    new_cves = self.get_cves()
  File "/Users/skill/Desktop/threat-broadcast/src/crawler/alicloud.py", line 53, in get_cves
    cve = self.to_cve(vul)
  File "/Users/skill/Desktop/threat-broadcast/src/crawler/alicloud.py", line 67, in to_cve
    cve.url = "{}/detail?id={}".format(self.home_pagerst[0][0])
AttributeError: 'AliCloud' object has no attribute 'home_pagerst'
Traceback (most recent call last):
  File "/Users/skill/Desktop/threat-broadcast/src/crawler/_base_crawler.py", line 62, in cves
    new_cves = self.get_cves()
  File "/Users/skill/Desktop/threat-broadcast/src/crawler/alicloud.py", line 53, in get_cves
    cve = self.to_cve(vul)
  File "/Users/skill/Desktop/threat-broadcast/src/crawler/alicloud.py", line 67, in to_cve
    cve.url = "{}/detail?id={}".format(self.home_pagerst[0][0])
AttributeError: 'AliCloud' object has no attribute 'home_pagerst'
2022-02-12 17:57:35 [ERROR] : [邮件] 推送威胁情报失败
Traceback (most recent call last):
  File "/Users/skill/Desktop/threat-broadcast/src/notice/mail.py", line 46, in to_mail
    smtpObj.login(sender, password)
  File "/Applications/Xcode.app/Contents/Developer/Library/Frameworks/Python3.framework/Versions/3.8/lib/python3.8/smtplib.py", line 732, in login
    (code, resp) = self.auth(
  File "/Applications/Xcode.app/Contents/Developer/Library/Frameworks/Python3.framework/Versions/3.8/lib/python3.8/smtplib.py", line 645, in auth
    authobject(challenge).encode('ascii'), eol='')
AttributeError: 'NoneType' object has no attribute 'encode'
2022-02-12 17:57:35 [ERROR] : Traceback (most recent call last):
  File "/Users/skill/Desktop/threat-broadcast/src/notice/mail.py", line 46, in to_mail
    smtpObj.login(sender, password)
  File "/Applications/Xcode.app/Contents/Developer/Library/Frameworks/Python3.framework/Versions/3.8/lib/python3.8/smtplib.py", line 732, in login
    (code, resp) = self.auth(
  File "/Applications/Xcode.app/Contents/Developer/Library/Frameworks/Python3.framework/Versions/3.8/lib/python3.8/smtplib.py", line 645, in auth
    authobject(challenge).encode('ascii'), eol='')
AttributeError: 'NoneType' object has no attribute 'encode'
Traceback (most recent call last):
  File "/Users/skill/Desktop/threat-broadcast/src/notice/mail.py", line 46, in to_mail
    smtpObj.login(sender, password)
  File "/Applications/Xcode.app/Contents/Developer/Library/Frameworks/Python3.framework/Versions/3.8/lib/python3.8/smtplib.py", line 732, in login
    (code, resp) = self.auth(
  File "/Applications/Xcode.app/Contents/Developer/Library/Frameworks/Python3.framework/Versions/3.8/lib/python3.8/smtplib.py", line 645, in auth
    authobject(challenge).encode('ascii'), eol='')
AttributeError: 'NoneType' object has no attribute 'encode'
2022-02-12 18:02:13 [ERROR] : [邮件] 推送威胁情报失败
Traceback (most recent call last):
  File "/Users/skill/Desktop/threat-broadcast/src/notice/mail.py", line 46, in to_mail
    smtpObj.login(sender, password)
  File "/Applications/Xcode.app/Contents/Developer/Library/Frameworks/Python3.framework/Versions/3.8/lib/python3.8/smtplib.py", line 732, in login
    (code, resp) = self.auth(
  File "/Applications/Xcode.app/Contents/Developer/Library/Frameworks/Python3.framework/Versions/3.8/lib/python3.8/smtplib.py", line 645, in auth
    authobject(challenge).encode('ascii'), eol='')
AttributeError: 'NoneType' object has no attribute 'encode'
2022-02-12 18:02:13 [ERROR] : Traceback (most recent call last):
  File "/Users/skill/Desktop/threat-broadcast/src/notice/mail.py", line 46, in to_mail
    smtpObj.login(sender, password)
  File "/Applications/Xcode.app/Contents/Developer/Library/Frameworks/Python3.framework/Versions/3.8/lib/python3.8/smtplib.py", line 732, in login
    (code, resp) = self.auth(
  File "/Applications/Xcode.app/Contents/Developer/Library/Frameworks/Python3.framework/Versions/3.8/lib/python3.8/smtplib.py", line 645, in auth
    authobject(challenge).encode('ascii'), eol='')
AttributeError: 'NoneType' object has no attribute 'encode'
Traceback (most recent call last):
  File "/Users/skill/Desktop/threat-broadcast/src/notice/mail.py", line 46, in to_mail
    smtpObj.login(sender, password)
  File "/Applications/Xcode.app/Contents/Developer/Library/Frameworks/Python3.framework/Versions/3.8/lib/python3.8/smtplib.py", line 732, in login
    (code, resp) = self.auth(
  File "/Applications/Xcode.app/Contents/Developer/Library/Frameworks/Python3.framework/Versions/3.8/lib/python3.8/smtplib.py", line 645, in auth
    authobject(challenge).encode('ascii'), eol='')
AttributeError: 'NoneType' object has no attribute 'encode'
2022-02-12 18:02:46 [ERROR] : 获取 [阿里云] 威胁情报异常
Traceback (most recent call last):
  File "/Users/skill/Desktop/threat-broadcast/src/crawler/_base_crawler.py", line 62, in cves
    new_cves = self.get_cves()
  File "/Users/skill/Desktop/threat-broadcast/src/crawler/alicloud.py", line 54, in get_cves
    cve = self.to_cve(vul)
  File "/Users/skill/Desktop/threat-broadcast/src/crawler/alicloud.py", line 69, in to_cve
    exit()
  File "/Applications/Xcode.app/Contents/Developer/Library/Frameworks/Python3.framework/Versions/3.8/lib/python3.8/_sitebuiltins.py", line 26, in __call__
    raise SystemExit(code)
SystemExit: None
2022-02-12 18:02:46 [ERROR] : Traceback (most recent call last):
  File "/Users/skill/Desktop/threat-broadcast/src/crawler/_base_crawler.py", line 62, in cves
    new_cves = self.get_cves()
  File "/Users/skill/Desktop/threat-broadcast/src/crawler/alicloud.py", line 54, in get_cves
    cve = self.to_cve(vul)
  File "/Users/skill/Desktop/threat-broadcast/src/crawler/alicloud.py", line 69, in to_cve
    exit()
  File "/Applications/Xcode.app/Contents/Developer/Library/Frameworks/Python3.framework/Versions/3.8/lib/python3.8/_sitebuiltins.py", line 26, in __call__
    raise SystemExit(code)
SystemExit: None
Traceback (most recent call last):
  File "/Users/skill/Desktop/threat-broadcast/src/crawler/_base_crawler.py", line 62, in cves
    new_cves = self.get_cves()
  File "/Users/skill/Desktop/threat-broadcast/src/crawler/alicloud.py", line 54, in get_cves
    cve = self.to_cve(vul)
  File "/Users/skill/Desktop/threat-broadcast/src/crawler/alicloud.py", line 69, in to_cve
    exit()
  File "/Applications/Xcode.app/Contents/Developer/Library/Frameworks/Python3.framework/Versions/3.8/lib/python3.8/_sitebuiltins.py", line 26, in __call__
    raise SystemExit(code)
SystemExit: None
2022-02-12 18:03:03 [ERROR] : 获取 [阿里云] 威胁情报异常
Traceback (most recent call last):
  File "/Users/skill/Desktop/threat-broadcast/src/crawler/_base_crawler.py", line 62, in cves
    new_cves = self.get_cves()
  File "/Users/skill/Desktop/threat-broadcast/src/crawler/alicloud.py", line 54, in get_cves
    cve = self.to_cve(vul)
  File "/Users/skill/Desktop/threat-broadcast/src/crawler/alicloud.py", line 69, in to_cve
    exit()
  File "/Applications/Xcode.app/Contents/Developer/Library/Frameworks/Python3.framework/Versions/3.8/lib/python3.8/_sitebuiltins.py", line 26, in __call__
    raise SystemExit(code)
SystemExit: None
2022-02-12 18:03:03 [ERROR] : Traceback (most recent call last):
  File "/Users/skill/Desktop/threat-broadcast/src/crawler/_base_crawler.py", line 62, in cves
    new_cves = self.get_cves()
  File "/Users/skill/Desktop/threat-broadcast/src/crawler/alicloud.py", line 54, in get_cves
    cve = self.to_cve(vul)
  File "/Users/skill/Desktop/threat-broadcast/src/crawler/alicloud.py", line 69, in to_cve
    exit()
  File "/Applications/Xcode.app/Contents/Developer/Library/Frameworks/Python3.framework/Versions/3.8/lib/python3.8/_sitebuiltins.py", line 26, in __call__
    raise SystemExit(code)
SystemExit: None
Traceback (most recent call last):
  File "/Users/skill/Desktop/threat-broadcast/src/crawler/_base_crawler.py", line 62, in cves
    new_cves = self.get_cves()
  File "/Users/skill/Desktop/threat-broadcast/src/crawler/alicloud.py", line 54, in get_cves
    cve = self.to_cve(vul)
  File "/Users/skill/Desktop/threat-broadcast/src/crawler/alicloud.py", line 69, in to_cve
    exit()
  File "/Applications/Xcode.app/Contents/Developer/Library/Frameworks/Python3.framework/Versions/3.8/lib/python3.8/_sitebuiltins.py", line 26, in __call__
    raise SystemExit(code)
SystemExit: None
2022-02-12 18:03:13 [ERROR] : 获取 [阿里云] 威胁情报异常
Traceback (most recent call last):
  File "/Users/skill/Desktop/threat-broadcast/src/crawler/_base_crawler.py", line 62, in cves
    new_cves = self.get_cves()
  File "/Users/skill/Desktop/threat-broadcast/src/crawler/alicloud.py", line 54, in get_cves
    cve = self.to_cve(vul)
  File "/Users/skill/Desktop/threat-broadcast/src/crawler/alicloud.py", line 69, in to_cve
    exit()
  File "/Applications/Xcode.app/Contents/Developer/Library/Frameworks/Python3.framework/Versions/3.8/lib/python3.8/_sitebuiltins.py", line 26, in __call__
    raise SystemExit(code)
SystemExit: None
2022-02-12 18:03:13 [ERROR] : Traceback (most recent call last):
  File "/Users/skill/Desktop/threat-broadcast/src/crawler/_base_crawler.py", line 62, in cves
    new_cves = self.get_cves()
  File "/Users/skill/Desktop/threat-broadcast/src/crawler/alicloud.py", line 54, in get_cves
    cve = self.to_cve(vul)
  File "/Users/skill/Desktop/threat-broadcast/src/crawler/alicloud.py", line 69, in to_cve
    exit()
  File "/Applications/Xcode.app/Contents/Developer/Library/Frameworks/Python3.framework/Versions/3.8/lib/python3.8/_sitebuiltins.py", line 26, in __call__
    raise SystemExit(code)
SystemExit: None
Traceback (most recent call last):
  File "/Users/skill/Desktop/threat-broadcast/src/crawler/_base_crawler.py", line 62, in cves
    new_cves = self.get_cves()
  File "/Users/skill/Desktop/threat-broadcast/src/crawler/alicloud.py", line 54, in get_cves
    cve = self.to_cve(vul)
  File "/Users/skill/Desktop/threat-broadcast/src/crawler/alicloud.py", line 69, in to_cve
    exit()
  File "/Applications/Xcode.app/Contents/Developer/Library/Frameworks/Python3.framework/Versions/3.8/lib/python3.8/_sitebuiltins.py", line 26, in __call__
    raise SystemExit(code)
SystemExit: None
2022-02-12 18:04:27 [ERROR] : 获取 [阿里云] 威胁情报异常
Traceback (most recent call last):
  File "/Users/skill/Desktop/threat-broadcast/src/crawler/_base_crawler.py", line 62, in cves
    new_cves = self.get_cves()
  File "/Users/skill/Desktop/threat-broadcast/src/crawler/alicloud.py", line 54, in get_cves
    cve = self.to_cve(vul)
  File "/Users/skill/Desktop/threat-broadcast/src/crawler/alicloud.py", line 68, in to_cve
    print(html.xpath("//td[1]").text)
AttributeError: 'list' object has no attribute 'text'
2022-02-12 18:04:27 [ERROR] : Traceback (most recent call last):
  File "/Users/skill/Desktop/threat-broadcast/src/crawler/_base_crawler.py", line 62, in cves
    new_cves = self.get_cves()
  File "/Users/skill/Desktop/threat-broadcast/src/crawler/alicloud.py", line 54, in get_cves
    cve = self.to_cve(vul)
  File "/Users/skill/Desktop/threat-broadcast/src/crawler/alicloud.py", line 68, in to_cve
    print(html.xpath("//td[1]").text)
AttributeError: 'list' object has no attribute 'text'
Traceback (most recent call last):
  File "/Users/skill/Desktop/threat-broadcast/src/crawler/_base_crawler.py", line 62, in cves
    new_cves = self.get_cves()
  File "/Users/skill/Desktop/threat-broadcast/src/crawler/alicloud.py", line 54, in get_cves
    cve = self.to_cve(vul)
  File "/Users/skill/Desktop/threat-broadcast/src/crawler/alicloud.py", line 68, in to_cve
    print(html.xpath("//td[1]").text)
AttributeError: 'list' object has no attribute 'text'
2022-02-12 18:04:52 [ERROR] : 获取 [阿里云] 威胁情报异常
Traceback (most recent call last):
  File "/Users/skill/Desktop/threat-broadcast/src/crawler/_base_crawler.py", line 62, in cves
    new_cves = self.get_cves()
  File "/Users/skill/Desktop/threat-broadcast/src/crawler/alicloud.py", line 54, in get_cves
    cve = self.to_cve(vul)
  File "/Users/skill/Desktop/threat-broadcast/src/crawler/alicloud.py", line 69, in to_cve
    exit()
  File "/Applications/Xcode.app/Contents/Developer/Library/Frameworks/Python3.framework/Versions/3.8/lib/python3.8/_sitebuiltins.py", line 26, in __call__
    raise SystemExit(code)
SystemExit: None
2022-02-12 18:04:52 [ERROR] : Traceback (most recent call last):
  File "/Users/skill/Desktop/threat-broadcast/src/crawler/_base_crawler.py", line 62, in cves
    new_cves = self.get_cves()
  File "/Users/skill/Desktop/threat-broadcast/src/crawler/alicloud.py", line 54, in get_cves
    cve = self.to_cve(vul)
  File "/Users/skill/Desktop/threat-broadcast/src/crawler/alicloud.py", line 69, in to_cve
    exit()
  File "/Applications/Xcode.app/Contents/Developer/Library/Frameworks/Python3.framework/Versions/3.8/lib/python3.8/_sitebuiltins.py", line 26, in __call__
    raise SystemExit(code)
SystemExit: None
Traceback (most recent call last):
  File "/Users/skill/Desktop/threat-broadcast/src/crawler/_base_crawler.py", line 62, in cves
    new_cves = self.get_cves()
  File "/Users/skill/Desktop/threat-broadcast/src/crawler/alicloud.py", line 54, in get_cves
    cve = self.to_cve(vul)
  File "/Users/skill/Desktop/threat-broadcast/src/crawler/alicloud.py", line 69, in to_cve
    exit()
  File "/Applications/Xcode.app/Contents/Developer/Library/Frameworks/Python3.framework/Versions/3.8/lib/python3.8/_sitebuiltins.py", line 26, in __call__
    raise SystemExit(code)
SystemExit: None
2022-02-12 18:05:59 [ERROR] : 获取 [阿里云] 威胁情报异常
Traceback (most recent call last):
  File "/Users/skill/Desktop/threat-broadcast/src/crawler/_base_crawler.py", line 62, in cves
    new_cves = self.get_cves()
  File "/Users/skill/Desktop/threat-broadcast/src/crawler/alicloud.py", line 54, in get_cves
    cve = self.to_cve(vul)
  File "/Users/skill/Desktop/threat-broadcast/src/crawler/alicloud.py", line 69, in to_cve
    exit()
  File "/Applications/Xcode.app/Contents/Developer/Library/Frameworks/Python3.framework/Versions/3.8/lib/python3.8/_sitebuiltins.py", line 26, in __call__
    raise SystemExit(code)
SystemExit: None
2022-02-12 18:05:59 [ERROR] : Traceback (most recent call last):
  File "/Users/skill/Desktop/threat-broadcast/src/crawler/_base_crawler.py", line 62, in cves
    new_cves = self.get_cves()
  File "/Users/skill/Desktop/threat-broadcast/src/crawler/alicloud.py", line 54, in get_cves
    cve = self.to_cve(vul)
  File "/Users/skill/Desktop/threat-broadcast/src/crawler/alicloud.py", line 69, in to_cve
    exit()
  File "/Applications/Xcode.app/Contents/Developer/Library/Frameworks/Python3.framework/Versions/3.8/lib/python3.8/_sitebuiltins.py", line 26, in __call__
    raise SystemExit(code)
SystemExit: None
Traceback (most recent call last):
  File "/Users/skill/Desktop/threat-broadcast/src/crawler/_base_crawler.py", line 62, in cves
    new_cves = self.get_cves()
  File "/Users/skill/Desktop/threat-broadcast/src/crawler/alicloud.py", line 54, in get_cves
    cve = self.to_cve(vul)
  File "/Users/skill/Desktop/threat-broadcast/src/crawler/alicloud.py", line 69, in to_cve
    exit()
  File "/Applications/Xcode.app/Contents/Developer/Library/Frameworks/Python3.framework/Versions/3.8/lib/python3.8/_sitebuiltins.py", line 26, in __call__
    raise SystemExit(code)
SystemExit: None
2022-02-12 18:07:03 [ERROR] : 获取 [阿里云] 威胁情报异常
Traceback (most recent call last):
  File "/Users/skill/Desktop/threat-broadcast/src/crawler/_base_crawler.py", line 62, in cves
    new_cves = self.get_cves()
  File "/Users/skill/Desktop/threat-broadcast/src/crawler/alicloud.py", line 54, in get_cves
    cve = self.to_cve(vul)
  File "/Users/skill/Desktop/threat-broadcast/src/crawler/alicloud.py", line 68, in to_cve
    print(etree.tostring(html.xpath("td")[1]))
IndexError: list index out of range
2022-02-12 18:07:03 [ERROR] : Traceback (most recent call last):
  File "/Users/skill/Desktop/threat-broadcast/src/crawler/_base_crawler.py", line 62, in cves
    new_cves = self.get_cves()
  File "/Users/skill/Desktop/threat-broadcast/src/crawler/alicloud.py", line 54, in get_cves
    cve = self.to_cve(vul)
  File "/Users/skill/Desktop/threat-broadcast/src/crawler/alicloud.py", line 68, in to_cve
    print(etree.tostring(html.xpath("td")[1]))
IndexError: list index out of range
Traceback (most recent call last):
  File "/Users/skill/Desktop/threat-broadcast/src/crawler/_base_crawler.py", line 62, in cves
    new_cves = self.get_cves()
  File "/Users/skill/Desktop/threat-broadcast/src/crawler/alicloud.py", line 54, in get_cves
    cve = self.to_cve(vul)
  File "/Users/skill/Desktop/threat-broadcast/src/crawler/alicloud.py", line 68, in to_cve
    print(etree.tostring(html.xpath("td")[1]))
IndexError: list index out of range
2022-02-12 18:07:33 [ERROR] : 获取 [阿里云] 威胁情报异常
Traceback (most recent call last):
  File "/Users/skill/Desktop/threat-broadcast/src/crawler/_base_crawler.py", line 62, in cves
    new_cves = self.get_cves()
  File "/Users/skill/Desktop/threat-broadcast/src/crawler/alicloud.py", line 54, in get_cves
    cve = self.to_cve(vul)
  File "/Users/skill/Desktop/threat-broadcast/src/crawler/alicloud.py", line 68, in to_cve
    print(etree.tostring(html.xpath("/td")[1]))
IndexError: list index out of range
2022-02-12 18:07:33 [ERROR] : Traceback (most recent call last):
  File "/Users/skill/Desktop/threat-broadcast/src/crawler/_base_crawler.py", line 62, in cves
    new_cves = self.get_cves()
  File "/Users/skill/Desktop/threat-broadcast/src/crawler/alicloud.py", line 54, in get_cves
    cve = self.to_cve(vul)
  File "/Users/skill/Desktop/threat-broadcast/src/crawler/alicloud.py", line 68, in to_cve
    print(etree.tostring(html.xpath("/td")[1]))
IndexError: list index out of range
Traceback (most recent call last):
  File "/Users/skill/Desktop/threat-broadcast/src/crawler/_base_crawler.py", line 62, in cves
    new_cves = self.get_cves()
  File "/Users/skill/Desktop/threat-broadcast/src/crawler/alicloud.py", line 54, in get_cves
    cve = self.to_cve(vul)
  File "/Users/skill/Desktop/threat-broadcast/src/crawler/alicloud.py", line 68, in to_cve
    print(etree.tostring(html.xpath("/td")[1]))
IndexError: list index out of range
2022-02-12 18:07:53 [ERROR] : 获取 [阿里云] 威胁情报异常
Traceback (most recent call last):
  File "/Users/skill/Desktop/threat-broadcast/src/crawler/_base_crawler.py", line 62, in cves
    new_cves = self.get_cves()
  File "/Users/skill/Desktop/threat-broadcast/src/crawler/alicloud.py", line 54, in get_cves
    cve = self.to_cve(vul)
  File "/Users/skill/Desktop/threat-broadcast/src/crawler/alicloud.py", line 68, in to_cve
    print(etree.tostring(html.xpath("td[1]")[1]))
IndexError: list index out of range
2022-02-12 18:07:53 [ERROR] : Traceback (most recent call last):
  File "/Users/skill/Desktop/threat-broadcast/src/crawler/_base_crawler.py", line 62, in cves
    new_cves = self.get_cves()
  File "/Users/skill/Desktop/threat-broadcast/src/crawler/alicloud.py", line 54, in get_cves
    cve = self.to_cve(vul)
  File "/Users/skill/Desktop/threat-broadcast/src/crawler/alicloud.py", line 68, in to_cve
    print(etree.tostring(html.xpath("td[1]")[1]))
IndexError: list index out of range
Traceback (most recent call last):
  File "/Users/skill/Desktop/threat-broadcast/src/crawler/_base_crawler.py", line 62, in cves
    new_cves = self.get_cves()
  File "/Users/skill/Desktop/threat-broadcast/src/crawler/alicloud.py", line 54, in get_cves
    cve = self.to_cve(vul)
  File "/Users/skill/Desktop/threat-broadcast/src/crawler/alicloud.py", line 68, in to_cve
    print(etree.tostring(html.xpath("td[1]")[1]))
IndexError: list index out of range
2022-02-12 18:08:17 [ERROR] : 获取 [阿里云] 威胁情报异常
Traceback (most recent call last):
  File "/Users/skill/Desktop/threat-broadcast/src/crawler/_base_crawler.py", line 62, in cves
    new_cves = self.get_cves()
  File "/Users/skill/Desktop/threat-broadcast/src/crawler/alicloud.py", line 54, in get_cves
    cve = self.to_cve(vul)
  File "/Users/skill/Desktop/threat-broadcast/src/crawler/alicloud.py", line 68, in to_cve
    print(etree.tostring(html.xpath("td")[1]))
IndexError: list index out of range
2022-02-12 18:08:17 [ERROR] : Traceback (most recent call last):
  File "/Users/skill/Desktop/threat-broadcast/src/crawler/_base_crawler.py", line 62, in cves
    new_cves = self.get_cves()
  File "/Users/skill/Desktop/threat-broadcast/src/crawler/alicloud.py", line 54, in get_cves
    cve = self.to_cve(vul)
  File "/Users/skill/Desktop/threat-broadcast/src/crawler/alicloud.py", line 68, in to_cve
    print(etree.tostring(html.xpath("td")[1]))
IndexError: list index out of range
Traceback (most recent call last):
  File "/Users/skill/Desktop/threat-broadcast/src/crawler/_base_crawler.py", line 62, in cves
    new_cves = self.get_cves()
  File "/Users/skill/Desktop/threat-broadcast/src/crawler/alicloud.py", line 54, in get_cves
    cve = self.to_cve(vul)
  File "/Users/skill/Desktop/threat-broadcast/src/crawler/alicloud.py", line 68, in to_cve
    print(etree.tostring(html.xpath("td")[1]))
IndexError: list index out of range
2022-02-12 18:08:48 [ERROR] : 获取 [阿里云] 威胁情报异常
Traceback (most recent call last):
  File "/Users/skill/Desktop/threat-broadcast/src/crawler/_base_crawler.py", line 62, in cves
    new_cves = self.get_cves()
  File "/Users/skill/Desktop/threat-broadcast/src/crawler/alicloud.py", line 54, in get_cves
    cve = self.to_cve(vul)
  File "/Users/skill/Desktop/threat-broadcast/src/crawler/alicloud.py", line 68, in to_cve
    print(html.xpath("td")[1])
IndexError: list index out of range
2022-02-12 18:08:48 [ERROR] : Traceback (most recent call last):
  File "/Users/skill/Desktop/threat-broadcast/src/crawler/_base_crawler.py", line 62, in cves
    new_cves = self.get_cves()
  File "/Users/skill/Desktop/threat-broadcast/src/crawler/alicloud.py", line 54, in get_cves
    cve = self.to_cve(vul)
  File "/Users/skill/Desktop/threat-broadcast/src/crawler/alicloud.py", line 68, in to_cve
    print(html.xpath("td")[1])
IndexError: list index out of range
Traceback (most recent call last):
  File "/Users/skill/Desktop/threat-broadcast/src/crawler/_base_crawler.py", line 62, in cves
    new_cves = self.get_cves()
  File "/Users/skill/Desktop/threat-broadcast/src/crawler/alicloud.py", line 54, in get_cves
    cve = self.to_cve(vul)
  File "/Users/skill/Desktop/threat-broadcast/src/crawler/alicloud.py", line 68, in to_cve
    print(html.xpath("td")[1])
IndexError: list index out of range
2022-02-12 18:08:53 [ERROR] : 获取 [阿里云] 威胁情报异常
Traceback (most recent call last):
  File "/Users/skill/Desktop/threat-broadcast/src/crawler/_base_crawler.py", line 62, in cves
    new_cves = self.get_cves()
  File "/Users/skill/Desktop/threat-broadcast/src/crawler/alicloud.py", line 54, in get_cves
    cve = self.to_cve(vul)
  File "/Users/skill/Desktop/threat-broadcast/src/crawler/alicloud.py", line 69, in to_cve
    exit()
  File "/Applications/Xcode.app/Contents/Developer/Library/Frameworks/Python3.framework/Versions/3.8/lib/python3.8/_sitebuiltins.py", line 26, in __call__
    raise SystemExit(code)
SystemExit: None
2022-02-12 18:08:53 [ERROR] : Traceback (most recent call last):
  File "/Users/skill/Desktop/threat-broadcast/src/crawler/_base_crawler.py", line 62, in cves
    new_cves = self.get_cves()
  File "/Users/skill/Desktop/threat-broadcast/src/crawler/alicloud.py", line 54, in get_cves
    cve = self.to_cve(vul)
  File "/Users/skill/Desktop/threat-broadcast/src/crawler/alicloud.py", line 69, in to_cve
    exit()
  File "/Applications/Xcode.app/Contents/Developer/Library/Frameworks/Python3.framework/Versions/3.8/lib/python3.8/_sitebuiltins.py", line 26, in __call__
    raise SystemExit(code)
SystemExit: None
Traceback (most recent call last):
  File "/Users/skill/Desktop/threat-broadcast/src/crawler/_base_crawler.py", line 62, in cves
    new_cves = self.get_cves()
  File "/Users/skill/Desktop/threat-broadcast/src/crawler/alicloud.py", line 54, in get_cves
    cve = self.to_cve(vul)
  File "/Users/skill/Desktop/threat-broadcast/src/crawler/alicloud.py", line 69, in to_cve
    exit()
  File "/Applications/Xcode.app/Contents/Developer/Library/Frameworks/Python3.framework/Versions/3.8/lib/python3.8/_sitebuiltins.py", line 26, in __call__
    raise SystemExit(code)
SystemExit: None
2022-02-12 18:09:00 [ERROR] : 获取 [阿里云] 威胁情报异常
Traceback (most recent call last):
  File "/Users/skill/Desktop/threat-broadcast/src/crawler/_base_crawler.py", line 62, in cves
    new_cves = self.get_cves()
  File "/Users/skill/Desktop/threat-broadcast/src/crawler/alicloud.py", line 54, in get_cves
    cve = self.to_cve(vul)
  File "/Users/skill/Desktop/threat-broadcast/src/crawler/alicloud.py", line 69, in to_cve
    exit()
  File "/Applications/Xcode.app/Contents/Developer/Library/Frameworks/Python3.framework/Versions/3.8/lib/python3.8/_sitebuiltins.py", line 26, in __call__
    raise SystemExit(code)
SystemExit: None
2022-02-12 18:09:00 [ERROR] : Traceback (most recent call last):
  File "/Users/skill/Desktop/threat-broadcast/src/crawler/_base_crawler.py", line 62, in cves
    new_cves = self.get_cves()
  File "/Users/skill/Desktop/threat-broadcast/src/crawler/alicloud.py", line 54, in get_cves
    cve = self.to_cve(vul)
  File "/Users/skill/Desktop/threat-broadcast/src/crawler/alicloud.py", line 69, in to_cve
    exit()
  File "/Applications/Xcode.app/Contents/Developer/Library/Frameworks/Python3.framework/Versions/3.8/lib/python3.8/_sitebuiltins.py", line 26, in __call__
    raise SystemExit(code)
SystemExit: None
Traceback (most recent call last):
  File "/Users/skill/Desktop/threat-broadcast/src/crawler/_base_crawler.py", line 62, in cves
    new_cves = self.get_cves()
  File "/Users/skill/Desktop/threat-broadcast/src/crawler/alicloud.py", line 54, in get_cves
    cve = self.to_cve(vul)
  File "/Users/skill/Desktop/threat-broadcast/src/crawler/alicloud.py", line 69, in to_cve
    exit()
  File "/Applications/Xcode.app/Contents/Developer/Library/Frameworks/Python3.framework/Versions/3.8/lib/python3.8/_sitebuiltins.py", line 26, in __call__
    raise SystemExit(code)
SystemExit: None
2022-02-12 18:09:05 [ERROR] : 获取 [阿里云] 威胁情报异常
Traceback (most recent call last):
  File "/Users/skill/Desktop/threat-broadcast/src/crawler/_base_crawler.py", line 62, in cves
    new_cves = self.get_cves()
  File "/Users/skill/Desktop/threat-broadcast/src/crawler/alicloud.py", line 54, in get_cves
    cve = self.to_cve(vul)
  File "/Users/skill/Desktop/threat-broadcast/src/crawler/alicloud.py", line 69, in to_cve
    exit()
  File "/Applications/Xcode.app/Contents/Developer/Library/Frameworks/Python3.framework/Versions/3.8/lib/python3.8/_sitebuiltins.py", line 26, in __call__
    raise SystemExit(code)
SystemExit: None
2022-02-12 18:09:05 [ERROR] : Traceback (most recent call last):
  File "/Users/skill/Desktop/threat-broadcast/src/crawler/_base_crawler.py", line 62, in cves
    new_cves = self.get_cves()
  File "/Users/skill/Desktop/threat-broadcast/src/crawler/alicloud.py", line 54, in get_cves
    cve = self.to_cve(vul)
  File "/Users/skill/Desktop/threat-broadcast/src/crawler/alicloud.py", line 69, in to_cve
    exit()
  File "/Applications/Xcode.app/Contents/Developer/Library/Frameworks/Python3.framework/Versions/3.8/lib/python3.8/_sitebuiltins.py", line 26, in __call__
    raise SystemExit(code)
SystemExit: None
Traceback (most recent call last):
  File "/Users/skill/Desktop/threat-broadcast/src/crawler/_base_crawler.py", line 62, in cves
    new_cves = self.get_cves()
  File "/Users/skill/Desktop/threat-broadcast/src/crawler/alicloud.py", line 54, in get_cves
    cve = self.to_cve(vul)
  File "/Users/skill/Desktop/threat-broadcast/src/crawler/alicloud.py", line 69, in to_cve
    exit()
  File "/Applications/Xcode.app/Contents/Developer/Library/Frameworks/Python3.framework/Versions/3.8/lib/python3.8/_sitebuiltins.py", line 26, in __call__
    raise SystemExit(code)
SystemExit: None
2022-02-12 18:09:15 [ERROR] : 获取 [阿里云] 威胁情报异常
Traceback (most recent call last):
  File "/Users/skill/Desktop/threat-broadcast/src/crawler/_base_crawler.py", line 62, in cves
    new_cves = self.get_cves()
  File "/Users/skill/Desktop/threat-broadcast/src/crawler/alicloud.py", line 54, in get_cves
    cve = self.to_cve(vul)
  File "/Users/skill/Desktop/threat-broadcast/src/crawler/alicloud.py", line 69, in to_cve
    exit()
  File "/Applications/Xcode.app/Contents/Developer/Library/Frameworks/Python3.framework/Versions/3.8/lib/python3.8/_sitebuiltins.py", line 26, in __call__
    raise SystemExit(code)
SystemExit: None
2022-02-12 18:09:15 [ERROR] : Traceback (most recent call last):
  File "/Users/skill/Desktop/threat-broadcast/src/crawler/_base_crawler.py", line 62, in cves
    new_cves = self.get_cves()
  File "/Users/skill/Desktop/threat-broadcast/src/crawler/alicloud.py", line 54, in get_cves
    cve = self.to_cve(vul)
  File "/Users/skill/Desktop/threat-broadcast/src/crawler/alicloud.py", line 69, in to_cve
    exit()
  File "/Applications/Xcode.app/Contents/Developer/Library/Frameworks/Python3.framework/Versions/3.8/lib/python3.8/_sitebuiltins.py", line 26, in __call__
    raise SystemExit(code)
SystemExit: None
Traceback (most recent call last):
  File "/Users/skill/Desktop/threat-broadcast/src/crawler/_base_crawler.py", line 62, in cves
    new_cves = self.get_cves()
  File "/Users/skill/Desktop/threat-broadcast/src/crawler/alicloud.py", line 54, in get_cves
    cve = self.to_cve(vul)
  File "/Users/skill/Desktop/threat-broadcast/src/crawler/alicloud.py", line 69, in to_cve
    exit()
  File "/Applications/Xcode.app/Contents/Developer/Library/Frameworks/Python3.framework/Versions/3.8/lib/python3.8/_sitebuiltins.py", line 26, in __call__
    raise SystemExit(code)
SystemExit: None
2022-02-12 18:09:34 [ERROR] : 获取 [阿里云] 威胁情报异常
Traceback (most recent call last):
  File "/Users/skill/Desktop/threat-broadcast/src/crawler/_base_crawler.py", line 62, in cves
    new_cves = self.get_cves()
  File "/Users/skill/Desktop/threat-broadcast/src/crawler/alicloud.py", line 54, in get_cves
    cve = self.to_cve(vul)
  File "/Users/skill/Desktop/threat-broadcast/src/crawler/alicloud.py", line 69, in to_cve
    exit()
  File "/Applications/Xcode.app/Contents/Developer/Library/Frameworks/Python3.framework/Versions/3.8/lib/python3.8/_sitebuiltins.py", line 26, in __call__
    raise SystemExit(code)
SystemExit: None
2022-02-12 18:09:34 [ERROR] : Traceback (most recent call last):
  File "/Users/skill/Desktop/threat-broadcast/src/crawler/_base_crawler.py", line 62, in cves
    new_cves = self.get_cves()
  File "/Users/skill/Desktop/threat-broadcast/src/crawler/alicloud.py", line 54, in get_cves
    cve = self.to_cve(vul)
  File "/Users/skill/Desktop/threat-broadcast/src/crawler/alicloud.py", line 69, in to_cve
    exit()
  File "/Applications/Xcode.app/Contents/Developer/Library/Frameworks/Python3.framework/Versions/3.8/lib/python3.8/_sitebuiltins.py", line 26, in __call__
    raise SystemExit(code)
SystemExit: None
Traceback (most recent call last):
  File "/Users/skill/Desktop/threat-broadcast/src/crawler/_base_crawler.py", line 62, in cves
    new_cves = self.get_cves()
  File "/Users/skill/Desktop/threat-broadcast/src/crawler/alicloud.py", line 54, in get_cves
    cve = self.to_cve(vul)
  File "/Users/skill/Desktop/threat-broadcast/src/crawler/alicloud.py", line 69, in to_cve
    exit()
  File "/Applications/Xcode.app/Contents/Developer/Library/Frameworks/Python3.framework/Versions/3.8/lib/python3.8/_sitebuiltins.py", line 26, in __call__
    raise SystemExit(code)
SystemExit: None
2022-02-12 18:09:48 [ERROR] : 获取 [阿里云] 威胁情报异常
Traceback (most recent call last):
  File "/Users/skill/Desktop/threat-broadcast/src/crawler/_base_crawler.py", line 62, in cves
    new_cves = self.get_cves()
  File "/Users/skill/Desktop/threat-broadcast/src/crawler/alicloud.py", line 54, in get_cves
    cve = self.to_cve(vul)
  File "/Users/skill/Desktop/threat-broadcast/src/crawler/alicloud.py", line 68, in to_cve
    print(etree.tostring(html.xpath("//td/text")[1]))
IndexError: list index out of range
2022-02-12 18:09:48 [ERROR] : Traceback (most recent call last):
  File "/Users/skill/Desktop/threat-broadcast/src/crawler/_base_crawler.py", line 62, in cves
    new_cves = self.get_cves()
  File "/Users/skill/Desktop/threat-broadcast/src/crawler/alicloud.py", line 54, in get_cves
    cve = self.to_cve(vul)
  File "/Users/skill/Desktop/threat-broadcast/src/crawler/alicloud.py", line 68, in to_cve
    print(etree.tostring(html.xpath("//td/text")[1]))
IndexError: list index out of range
Traceback (most recent call last):
  File "/Users/skill/Desktop/threat-broadcast/src/crawler/_base_crawler.py", line 62, in cves
    new_cves = self.get_cves()
  File "/Users/skill/Desktop/threat-broadcast/src/crawler/alicloud.py", line 54, in get_cves
    cve = self.to_cve(vul)
  File "/Users/skill/Desktop/threat-broadcast/src/crawler/alicloud.py", line 68, in to_cve
    print(etree.tostring(html.xpath("//td/text")[1]))
IndexError: list index out of range
2022-02-12 18:10:26 [ERROR] : 获取 [阿里云] 威胁情报异常
Traceback (most recent call last):
  File "/Users/skill/Desktop/threat-broadcast/src/crawler/_base_crawler.py", line 62, in cves
    new_cves = self.get_cves()
  File "/Users/skill/Desktop/threat-broadcast/src/crawler/alicloud.py", line 54, in get_cves
    cve = self.to_cve(vul)
  File "/Users/skill/Desktop/threat-broadcast/src/crawler/alicloud.py", line 68, in to_cve
    print(etree.tostring(html.xpath("//td@text")[1]))
  File "src/lxml/etree.pyx", line 1582, in lxml.etree._Element.xpath
  File "src/lxml/xpath.pxi", line 305, in lxml.etree.XPathElementEvaluator.__call__
  File "src/lxml/xpath.pxi", line 225, in lxml.etree._XPathEvaluatorBase._handle_result
lxml.etree.XPathEvalError: Invalid expression
2022-02-12 18:10:26 [ERROR] : Traceback (most recent call last):
  File "/Users/skill/Desktop/threat-broadcast/src/crawler/_base_crawler.py", line 62, in cves
    new_cves = self.get_cves()
  File "/Users/skill/Desktop/threat-broadcast/src/crawler/alicloud.py", line 54, in get_cves
    cve = self.to_cve(vul)
  File "/Users/skill/Desktop/threat-broadcast/src/crawler/alicloud.py", line 68, in to_cve
    print(etree.tostring(html.xpath("//td@text")[1]))
  File "src/lxml/etree.pyx", line 1582, in lxml.etree._Element.xpath
  File "src/lxml/xpath.pxi", line 305, in lxml.etree.XPathElementEvaluator.__call__
  File "src/lxml/xpath.pxi", line 225, in lxml.etree._XPathEvaluatorBase._handle_result
lxml.etree.XPathEvalError: Invalid expression
Traceback (most recent call last):
  File "/Users/skill/Desktop/threat-broadcast/src/crawler/_base_crawler.py", line 62, in cves
    new_cves = self.get_cves()
  File "/Users/skill/Desktop/threat-broadcast/src/crawler/alicloud.py", line 54, in get_cves
    cve = self.to_cve(vul)
  File "/Users/skill/Desktop/threat-broadcast/src/crawler/alicloud.py", line 68, in to_cve
    print(etree.tostring(html.xpath("//td@text")[1]))
  File "src/lxml/etree.pyx", line 1582, in lxml.etree._Element.xpath
  File "src/lxml/xpath.pxi", line 305, in lxml.etree.XPathElementEvaluator.__call__
  File "src/lxml/xpath.pxi", line 225, in lxml.etree._XPathEvaluatorBase._handle_result
lxml.etree.XPathEvalError: Invalid expression
2022-02-12 18:10:36 [ERROR] : 获取 [阿里云] 威胁情报异常
Traceback (most recent call last):
  File "/Users/skill/Desktop/threat-broadcast/src/crawler/_base_crawler.py", line 62, in cves
    new_cves = self.get_cves()
  File "/Users/skill/Desktop/threat-broadcast/src/crawler/alicloud.py", line 54, in get_cves
    cve = self.to_cve(vul)
  File "/Users/skill/Desktop/threat-broadcast/src/crawler/alicloud.py", line 68, in to_cve
    print(etree.tostring(html.xpath("//td@text")[1]))
  File "src/lxml/etree.pyx", line 1582, in lxml.etree._Element.xpath
  File "src/lxml/xpath.pxi", line 305, in lxml.etree.XPathElementEvaluator.__call__
  File "src/lxml/xpath.pxi", line 225, in lxml.etree._XPathEvaluatorBase._handle_result
lxml.etree.XPathEvalError: Invalid expression
2022-02-12 18:10:36 [ERROR] : Traceback (most recent call last):
  File "/Users/skill/Desktop/threat-broadcast/src/crawler/_base_crawler.py", line 62, in cves
    new_cves = self.get_cves()
  File "/Users/skill/Desktop/threat-broadcast/src/crawler/alicloud.py", line 54, in get_cves
    cve = self.to_cve(vul)
  File "/Users/skill/Desktop/threat-broadcast/src/crawler/alicloud.py", line 68, in to_cve
    print(etree.tostring(html.xpath("//td@text")[1]))
  File "src/lxml/etree.pyx", line 1582, in lxml.etree._Element.xpath
  File "src/lxml/xpath.pxi", line 305, in lxml.etree.XPathElementEvaluator.__call__
  File "src/lxml/xpath.pxi", line 225, in lxml.etree._XPathEvaluatorBase._handle_result
lxml.etree.XPathEvalError: Invalid expression
Traceback (most recent call last):
  File "/Users/skill/Desktop/threat-broadcast/src/crawler/_base_crawler.py", line 62, in cves
    new_cves = self.get_cves()
  File "/Users/skill/Desktop/threat-broadcast/src/crawler/alicloud.py", line 54, in get_cves
    cve = self.to_cve(vul)
  File "/Users/skill/Desktop/threat-broadcast/src/crawler/alicloud.py", line 68, in to_cve
    print(etree.tostring(html.xpath("//td@text")[1]))
  File "src/lxml/etree.pyx", line 1582, in lxml.etree._Element.xpath
  File "src/lxml/xpath.pxi", line 305, in lxml.etree.XPathElementEvaluator.__call__
  File "src/lxml/xpath.pxi", line 225, in lxml.etree._XPathEvaluatorBase._handle_result
lxml.etree.XPathEvalError: Invalid expression
2022-02-12 18:10:42 [ERROR] : 获取 [阿里云] 威胁情报异常
Traceback (most recent call last):
  File "/Users/skill/Desktop/threat-broadcast/src/crawler/_base_crawler.py", line 62, in cves
    new_cves = self.get_cves()
  File "/Users/skill/Desktop/threat-broadcast/src/crawler/alicloud.py", line 54, in get_cves
    cve = self.to_cve(vul)
  File "/Users/skill/Desktop/threat-broadcast/src/crawler/alicloud.py", line 69, in to_cve
    exit()
  File "/Applications/Xcode.app/Contents/Developer/Library/Frameworks/Python3.framework/Versions/3.8/lib/python3.8/_sitebuiltins.py", line 26, in __call__
    raise SystemExit(code)
SystemExit: None
2022-02-12 18:10:42 [ERROR] : Traceback (most recent call last):
  File "/Users/skill/Desktop/threat-broadcast/src/crawler/_base_crawler.py", line 62, in cves
    new_cves = self.get_cves()
  File "/Users/skill/Desktop/threat-broadcast/src/crawler/alicloud.py", line 54, in get_cves
    cve = self.to_cve(vul)
  File "/Users/skill/Desktop/threat-broadcast/src/crawler/alicloud.py", line 69, in to_cve
    exit()
  File "/Applications/Xcode.app/Contents/Developer/Library/Frameworks/Python3.framework/Versions/3.8/lib/python3.8/_sitebuiltins.py", line 26, in __call__
    raise SystemExit(code)
SystemExit: None
Traceback (most recent call last):
  File "/Users/skill/Desktop/threat-broadcast/src/crawler/_base_crawler.py", line 62, in cves
    new_cves = self.get_cves()
  File "/Users/skill/Desktop/threat-broadcast/src/crawler/alicloud.py", line 54, in get_cves
    cve = self.to_cve(vul)
  File "/Users/skill/Desktop/threat-broadcast/src/crawler/alicloud.py", line 69, in to_cve
    exit()
  File "/Applications/Xcode.app/Contents/Developer/Library/Frameworks/Python3.framework/Versions/3.8/lib/python3.8/_sitebuiltins.py", line 26, in __call__
    raise SystemExit(code)
SystemExit: None
2022-02-12 18:11:00 [ERROR] : 获取 [阿里云] 威胁情报异常
Traceback (most recent call last):
  File "/Users/skill/Desktop/threat-broadcast/src/crawler/_base_crawler.py", line 62, in cves
    new_cves = self.get_cves()
  File "/Users/skill/Desktop/threat-broadcast/src/crawler/alicloud.py", line 54, in get_cves
    cve = self.to_cve(vul)
  File "/Users/skill/Desktop/threat-broadcast/src/crawler/alicloud.py", line 69, in to_cve
    exit()
  File "/Applications/Xcode.app/Contents/Developer/Library/Frameworks/Python3.framework/Versions/3.8/lib/python3.8/_sitebuiltins.py", line 26, in __call__
    raise SystemExit(code)
SystemExit: None
2022-02-12 18:11:00 [ERROR] : Traceback (most recent call last):
  File "/Users/skill/Desktop/threat-broadcast/src/crawler/_base_crawler.py", line 62, in cves
    new_cves = self.get_cves()
  File "/Users/skill/Desktop/threat-broadcast/src/crawler/alicloud.py", line 54, in get_cves
    cve = self.to_cve(vul)
  File "/Users/skill/Desktop/threat-broadcast/src/crawler/alicloud.py", line 69, in to_cve
    exit()
  File "/Applications/Xcode.app/Contents/Developer/Library/Frameworks/Python3.framework/Versions/3.8/lib/python3.8/_sitebuiltins.py", line 26, in __call__
    raise SystemExit(code)
SystemExit: None
Traceback (most recent call last):
  File "/Users/skill/Desktop/threat-broadcast/src/crawler/_base_crawler.py", line 62, in cves
    new_cves = self.get_cves()
  File "/Users/skill/Desktop/threat-broadcast/src/crawler/alicloud.py", line 54, in get_cves
    cve = self.to_cve(vul)
  File "/Users/skill/Desktop/threat-broadcast/src/crawler/alicloud.py", line 69, in to_cve
    exit()
  File "/Applications/Xcode.app/Contents/Developer/Library/Frameworks/Python3.framework/Versions/3.8/lib/python3.8/_sitebuiltins.py", line 26, in __call__
    raise SystemExit(code)
SystemExit: None
2022-02-12 18:12:06 [ERROR] : 获取 [阿里云] 威胁情报异常
Traceback (most recent call last):
  File "/Users/skill/Desktop/threat-broadcast/src/crawler/_base_crawler.py", line 62, in cves
    new_cves = self.get_cves()
  File "/Users/skill/Desktop/threat-broadcast/src/crawler/alicloud.py", line 54, in get_cves
    cve = self.to_cve(vul)
  File "/Users/skill/Desktop/threat-broadcast/src/crawler/alicloud.py", line 69, in to_cve
    exit()
  File "/Applications/Xcode.app/Contents/Developer/Library/Frameworks/Python3.framework/Versions/3.8/lib/python3.8/_sitebuiltins.py", line 26, in __call__
    raise SystemExit(code)
SystemExit: None
2022-02-12 18:12:06 [ERROR] : Traceback (most recent call last):
  File "/Users/skill/Desktop/threat-broadcast/src/crawler/_base_crawler.py", line 62, in cves
    new_cves = self.get_cves()
  File "/Users/skill/Desktop/threat-broadcast/src/crawler/alicloud.py", line 54, in get_cves
    cve = self.to_cve(vul)
  File "/Users/skill/Desktop/threat-broadcast/src/crawler/alicloud.py", line 69, in to_cve
    exit()
  File "/Applications/Xcode.app/Contents/Developer/Library/Frameworks/Python3.framework/Versions/3.8/lib/python3.8/_sitebuiltins.py", line 26, in __call__
    raise SystemExit(code)
SystemExit: None
Traceback (most recent call last):
  File "/Users/skill/Desktop/threat-broadcast/src/crawler/_base_crawler.py", line 62, in cves
    new_cves = self.get_cves()
  File "/Users/skill/Desktop/threat-broadcast/src/crawler/alicloud.py", line 54, in get_cves
    cve = self.to_cve(vul)
  File "/Users/skill/Desktop/threat-broadcast/src/crawler/alicloud.py", line 69, in to_cve
    exit()
  File "/Applications/Xcode.app/Contents/Developer/Library/Frameworks/Python3.framework/Versions/3.8/lib/python3.8/_sitebuiltins.py", line 26, in __call__
    raise SystemExit(code)
SystemExit: None
2022-02-12 18:12:26 [ERROR] : 获取 [阿里云] 威胁情报异常
Traceback (most recent call last):
  File "/Users/skill/Desktop/threat-broadcast/src/crawler/_base_crawler.py", line 62, in cves
    new_cves = self.get_cves()
  File "/Users/skill/Desktop/threat-broadcast/src/crawler/alicloud.py", line 54, in get_cves
    cve = self.to_cve(vul)
  File "/Users/skill/Desktop/threat-broadcast/src/crawler/alicloud.py", line 69, in to_cve
    exit()
  File "/Applications/Xcode.app/Contents/Developer/Library/Frameworks/Python3.framework/Versions/3.8/lib/python3.8/_sitebuiltins.py", line 26, in __call__
    raise SystemExit(code)
SystemExit: None
2022-02-12 18:12:26 [ERROR] : Traceback (most recent call last):
  File "/Users/skill/Desktop/threat-broadcast/src/crawler/_base_crawler.py", line 62, in cves
    new_cves = self.get_cves()
  File "/Users/skill/Desktop/threat-broadcast/src/crawler/alicloud.py", line 54, in get_cves
    cve = self.to_cve(vul)
  File "/Users/skill/Desktop/threat-broadcast/src/crawler/alicloud.py", line 69, in to_cve
    exit()
  File "/Applications/Xcode.app/Contents/Developer/Library/Frameworks/Python3.framework/Versions/3.8/lib/python3.8/_sitebuiltins.py", line 26, in __call__
    raise SystemExit(code)
SystemExit: None
Traceback (most recent call last):
  File "/Users/skill/Desktop/threat-broadcast/src/crawler/_base_crawler.py", line 62, in cves
    new_cves = self.get_cves()
  File "/Users/skill/Desktop/threat-broadcast/src/crawler/alicloud.py", line 54, in get_cves
    cve = self.to_cve(vul)
  File "/Users/skill/Desktop/threat-broadcast/src/crawler/alicloud.py", line 69, in to_cve
    exit()
  File "/Applications/Xcode.app/Contents/Developer/Library/Frameworks/Python3.framework/Versions/3.8/lib/python3.8/_sitebuiltins.py", line 26, in __call__
    raise SystemExit(code)
SystemExit: None
2022-02-12 18:13:43 [ERROR] : [邮件] 推送威胁情报失败
Traceback (most recent call last):
  File "/Users/skill/Desktop/threat-broadcast/src/notice/mail.py", line 46, in to_mail
    smtpObj.login(sender, password)
  File "/Applications/Xcode.app/Contents/Developer/Library/Frameworks/Python3.framework/Versions/3.8/lib/python3.8/smtplib.py", line 732, in login
    (code, resp) = self.auth(
  File "/Applications/Xcode.app/Contents/Developer/Library/Frameworks/Python3.framework/Versions/3.8/lib/python3.8/smtplib.py", line 645, in auth
    authobject(challenge).encode('ascii'), eol='')
AttributeError: 'NoneType' object has no attribute 'encode'
2022-02-12 18:13:43 [ERROR] : Traceback (most recent call last):
  File "/Users/skill/Desktop/threat-broadcast/src/notice/mail.py", line 46, in to_mail
    smtpObj.login(sender, password)
  File "/Applications/Xcode.app/Contents/Developer/Library/Frameworks/Python3.framework/Versions/3.8/lib/python3.8/smtplib.py", line 732, in login
    (code, resp) = self.auth(
  File "/Applications/Xcode.app/Contents/Developer/Library/Frameworks/Python3.framework/Versions/3.8/lib/python3.8/smtplib.py", line 645, in auth
    authobject(challenge).encode('ascii'), eol='')
AttributeError: 'NoneType' object has no attribute 'encode'
Traceback (most recent call last):
  File "/Users/skill/Desktop/threat-broadcast/src/notice/mail.py", line 46, in to_mail
    smtpObj.login(sender, password)
  File "/Applications/Xcode.app/Contents/Developer/Library/Frameworks/Python3.framework/Versions/3.8/lib/python3.8/smtplib.py", line 732, in login
    (code, resp) = self.auth(
  File "/Applications/Xcode.app/Contents/Developer/Library/Frameworks/Python3.framework/Versions/3.8/lib/python3.8/smtplib.py", line 645, in auth
    authobject(challenge).encode('ascii'), eol='')
AttributeError: 'NoneType' object has no attribute 'encode'
2022-02-12 18:15:53 [ERROR] : [邮件] 推送威胁情报失败
Traceback (most recent call last):
  File "/Users/skill/Desktop/threat-broadcast/src/notice/mail.py", line 46, in to_mail
    smtpObj.login(sender, password)
  File "/Applications/Xcode.app/Contents/Developer/Library/Frameworks/Python3.framework/Versions/3.8/lib/python3.8/smtplib.py", line 732, in login
    (code, resp) = self.auth(
  File "/Applications/Xcode.app/Contents/Developer/Library/Frameworks/Python3.framework/Versions/3.8/lib/python3.8/smtplib.py", line 645, in auth
    authobject(challenge).encode('ascii'), eol='')
AttributeError: 'NoneType' object has no attribute 'encode'
2022-02-12 18:15:53 [ERROR] : Traceback (most recent call last):
  File "/Users/skill/Desktop/threat-broadcast/src/notice/mail.py", line 46, in to_mail
    smtpObj.login(sender, password)
  File "/Applications/Xcode.app/Contents/Developer/Library/Frameworks/Python3.framework/Versions/3.8/lib/python3.8/smtplib.py", line 732, in login
    (code, resp) = self.auth(
  File "/Applications/Xcode.app/Contents/Developer/Library/Frameworks/Python3.framework/Versions/3.8/lib/python3.8/smtplib.py", line 645, in auth
    authobject(challenge).encode('ascii'), eol='')
AttributeError: 'NoneType' object has no attribute 'encode'
Traceback (most recent call last):
  File "/Users/skill/Desktop/threat-broadcast/src/notice/mail.py", line 46, in to_mail
    smtpObj.login(sender, password)
  File "/Applications/Xcode.app/Contents/Developer/Library/Frameworks/Python3.framework/Versions/3.8/lib/python3.8/smtplib.py", line 732, in login
    (code, resp) = self.auth(
  File "/Applications/Xcode.app/Contents/Developer/Library/Frameworks/Python3.framework/Versions/3.8/lib/python3.8/smtplib.py", line 645, in auth
    authobject(challenge).encode('ascii'), eol='')
AttributeError: 'NoneType' object has no attribute 'encode'
2022-02-12 18:18:09 [ERROR] : [邮件] 推送威胁情报失败
Traceback (most recent call last):
  File "/Users/skill/Desktop/threat-broadcast/src/notice/mail.py", line 46, in to_mail
    smtpObj.login(sender, password)
  File "/Applications/Xcode.app/Contents/Developer/Library/Frameworks/Python3.framework/Versions/3.8/lib/python3.8/smtplib.py", line 732, in login
    (code, resp) = self.auth(
  File "/Applications/Xcode.app/Contents/Developer/Library/Frameworks/Python3.framework/Versions/3.8/lib/python3.8/smtplib.py", line 645, in auth
    authobject(challenge).encode('ascii'), eol='')
AttributeError: 'NoneType' object has no attribute 'encode'
2022-02-12 18:18:09 [ERROR] : Traceback (most recent call last):
  File "/Users/skill/Desktop/threat-broadcast/src/notice/mail.py", line 46, in to_mail
    smtpObj.login(sender, password)
  File "/Applications/Xcode.app/Contents/Developer/Library/Frameworks/Python3.framework/Versions/3.8/lib/python3.8/smtplib.py", line 732, in login
    (code, resp) = self.auth(
  File "/Applications/Xcode.app/Contents/Developer/Library/Frameworks/Python3.framework/Versions/3.8/lib/python3.8/smtplib.py", line 645, in auth
    authobject(challenge).encode('ascii'), eol='')
AttributeError: 'NoneType' object has no attribute 'encode'
Traceback (most recent call last):
  File "/Users/skill/Desktop/threat-broadcast/src/notice/mail.py", line 46, in to_mail
    smtpObj.login(sender, password)
  File "/Applications/Xcode.app/Contents/Developer/Library/Frameworks/Python3.framework/Versions/3.8/lib/python3.8/smtplib.py", line 732, in login
    (code, resp) = self.auth(
  File "/Applications/Xcode.app/Contents/Developer/Library/Frameworks/Python3.framework/Versions/3.8/lib/python3.8/smtplib.py", line 645, in auth
    authobject(challenge).encode('ascii'), eol='')
AttributeError: 'NoneType' object has no attribute 'encode'
2022-02-12 18:19:16 [ERROR] : [邮件] 推送威胁情报失败
Traceback (most recent call last):
  File "/Users/skill/Desktop/threat-broadcast/src/notice/mail.py", line 46, in to_mail
    smtpObj.login(sender, password)
  File "/Applications/Xcode.app/Contents/Developer/Library/Frameworks/Python3.framework/Versions/3.8/lib/python3.8/smtplib.py", line 732, in login
    (code, resp) = self.auth(
  File "/Applications/Xcode.app/Contents/Developer/Library/Frameworks/Python3.framework/Versions/3.8/lib/python3.8/smtplib.py", line 645, in auth
    authobject(challenge).encode('ascii'), eol='')
AttributeError: 'NoneType' object has no attribute 'encode'
2022-02-12 18:19:16 [ERROR] : Traceback (most recent call last):
  File "/Users/skill/Desktop/threat-broadcast/src/notice/mail.py", line 46, in to_mail
    smtpObj.login(sender, password)
  File "/Applications/Xcode.app/Contents/Developer/Library/Frameworks/Python3.framework/Versions/3.8/lib/python3.8/smtplib.py", line 732, in login
    (code, resp) = self.auth(
  File "/Applications/Xcode.app/Contents/Developer/Library/Frameworks/Python3.framework/Versions/3.8/lib/python3.8/smtplib.py", line 645, in auth
    authobject(challenge).encode('ascii'), eol='')
AttributeError: 'NoneType' object has no attribute 'encode'
Traceback (most recent call last):
  File "/Users/skill/Desktop/threat-broadcast/src/notice/mail.py", line 46, in to_mail
    smtpObj.login(sender, password)
  File "/Applications/Xcode.app/Contents/Developer/Library/Frameworks/Python3.framework/Versions/3.8/lib/python3.8/smtplib.py", line 732, in login
    (code, resp) = self.auth(
  File "/Applications/Xcode.app/Contents/Developer/Library/Frameworks/Python3.framework/Versions/3.8/lib/python3.8/smtplib.py", line 645, in auth
    authobject(challenge).encode('ascii'), eol='')
AttributeError: 'NoneType' object has no attribute 'encode'
2022-02-12 18:19:58 [ERROR] : 获取 [阿里云] 威胁情报异常
Traceback (most recent call last):
  File "/Users/skill/Desktop/threat-broadcast/src/crawler/_base_crawler.py", line 62, in cves
    new_cves = self.get_cves()
  File "/Users/skill/Desktop/threat-broadcast/src/crawler/alicloud.py", line 55, in get_cves
    cve = self.to_cve(vul)
  File "/Users/skill/Desktop/threat-broadcast/src/crawler/alicloud.py", line 79, in to_cve
    cve.time = rst[1] + time.strftime(" %H:%M:%S", time.localtime())
IndexError: list index out of range
2022-02-12 18:19:58 [ERROR] : Traceback (most recent call last):
  File "/Users/skill/Desktop/threat-broadcast/src/crawler/_base_crawler.py", line 62, in cves
    new_cves = self.get_cves()
  File "/Users/skill/Desktop/threat-broadcast/src/crawler/alicloud.py", line 55, in get_cves
    cve = self.to_cve(vul)
  File "/Users/skill/Desktop/threat-broadcast/src/crawler/alicloud.py", line 79, in to_cve
    cve.time = rst[1] + time.strftime(" %H:%M:%S", time.localtime())
IndexError: list index out of range
Traceback (most recent call last):
  File "/Users/skill/Desktop/threat-broadcast/src/crawler/_base_crawler.py", line 62, in cves
    new_cves = self.get_cves()
  File "/Users/skill/Desktop/threat-broadcast/src/crawler/alicloud.py", line 55, in get_cves
    cve = self.to_cve(vul)
  File "/Users/skill/Desktop/threat-broadcast/src/crawler/alicloud.py", line 79, in to_cve
    cve.time = rst[1] + time.strftime(" %H:%M:%S", time.localtime())
IndexError: list index out of range
2022-02-12 18:20:07 [ERROR] : 获取 [阿里云] 威胁情报异常
Traceback (most recent call last):
  File "/Users/skill/Desktop/threat-broadcast/src/crawler/_base_crawler.py", line 62, in cves
    new_cves = self.get_cves()
  File "/Users/skill/Desktop/threat-broadcast/src/crawler/alicloud.py", line 55, in get_cves
    cve = self.to_cve(vul)
  File "/Users/skill/Desktop/threat-broadcast/src/crawler/alicloud.py", line 79, in to_cve
    cve.time = rst[1] + time.strftime(" %H:%M:%S", time.localtime())
IndexError: list index out of range
2022-02-12 18:20:07 [ERROR] : Traceback (most recent call last):
  File "/Users/skill/Desktop/threat-broadcast/src/crawler/_base_crawler.py", line 62, in cves
    new_cves = self.get_cves()
  File "/Users/skill/Desktop/threat-broadcast/src/crawler/alicloud.py", line 55, in get_cves
    cve = self.to_cve(vul)
  File "/Users/skill/Desktop/threat-broadcast/src/crawler/alicloud.py", line 79, in to_cve
    cve.time = rst[1] + time.strftime(" %H:%M:%S", time.localtime())
IndexError: list index out of range
Traceback (most recent call last):
  File "/Users/skill/Desktop/threat-broadcast/src/crawler/_base_crawler.py", line 62, in cves
    new_cves = self.get_cves()
  File "/Users/skill/Desktop/threat-broadcast/src/crawler/alicloud.py", line 55, in get_cves
    cve = self.to_cve(vul)
  File "/Users/skill/Desktop/threat-broadcast/src/crawler/alicloud.py", line 79, in to_cve
    cve.time = rst[1] + time.strftime(" %H:%M:%S", time.localtime())
IndexError: list index out of range
2022-02-12 18:20:31 [ERROR] : 获取 [阿里云] 威胁情报异常
Traceback (most recent call last):
  File "/Users/skill/Desktop/threat-broadcast/src/crawler/_base_crawler.py", line 62, in cves
    new_cves = self.get_cves()
  File "/Users/skill/Desktop/threat-broadcast/src/crawler/alicloud.py", line 55, in get_cves
    cve = self.to_cve(vul)
  File "/Users/skill/Desktop/threat-broadcast/src/crawler/alicloud.py", line 80, in to_cve
    cve.time = rst[1] + time.strftime(" %H:%M:%S", time.localtime())
IndexError: list index out of range
2022-02-12 18:20:31 [ERROR] : Traceback (most recent call last):
  File "/Users/skill/Desktop/threat-broadcast/src/crawler/_base_crawler.py", line 62, in cves
    new_cves = self.get_cves()
  File "/Users/skill/Desktop/threat-broadcast/src/crawler/alicloud.py", line 55, in get_cves
    cve = self.to_cve(vul)
  File "/Users/skill/Desktop/threat-broadcast/src/crawler/alicloud.py", line 80, in to_cve
    cve.time = rst[1] + time.strftime(" %H:%M:%S", time.localtime())
IndexError: list index out of range
Traceback (most recent call last):
  File "/Users/skill/Desktop/threat-broadcast/src/crawler/_base_crawler.py", line 62, in cves
    new_cves = self.get_cves()
  File "/Users/skill/Desktop/threat-broadcast/src/crawler/alicloud.py", line 55, in get_cves
    cve = self.to_cve(vul)
  File "/Users/skill/Desktop/threat-broadcast/src/crawler/alicloud.py", line 80, in to_cve
    cve.time = rst[1] + time.strftime(" %H:%M:%S", time.localtime())
IndexError: list index out of range
2022-02-12 18:20:54 [ERROR] : [邮件] 推送威胁情报失败
Traceback (most recent call last):
  File "/Users/skill/Desktop/threat-broadcast/src/notice/mail.py", line 46, in to_mail
    smtpObj.login(sender, password)
  File "/Applications/Xcode.app/Contents/Developer/Library/Frameworks/Python3.framework/Versions/3.8/lib/python3.8/smtplib.py", line 732, in login
    (code, resp) = self.auth(
  File "/Applications/Xcode.app/Contents/Developer/Library/Frameworks/Python3.framework/Versions/3.8/lib/python3.8/smtplib.py", line 645, in auth
    authobject(challenge).encode('ascii'), eol='')
AttributeError: 'NoneType' object has no attribute 'encode'
2022-02-12 18:20:54 [ERROR] : Traceback (most recent call last):
  File "/Users/skill/Desktop/threat-broadcast/src/notice/mail.py", line 46, in to_mail
    smtpObj.login(sender, password)
  File "/Applications/Xcode.app/Contents/Developer/Library/Frameworks/Python3.framework/Versions/3.8/lib/python3.8/smtplib.py", line 732, in login
    (code, resp) = self.auth(
  File "/Applications/Xcode.app/Contents/Developer/Library/Frameworks/Python3.framework/Versions/3.8/lib/python3.8/smtplib.py", line 645, in auth
    authobject(challenge).encode('ascii'), eol='')
AttributeError: 'NoneType' object has no attribute 'encode'
Traceback (most recent call last):
  File "/Users/skill/Desktop/threat-broadcast/src/notice/mail.py", line 46, in to_mail
    smtpObj.login(sender, password)
  File "/Applications/Xcode.app/Contents/Developer/Library/Frameworks/Python3.framework/Versions/3.8/lib/python3.8/smtplib.py", line 732, in login
    (code, resp) = self.auth(
  File "/Applications/Xcode.app/Contents/Developer/Library/Frameworks/Python3.framework/Versions/3.8/lib/python3.8/smtplib.py", line 645, in auth
    authobject(challenge).encode('ascii'), eol='')
AttributeError: 'NoneType' object has no attribute 'encode'
2022-02-12 18:25:23 [ERROR] : [邮件] 推送威胁情报失败
Traceback (most recent call last):
  File "/Users/skill/Desktop/threat-broadcast/src/notice/mail.py", line 46, in to_mail
    smtpObj.login(sender, password)
  File "/Applications/Xcode.app/Contents/Developer/Library/Frameworks/Python3.framework/Versions/3.8/lib/python3.8/smtplib.py", line 732, in login
    (code, resp) = self.auth(
  File "/Applications/Xcode.app/Contents/Developer/Library/Frameworks/Python3.framework/Versions/3.8/lib/python3.8/smtplib.py", line 645, in auth
    authobject(challenge).encode('ascii'), eol='')
AttributeError: 'NoneType' object has no attribute 'encode'
2022-02-12 18:25:23 [ERROR] : Traceback (most recent call last):
  File "/Users/skill/Desktop/threat-broadcast/src/notice/mail.py", line 46, in to_mail
    smtpObj.login(sender, password)
  File "/Applications/Xcode.app/Contents/Developer/Library/Frameworks/Python3.framework/Versions/3.8/lib/python3.8/smtplib.py", line 732, in login
    (code, resp) = self.auth(
  File "/Applications/Xcode.app/Contents/Developer/Library/Frameworks/Python3.framework/Versions/3.8/lib/python3.8/smtplib.py", line 645, in auth
    authobject(challenge).encode('ascii'), eol='')
AttributeError: 'NoneType' object has no attribute 'encode'
Traceback (most recent call last):
  File "/Users/skill/Desktop/threat-broadcast/src/notice/mail.py", line 46, in to_mail
    smtpObj.login(sender, password)
  File "/Applications/Xcode.app/Contents/Developer/Library/Frameworks/Python3.framework/Versions/3.8/lib/python3.8/smtplib.py", line 732, in login
    (code, resp) = self.auth(
  File "/Applications/Xcode.app/Contents/Developer/Library/Frameworks/Python3.framework/Versions/3.8/lib/python3.8/smtplib.py", line 645, in auth
    authobject(challenge).encode('ascii'), eol='')
AttributeError: 'NoneType' object has no attribute 'encode'
2022-02-12 18:25:49 [ERROR] : [邮件] 推送威胁情报失败
Traceback (most recent call last):
  File "/Users/skill/Desktop/threat-broadcast/src/notice/mail.py", line 46, in to_mail
    smtpObj.login(sender, password)
  File "/Applications/Xcode.app/Contents/Developer/Library/Frameworks/Python3.framework/Versions/3.8/lib/python3.8/smtplib.py", line 732, in login
    (code, resp) = self.auth(
  File "/Applications/Xcode.app/Contents/Developer/Library/Frameworks/Python3.framework/Versions/3.8/lib/python3.8/smtplib.py", line 645, in auth
    authobject(challenge).encode('ascii'), eol='')
AttributeError: 'NoneType' object has no attribute 'encode'
2022-02-12 18:25:49 [ERROR] : Traceback (most recent call last):
  File "/Users/skill/Desktop/threat-broadcast/src/notice/mail.py", line 46, in to_mail
    smtpObj.login(sender, password)
  File "/Applications/Xcode.app/Contents/Developer/Library/Frameworks/Python3.framework/Versions/3.8/lib/python3.8/smtplib.py", line 732, in login
    (code, resp) = self.auth(
  File "/Applications/Xcode.app/Contents/Developer/Library/Frameworks/Python3.framework/Versions/3.8/lib/python3.8/smtplib.py", line 645, in auth
    authobject(challenge).encode('ascii'), eol='')
AttributeError: 'NoneType' object has no attribute 'encode'
Traceback (most recent call last):
  File "/Users/skill/Desktop/threat-broadcast/src/notice/mail.py", line 46, in to_mail
    smtpObj.login(sender, password)
  File "/Applications/Xcode.app/Contents/Developer/Library/Frameworks/Python3.framework/Versions/3.8/lib/python3.8/smtplib.py", line 732, in login
    (code, resp) = self.auth(
  File "/Applications/Xcode.app/Contents/Developer/Library/Frameworks/Python3.framework/Versions/3.8/lib/python3.8/smtplib.py", line 645, in auth
    authobject(challenge).encode('ascii'), eol='')
AttributeError: 'NoneType' object has no attribute 'encode'
2022-02-12 18:28:02 [ERROR] : [邮件] 推送威胁情报失败
Traceback (most recent call last):
  File "/Users/skill/Desktop/threat-broadcast/src/notice/mail.py", line 46, in to_mail
    smtpObj.login(sender, password)
  File "/Applications/Xcode.app/Contents/Developer/Library/Frameworks/Python3.framework/Versions/3.8/lib/python3.8/smtplib.py", line 732, in login
    (code, resp) = self.auth(
  File "/Applications/Xcode.app/Contents/Developer/Library/Frameworks/Python3.framework/Versions/3.8/lib/python3.8/smtplib.py", line 645, in auth
    authobject(challenge).encode('ascii'), eol='')
AttributeError: 'NoneType' object has no attribute 'encode'
2022-02-12 18:28:02 [ERROR] : Traceback (most recent call last):
  File "/Users/skill/Desktop/threat-broadcast/src/notice/mail.py", line 46, in to_mail
    smtpObj.login(sender, password)
  File "/Applications/Xcode.app/Contents/Developer/Library/Frameworks/Python3.framework/Versions/3.8/lib/python3.8/smtplib.py", line 732, in login
    (code, resp) = self.auth(
  File "/Applications/Xcode.app/Contents/Developer/Library/Frameworks/Python3.framework/Versions/3.8/lib/python3.8/smtplib.py", line 645, in auth
    authobject(challenge).encode('ascii'), eol='')
AttributeError: 'NoneType' object has no attribute 'encode'
Traceback (most recent call last):
  File "/Users/skill/Desktop/threat-broadcast/src/notice/mail.py", line 46, in to_mail
    smtpObj.login(sender, password)
  File "/Applications/Xcode.app/Contents/Developer/Library/Frameworks/Python3.framework/Versions/3.8/lib/python3.8/smtplib.py", line 732, in login
    (code, resp) = self.auth(
  File "/Applications/Xcode.app/Contents/Developer/Library/Frameworks/Python3.framework/Versions/3.8/lib/python3.8/smtplib.py", line 645, in auth
    authobject(challenge).encode('ascii'), eol='')
AttributeError: 'NoneType' object has no attribute 'encode'
2022-02-12 18:29:28 [ERROR] : [邮件] 推送威胁情报失败
Traceback (most recent call last):
  File "/Users/skill/Desktop/threat-broadcast/src/notice/mail.py", line 46, in to_mail
    smtpObj.login(sender, password)
  File "/Applications/Xcode.app/Contents/Developer/Library/Frameworks/Python3.framework/Versions/3.8/lib/python3.8/smtplib.py", line 732, in login
    (code, resp) = self.auth(
  File "/Applications/Xcode.app/Contents/Developer/Library/Frameworks/Python3.framework/Versions/3.8/lib/python3.8/smtplib.py", line 645, in auth
    authobject(challenge).encode('ascii'), eol='')
AttributeError: 'NoneType' object has no attribute 'encode'
2022-02-12 18:29:28 [ERROR] : Traceback (most recent call last):
  File "/Users/skill/Desktop/threat-broadcast/src/notice/mail.py", line 46, in to_mail
    smtpObj.login(sender, password)
  File "/Applications/Xcode.app/Contents/Developer/Library/Frameworks/Python3.framework/Versions/3.8/lib/python3.8/smtplib.py", line 732, in login
    (code, resp) = self.auth(
  File "/Applications/Xcode.app/Contents/Developer/Library/Frameworks/Python3.framework/Versions/3.8/lib/python3.8/smtplib.py", line 645, in auth
    authobject(challenge).encode('ascii'), eol='')
AttributeError: 'NoneType' object has no attribute 'encode'
Traceback (most recent call last):
  File "/Users/skill/Desktop/threat-broadcast/src/notice/mail.py", line 46, in to_mail
    smtpObj.login(sender, password)
  File "/Applications/Xcode.app/Contents/Developer/Library/Frameworks/Python3.framework/Versions/3.8/lib/python3.8/smtplib.py", line 732, in login
    (code, resp) = self.auth(
  File "/Applications/Xcode.app/Contents/Developer/Library/Frameworks/Python3.framework/Versions/3.8/lib/python3.8/smtplib.py", line 645, in auth
    authobject(challenge).encode('ascii'), eol='')
AttributeError: 'NoneType' object has no attribute 'encode'
2022-02-12 18:31:21 [ERROR] : [邮件] 推送威胁情报失败
Traceback (most recent call last):
  File "/Users/skill/Desktop/threat-broadcast/src/notice/mail.py", line 46, in to_mail
    smtpObj.login(sender, password)
  File "/Applications/Xcode.app/Contents/Developer/Library/Frameworks/Python3.framework/Versions/3.8/lib/python3.8/smtplib.py", line 732, in login
    (code, resp) = self.auth(
  File "/Applications/Xcode.app/Contents/Developer/Library/Frameworks/Python3.framework/Versions/3.8/lib/python3.8/smtplib.py", line 645, in auth
    authobject(challenge).encode('ascii'), eol='')
AttributeError: 'NoneType' object has no attribute 'encode'
2022-02-12 18:31:21 [ERROR] : Traceback (most recent call last):
  File "/Users/skill/Desktop/threat-broadcast/src/notice/mail.py", line 46, in to_mail
    smtpObj.login(sender, password)
  File "/Applications/Xcode.app/Contents/Developer/Library/Frameworks/Python3.framework/Versions/3.8/lib/python3.8/smtplib.py", line 732, in login
    (code, resp) = self.auth(
  File "/Applications/Xcode.app/Contents/Developer/Library/Frameworks/Python3.framework/Versions/3.8/lib/python3.8/smtplib.py", line 645, in auth
    authobject(challenge).encode('ascii'), eol='')
AttributeError: 'NoneType' object has no attribute 'encode'
Traceback (most recent call last):
  File "/Users/skill/Desktop/threat-broadcast/src/notice/mail.py", line 46, in to_mail
    smtpObj.login(sender, password)
  File "/Applications/Xcode.app/Contents/Developer/Library/Frameworks/Python3.framework/Versions/3.8/lib/python3.8/smtplib.py", line 732, in login
    (code, resp) = self.auth(
  File "/Applications/Xcode.app/Contents/Developer/Library/Frameworks/Python3.framework/Versions/3.8/lib/python3.8/smtplib.py", line 645, in auth
    authobject(challenge).encode('ascii'), eol='')
AttributeError: 'NoneType' object has no attribute 'encode'
2022-02-12 18:44:26 [ERROR] : [邮件] 推送威胁情报失败
Traceback (most recent call last):
  File "/Users/skill/Desktop/threat-broadcast/src/notice/mail.py", line 46, in to_mail
    smtpObj.login(sender, password)
  File "/Applications/Xcode.app/Contents/Developer/Library/Frameworks/Python3.framework/Versions/3.8/lib/python3.8/smtplib.py", line 732, in login
    (code, resp) = self.auth(
  File "/Applications/Xcode.app/Contents/Developer/Library/Frameworks/Python3.framework/Versions/3.8/lib/python3.8/smtplib.py", line 645, in auth
    authobject(challenge).encode('ascii'), eol='')
AttributeError: 'NoneType' object has no attribute 'encode'
2022-02-12 18:44:26 [ERROR] : Traceback (most recent call last):
  File "/Users/skill/Desktop/threat-broadcast/src/notice/mail.py", line 46, in to_mail
    smtpObj.login(sender, password)
  File "/Applications/Xcode.app/Contents/Developer/Library/Frameworks/Python3.framework/Versions/3.8/lib/python3.8/smtplib.py", line 732, in login
    (code, resp) = self.auth(
  File "/Applications/Xcode.app/Contents/Developer/Library/Frameworks/Python3.framework/Versions/3.8/lib/python3.8/smtplib.py", line 645, in auth
    authobject(challenge).encode('ascii'), eol='')
AttributeError: 'NoneType' object has no attribute 'encode'
Traceback (most recent call last):
  File "/Users/skill/Desktop/threat-broadcast/src/notice/mail.py", line 46, in to_mail
    smtpObj.login(sender, password)
  File "/Applications/Xcode.app/Contents/Developer/Library/Frameworks/Python3.framework/Versions/3.8/lib/python3.8/smtplib.py", line 732, in login
    (code, resp) = self.auth(
  File "/Applications/Xcode.app/Contents/Developer/Library/Frameworks/Python3.framework/Versions/3.8/lib/python3.8/smtplib.py", line 645, in auth
    authobject(challenge).encode('ascii'), eol='')
AttributeError: 'NoneType' object has no attribute 'encode'
2022-02-12 18:44:52 [ERROR] : [邮件] 推送威胁情报失败
Traceback (most recent call last):
  File "/Users/skill/Desktop/threat-broadcast/src/notice/mail.py", line 46, in to_mail
    smtpObj.login(sender, password)
  File "/Applications/Xcode.app/Contents/Developer/Library/Frameworks/Python3.framework/Versions/3.8/lib/python3.8/smtplib.py", line 732, in login
    (code, resp) = self.auth(
  File "/Applications/Xcode.app/Contents/Developer/Library/Frameworks/Python3.framework/Versions/3.8/lib/python3.8/smtplib.py", line 645, in auth
    authobject(challenge).encode('ascii'), eol='')
AttributeError: 'NoneType' object has no attribute 'encode'
2022-02-12 18:44:52 [ERROR] : Traceback (most recent call last):
  File "/Users/skill/Desktop/threat-broadcast/src/notice/mail.py", line 46, in to_mail
    smtpObj.login(sender, password)
  File "/Applications/Xcode.app/Contents/Developer/Library/Frameworks/Python3.framework/Versions/3.8/lib/python3.8/smtplib.py", line 732, in login
    (code, resp) = self.auth(
  File "/Applications/Xcode.app/Contents/Developer/Library/Frameworks/Python3.framework/Versions/3.8/lib/python3.8/smtplib.py", line 645, in auth
    authobject(challenge).encode('ascii'), eol='')
AttributeError: 'NoneType' object has no attribute 'encode'
Traceback (most recent call last):
  File "/Users/skill/Desktop/threat-broadcast/src/notice/mail.py", line 46, in to_mail
    smtpObj.login(sender, password)
  File "/Applications/Xcode.app/Contents/Developer/Library/Frameworks/Python3.framework/Versions/3.8/lib/python3.8/smtplib.py", line 732, in login
    (code, resp) = self.auth(
  File "/Applications/Xcode.app/Contents/Developer/Library/Frameworks/Python3.framework/Versions/3.8/lib/python3.8/smtplib.py", line 645, in auth
    authobject(challenge).encode('ascii'), eol='')
AttributeError: 'NoneType' object has no attribute 'encode'
2022-02-12 18:45:13 [ERROR] : [邮件] 推送威胁情报失败
Traceback (most recent call last):
  File "/Users/skill/Desktop/threat-broadcast/src/notice/mail.py", line 46, in to_mail
    smtpObj.login(sender, password)
  File "/Applications/Xcode.app/Contents/Developer/Library/Frameworks/Python3.framework/Versions/3.8/lib/python3.8/smtplib.py", line 732, in login
    (code, resp) = self.auth(
  File "/Applications/Xcode.app/Contents/Developer/Library/Frameworks/Python3.framework/Versions/3.8/lib/python3.8/smtplib.py", line 645, in auth
    authobject(challenge).encode('ascii'), eol='')
AttributeError: 'NoneType' object has no attribute 'encode'
2022-02-12 18:45:13 [ERROR] : Traceback (most recent call last):
  File "/Users/skill/Desktop/threat-broadcast/src/notice/mail.py", line 46, in to_mail
    smtpObj.login(sender, password)
  File "/Applications/Xcode.app/Contents/Developer/Library/Frameworks/Python3.framework/Versions/3.8/lib/python3.8/smtplib.py", line 732, in login
    (code, resp) = self.auth(
  File "/Applications/Xcode.app/Contents/Developer/Library/Frameworks/Python3.framework/Versions/3.8/lib/python3.8/smtplib.py", line 645, in auth
    authobject(challenge).encode('ascii'), eol='')
AttributeError: 'NoneType' object has no attribute 'encode'
Traceback (most recent call last):
  File "/Users/skill/Desktop/threat-broadcast/src/notice/mail.py", line 46, in to_mail
    smtpObj.login(sender, password)
  File "/Applications/Xcode.app/Contents/Developer/Library/Frameworks/Python3.framework/Versions/3.8/lib/python3.8/smtplib.py", line 732, in login
    (code, resp) = self.auth(
  File "/Applications/Xcode.app/Contents/Developer/Library/Frameworks/Python3.framework/Versions/3.8/lib/python3.8/smtplib.py", line 645, in auth
    authobject(challenge).encode('ascii'), eol='')
AttributeError: 'NoneType' object has no attribute 'encode'
2022-02-12 18:46:01 [ERROR] : [邮件] 推送威胁情报失败
Traceback (most recent call last):
  File "/Users/skill/Desktop/threat-broadcast/src/notice/mail.py", line 46, in to_mail
    smtpObj.login(sender, password)
  File "/Applications/Xcode.app/Contents/Developer/Library/Frameworks/Python3.framework/Versions/3.8/lib/python3.8/smtplib.py", line 732, in login
    (code, resp) = self.auth(
  File "/Applications/Xcode.app/Contents/Developer/Library/Frameworks/Python3.framework/Versions/3.8/lib/python3.8/smtplib.py", line 645, in auth
    authobject(challenge).encode('ascii'), eol='')
AttributeError: 'NoneType' object has no attribute 'encode'
2022-02-12 18:46:01 [ERROR] : Traceback (most recent call last):
  File "/Users/skill/Desktop/threat-broadcast/src/notice/mail.py", line 46, in to_mail
    smtpObj.login(sender, password)
  File "/Applications/Xcode.app/Contents/Developer/Library/Frameworks/Python3.framework/Versions/3.8/lib/python3.8/smtplib.py", line 732, in login
    (code, resp) = self.auth(
  File "/Applications/Xcode.app/Contents/Developer/Library/Frameworks/Python3.framework/Versions/3.8/lib/python3.8/smtplib.py", line 645, in auth
    authobject(challenge).encode('ascii'), eol='')
AttributeError: 'NoneType' object has no attribute 'encode'
Traceback (most recent call last):
  File "/Users/skill/Desktop/threat-broadcast/src/notice/mail.py", line 46, in to_mail
    smtpObj.login(sender, password)
  File "/Applications/Xcode.app/Contents/Developer/Library/Frameworks/Python3.framework/Versions/3.8/lib/python3.8/smtplib.py", line 732, in login
    (code, resp) = self.auth(
  File "/Applications/Xcode.app/Contents/Developer/Library/Frameworks/Python3.framework/Versions/3.8/lib/python3.8/smtplib.py", line 645, in auth
    authobject(challenge).encode('ascii'), eol='')
AttributeError: 'NoneType' object has no attribute 'encode'
2022-02-12 18:47:47 [ERROR] : [邮件] 推送威胁情报失败
Traceback (most recent call last):
  File "/Users/skill/Desktop/threat-broadcast/src/notice/mail.py", line 46, in to_mail
    smtpObj.login(sender, password)
  File "/Applications/Xcode.app/Contents/Developer/Library/Frameworks/Python3.framework/Versions/3.8/lib/python3.8/smtplib.py", line 732, in login
    (code, resp) = self.auth(
  File "/Applications/Xcode.app/Contents/Developer/Library/Frameworks/Python3.framework/Versions/3.8/lib/python3.8/smtplib.py", line 645, in auth
    authobject(challenge).encode('ascii'), eol='')
AttributeError: 'NoneType' object has no attribute 'encode'
2022-02-12 18:47:47 [ERROR] : Traceback (most recent call last):
  File "/Users/skill/Desktop/threat-broadcast/src/notice/mail.py", line 46, in to_mail
    smtpObj.login(sender, password)
  File "/Applications/Xcode.app/Contents/Developer/Library/Frameworks/Python3.framework/Versions/3.8/lib/python3.8/smtplib.py", line 732, in login
    (code, resp) = self.auth(
  File "/Applications/Xcode.app/Contents/Developer/Library/Frameworks/Python3.framework/Versions/3.8/lib/python3.8/smtplib.py", line 645, in auth
    authobject(challenge).encode('ascii'), eol='')
AttributeError: 'NoneType' object has no attribute 'encode'
Traceback (most recent call last):
  File "/Users/skill/Desktop/threat-broadcast/src/notice/mail.py", line 46, in to_mail
    smtpObj.login(sender, password)
  File "/Applications/Xcode.app/Contents/Developer/Library/Frameworks/Python3.framework/Versions/3.8/lib/python3.8/smtplib.py", line 732, in login
    (code, resp) = self.auth(
  File "/Applications/Xcode.app/Contents/Developer/Library/Frameworks/Python3.framework/Versions/3.8/lib/python3.8/smtplib.py", line 645, in auth
    authobject(challenge).encode('ascii'), eol='')
AttributeError: 'NoneType' object has no attribute 'encode'
2022-02-12 18:48:52 [ERROR] : [邮件] 推送威胁情报失败
Traceback (most recent call last):
  File "/Users/skill/Desktop/threat-broadcast/src/notice/mail.py", line 46, in to_mail
    smtpObj.login(sender, password)
  File "/Applications/Xcode.app/Contents/Developer/Library/Frameworks/Python3.framework/Versions/3.8/lib/python3.8/smtplib.py", line 732, in login
    (code, resp) = self.auth(
  File "/Applications/Xcode.app/Contents/Developer/Library/Frameworks/Python3.framework/Versions/3.8/lib/python3.8/smtplib.py", line 645, in auth
    authobject(challenge).encode('ascii'), eol='')
AttributeError: 'NoneType' object has no attribute 'encode'
2022-02-12 18:48:52 [ERROR] : Traceback (most recent call last):
  File "/Users/skill/Desktop/threat-broadcast/src/notice/mail.py", line 46, in to_mail
    smtpObj.login(sender, password)
  File "/Applications/Xcode.app/Contents/Developer/Library/Frameworks/Python3.framework/Versions/3.8/lib/python3.8/smtplib.py", line 732, in login
    (code, resp) = self.auth(
  File "/Applications/Xcode.app/Contents/Developer/Library/Frameworks/Python3.framework/Versions/3.8/lib/python3.8/smtplib.py", line 645, in auth
    authobject(challenge).encode('ascii'), eol='')
AttributeError: 'NoneType' object has no attribute 'encode'
Traceback (most recent call last):
  File "/Users/skill/Desktop/threat-broadcast/src/notice/mail.py", line 46, in to_mail
    smtpObj.login(sender, password)
  File "/Applications/Xcode.app/Contents/Developer/Library/Frameworks/Python3.framework/Versions/3.8/lib/python3.8/smtplib.py", line 732, in login
    (code, resp) = self.auth(
  File "/Applications/Xcode.app/Contents/Developer/Library/Frameworks/Python3.framework/Versions/3.8/lib/python3.8/smtplib.py", line 645, in auth
    authobject(challenge).encode('ascii'), eol='')
AttributeError: 'NoneType' object has no attribute 'encode'
