2022-02-21 07:38:00 [ERROR] : 获取 [国家信息安全漏洞共享平台（CNVD）] 威胁情报异常
Traceback (most recent call last):
  File "/opt/hostedtoolcache/Python/3.8.12/x64/lib/python3.8/site-packages/urllib3/connectionpool.py", line 426, in _make_request
    six.raise_from(e, None)
  File "<string>", line 3, in raise_from
  File "/opt/hostedtoolcache/Python/3.8.12/x64/lib/python3.8/site-packages/urllib3/connectionpool.py", line 421, in _make_request
    httplib_response = conn.getresponse()
  File "/opt/hostedtoolcache/Python/3.8.12/x64/lib/python3.8/http/client.py", line 1348, in getresponse
    response.begin()
  File "/opt/hostedtoolcache/Python/3.8.12/x64/lib/python3.8/http/client.py", line 316, in begin
    version, status, reason = self._read_status()
  File "/opt/hostedtoolcache/Python/3.8.12/x64/lib/python3.8/http/client.py", line 277, in _read_status
    line = str(self.fp.readline(_MAXLINE + 1), "iso-8859-1")
  File "/opt/hostedtoolcache/Python/3.8.12/x64/lib/python3.8/socket.py", line 669, in readinto
    return self._sock.recv_into(b)
  File "/opt/hostedtoolcache/Python/3.8.12/x64/lib/python3.8/ssl.py", line 1241, in recv_into
    return self.read(nbytes, buffer)
  File "/opt/hostedtoolcache/Python/3.8.12/x64/lib/python3.8/ssl.py", line 1099, in read
    return self._sslobj.read(len, buffer)
socket.timeout: The read operation timed out

During handling of the above exception, another exception occurred:

Traceback (most recent call last):
  File "/opt/hostedtoolcache/Python/3.8.12/x64/lib/python3.8/site-packages/requests/adapters.py", line 439, in send
    resp = conn.urlopen(
  File "/opt/hostedtoolcache/Python/3.8.12/x64/lib/python3.8/site-packages/urllib3/connectionpool.py", line 726, in urlopen
    retries = retries.increment(
  File "/opt/hostedtoolcache/Python/3.8.12/x64/lib/python3.8/site-packages/urllib3/util/retry.py", line 410, in increment
    raise six.reraise(type(error), error, _stacktrace)
  File "/opt/hostedtoolcache/Python/3.8.12/x64/lib/python3.8/site-packages/urllib3/packages/six.py", line 735, in reraise
    raise value
  File "/opt/hostedtoolcache/Python/3.8.12/x64/lib/python3.8/site-packages/urllib3/connectionpool.py", line 670, in urlopen
    httplib_response = self._make_request(
  File "/opt/hostedtoolcache/Python/3.8.12/x64/lib/python3.8/site-packages/urllib3/connectionpool.py", line 428, in _make_request
    self._raise_timeout(err=e, url=url, timeout_value=read_timeout)
  File "/opt/hostedtoolcache/Python/3.8.12/x64/lib/python3.8/site-packages/urllib3/connectionpool.py", line 335, in _raise_timeout
    raise ReadTimeoutError(
urllib3.exceptions.ReadTimeoutError: HTTPSConnectionPool(host='www.cnvd.org.cn', port=443): Read timed out. (read timeout=60)

During handling of the above exception, another exception occurred:

Traceback (most recent call last):
  File "/home/runner/work/threat-broadcast/threat-broadcast/src/crawler/_base_crawler.py", line 62, in cves
    new_cves = self.get_cves()
  File "/home/runner/work/threat-broadcast/threat-broadcast/src/crawler/cnvd.py", line 117, in get_cves
    response = self.session.get(
  File "/opt/hostedtoolcache/Python/3.8.12/x64/lib/python3.8/site-packages/requests/sessions.py", line 546, in get
    return self.request('GET', url, **kwargs)
  File "/opt/hostedtoolcache/Python/3.8.12/x64/lib/python3.8/site-packages/requests/sessions.py", line 533, in request
    resp = self.send(prep, **send_kwargs)
  File "/opt/hostedtoolcache/Python/3.8.12/x64/lib/python3.8/site-packages/requests/sessions.py", line 646, in send
    r = adapter.send(request, **kwargs)
  File "/opt/hostedtoolcache/Python/3.8.12/x64/lib/python3.8/site-packages/requests/adapters.py", line 529, in send
    raise ReadTimeout(e, request=request)
requests.exceptions.ReadTimeout: HTTPSConnectionPool(host='www.cnvd.org.cn', port=443): Read timed out. (read timeout=60)
2022-02-21 07:38:00 [ERROR] : Traceback (most recent call last):
  File "/opt/hostedtoolcache/Python/3.8.12/x64/lib/python3.8/site-packages/urllib3/connectionpool.py", line 426, in _make_request
    six.raise_from(e, None)
  File "<string>", line 3, in raise_from
  File "/opt/hostedtoolcache/Python/3.8.12/x64/lib/python3.8/site-packages/urllib3/connectionpool.py", line 421, in _make_request
    httplib_response = conn.getresponse()
  File "/opt/hostedtoolcache/Python/3.8.12/x64/lib/python3.8/http/client.py", line 1348, in getresponse
    response.begin()
  File "/opt/hostedtoolcache/Python/3.8.12/x64/lib/python3.8/http/client.py", line 316, in begin
    version, status, reason = self._read_status()
  File "/opt/hostedtoolcache/Python/3.8.12/x64/lib/python3.8/http/client.py", line 277, in _read_status
    line = str(self.fp.readline(_MAXLINE + 1), "iso-8859-1")
  File "/opt/hostedtoolcache/Python/3.8.12/x64/lib/python3.8/socket.py", line 669, in readinto
    return self._sock.recv_into(b)
  File "/opt/hostedtoolcache/Python/3.8.12/x64/lib/python3.8/ssl.py", line 1241, in recv_into
    return self.read(nbytes, buffer)
  File "/opt/hostedtoolcache/Python/3.8.12/x64/lib/python3.8/ssl.py", line 1099, in read
    return self._sslobj.read(len, buffer)
socket.timeout: The read operation timed out

During handling of the above exception, another exception occurred:

Traceback (most recent call last):
  File "/opt/hostedtoolcache/Python/3.8.12/x64/lib/python3.8/site-packages/requests/adapters.py", line 439, in send
    resp = conn.urlopen(
  File "/opt/hostedtoolcache/Python/3.8.12/x64/lib/python3.8/site-packages/urllib3/connectionpool.py", line 726, in urlopen
    retries = retries.increment(
  File "/opt/hostedtoolcache/Python/3.8.12/x64/lib/python3.8/site-packages/urllib3/util/retry.py", line 410, in increment
    raise six.reraise(type(error), error, _stacktrace)
  File "/opt/hostedtoolcache/Python/3.8.12/x64/lib/python3.8/site-packages/urllib3/packages/six.py", line 735, in reraise
    raise value
  File "/opt/hostedtoolcache/Python/3.8.12/x64/lib/python3.8/site-packages/urllib3/connectionpool.py", line 670, in urlopen
    httplib_response = self._make_request(
  File "/opt/hostedtoolcache/Python/3.8.12/x64/lib/python3.8/site-packages/urllib3/connectionpool.py", line 428, in _make_request
    self._raise_timeout(err=e, url=url, timeout_value=read_timeout)
  File "/opt/hostedtoolcache/Python/3.8.12/x64/lib/python3.8/site-packages/urllib3/connectionpool.py", line 335, in _raise_timeout
    raise ReadTimeoutError(
urllib3.exceptions.ReadTimeoutError: HTTPSConnectionPool(host='www.cnvd.org.cn', port=443): Read timed out. (read timeout=60)

During handling of the above exception, another exception occurred:

Traceback (most recent call last):
  File "/home/runner/work/threat-broadcast/threat-broadcast/src/crawler/_base_crawler.py", line 62, in cves
    new_cves = self.get_cves()
  File "/home/runner/work/threat-broadcast/threat-broadcast/src/crawler/cnvd.py", line 117, in get_cves
    response = self.session.get(
  File "/opt/hostedtoolcache/Python/3.8.12/x64/lib/python3.8/site-packages/requests/sessions.py", line 546, in get
    return self.request('GET', url, **kwargs)
  File "/opt/hostedtoolcache/Python/3.8.12/x64/lib/python3.8/site-packages/requests/sessions.py", line 533, in request
    resp = self.send(prep, **send_kwargs)
  File "/opt/hostedtoolcache/Python/3.8.12/x64/lib/python3.8/site-packages/requests/sessions.py", line 646, in send
    r = adapter.send(request, **kwargs)
  File "/opt/hostedtoolcache/Python/3.8.12/x64/lib/python3.8/site-packages/requests/adapters.py", line 529, in send
    raise ReadTimeout(e, request=request)
requests.exceptions.ReadTimeout: HTTPSConnectionPool(host='www.cnvd.org.cn', port=443): Read timed out. (read timeout=60)
Traceback (most recent call last):
  File "/opt/hostedtoolcache/Python/3.8.12/x64/lib/python3.8/site-packages/urllib3/connectionpool.py", line 426, in _make_request
    six.raise_from(e, None)
  File "<string>", line 3, in raise_from
  File "/opt/hostedtoolcache/Python/3.8.12/x64/lib/python3.8/site-packages/urllib3/connectionpool.py", line 421, in _make_request
    httplib_response = conn.getresponse()
  File "/opt/hostedtoolcache/Python/3.8.12/x64/lib/python3.8/http/client.py", line 1348, in getresponse
    response.begin()
  File "/opt/hostedtoolcache/Python/3.8.12/x64/lib/python3.8/http/client.py", line 316, in begin
    version, status, reason = self._read_status()
  File "/opt/hostedtoolcache/Python/3.8.12/x64/lib/python3.8/http/client.py", line 277, in _read_status
    line = str(self.fp.readline(_MAXLINE + 1), "iso-8859-1")
  File "/opt/hostedtoolcache/Python/3.8.12/x64/lib/python3.8/socket.py", line 669, in readinto
    return self._sock.recv_into(b)
  File "/opt/hostedtoolcache/Python/3.8.12/x64/lib/python3.8/ssl.py", line 1241, in recv_into
    return self.read(nbytes, buffer)
  File "/opt/hostedtoolcache/Python/3.8.12/x64/lib/python3.8/ssl.py", line 1099, in read
    return self._sslobj.read(len, buffer)
socket.timeout: The read operation timed out

During handling of the above exception, another exception occurred:

Traceback (most recent call last):
  File "/opt/hostedtoolcache/Python/3.8.12/x64/lib/python3.8/site-packages/requests/adapters.py", line 439, in send
    resp = conn.urlopen(
  File "/opt/hostedtoolcache/Python/3.8.12/x64/lib/python3.8/site-packages/urllib3/connectionpool.py", line 726, in urlopen
    retries = retries.increment(
  File "/opt/hostedtoolcache/Python/3.8.12/x64/lib/python3.8/site-packages/urllib3/util/retry.py", line 410, in increment
    raise six.reraise(type(error), error, _stacktrace)
  File "/opt/hostedtoolcache/Python/3.8.12/x64/lib/python3.8/site-packages/urllib3/packages/six.py", line 735, in reraise
    raise value
  File "/opt/hostedtoolcache/Python/3.8.12/x64/lib/python3.8/site-packages/urllib3/connectionpool.py", line 670, in urlopen
    httplib_response = self._make_request(
  File "/opt/hostedtoolcache/Python/3.8.12/x64/lib/python3.8/site-packages/urllib3/connectionpool.py", line 428, in _make_request
    self._raise_timeout(err=e, url=url, timeout_value=read_timeout)
  File "/opt/hostedtoolcache/Python/3.8.12/x64/lib/python3.8/site-packages/urllib3/connectionpool.py", line 335, in _raise_timeout
    raise ReadTimeoutError(
urllib3.exceptions.ReadTimeoutError: HTTPSConnectionPool(host='www.cnvd.org.cn', port=443): Read timed out. (read timeout=60)

During handling of the above exception, another exception occurred:

Traceback (most recent call last):
  File "/home/runner/work/threat-broadcast/threat-broadcast/src/crawler/_base_crawler.py", line 62, in cves
    new_cves = self.get_cves()
  File "/home/runner/work/threat-broadcast/threat-broadcast/src/crawler/cnvd.py", line 117, in get_cves
    response = self.session.get(
  File "/opt/hostedtoolcache/Python/3.8.12/x64/lib/python3.8/site-packages/requests/sessions.py", line 546, in get
    return self.request('GET', url, **kwargs)
  File "/opt/hostedtoolcache/Python/3.8.12/x64/lib/python3.8/site-packages/requests/sessions.py", line 533, in request
    resp = self.send(prep, **send_kwargs)
  File "/opt/hostedtoolcache/Python/3.8.12/x64/lib/python3.8/site-packages/requests/sessions.py", line 646, in send
    r = adapter.send(request, **kwargs)
  File "/opt/hostedtoolcache/Python/3.8.12/x64/lib/python3.8/site-packages/requests/adapters.py", line 529, in send
    raise ReadTimeout(e, request=request)
requests.exceptions.ReadTimeout: HTTPSConnectionPool(host='www.cnvd.org.cn', port=443): Read timed out. (read timeout=60)
