2022-02-19 01:52:41 [ERROR] : 获取 [信息安全漏洞门户] 威胁情报异常
Traceback (most recent call last):
  File "/Users/skill/Desktop/threat-broadcast/src/crawler/_base_crawler.py", line 62, in cves
    new_cves = self.get_cves()
  File "/Users/skill/Desktop/threat-broadcast/src/crawler/vulhub.py", line 55, in get_cves
    cve = self.to_cve(vul)
  File "/Users/skill/Desktop/threat-broadcast/src/crawler/vulhub.py", line 76, in to_cve
    cve.id = cve.url.split("=")[1]
IndexError: list index out of range
2022-02-19 01:52:41 [ERROR] : Traceback (most recent call last):
  File "/Users/skill/Desktop/threat-broadcast/src/crawler/_base_crawler.py", line 62, in cves
    new_cves = self.get_cves()
  File "/Users/skill/Desktop/threat-broadcast/src/crawler/vulhub.py", line 55, in get_cves
    cve = self.to_cve(vul)
  File "/Users/skill/Desktop/threat-broadcast/src/crawler/vulhub.py", line 76, in to_cve
    cve.id = cve.url.split("=")[1]
IndexError: list index out of range
Traceback (most recent call last):
  File "/Users/skill/Desktop/threat-broadcast/src/crawler/_base_crawler.py", line 62, in cves
    new_cves = self.get_cves()
  File "/Users/skill/Desktop/threat-broadcast/src/crawler/vulhub.py", line 55, in get_cves
    cve = self.to_cve(vul)
  File "/Users/skill/Desktop/threat-broadcast/src/crawler/vulhub.py", line 76, in to_cve
    cve.id = cve.url.split("=")[1]
IndexError: list index out of range
2022-02-19 01:52:49 [ERROR] : [邮件] 推送威胁情报失败
Traceback (most recent call last):
  File "/Users/skill/Desktop/threat-broadcast/src/notice/mail.py", line 46, in to_mail
    smtpObj.login(sender, password)
  File "/Applications/Xcode.app/Contents/Developer/Library/Frameworks/Python3.framework/Versions/3.8/lib/python3.8/smtplib.py", line 732, in login
    (code, resp) = self.auth(
  File "/Applications/Xcode.app/Contents/Developer/Library/Frameworks/Python3.framework/Versions/3.8/lib/python3.8/smtplib.py", line 645, in auth
    authobject(challenge).encode('ascii'), eol='')
AttributeError: 'NoneType' object has no attribute 'encode'
2022-02-19 01:52:49 [ERROR] : Traceback (most recent call last):
  File "/Users/skill/Desktop/threat-broadcast/src/notice/mail.py", line 46, in to_mail
    smtpObj.login(sender, password)
  File "/Applications/Xcode.app/Contents/Developer/Library/Frameworks/Python3.framework/Versions/3.8/lib/python3.8/smtplib.py", line 732, in login
    (code, resp) = self.auth(
  File "/Applications/Xcode.app/Contents/Developer/Library/Frameworks/Python3.framework/Versions/3.8/lib/python3.8/smtplib.py", line 645, in auth
    authobject(challenge).encode('ascii'), eol='')
AttributeError: 'NoneType' object has no attribute 'encode'
Traceback (most recent call last):
  File "/Users/skill/Desktop/threat-broadcast/src/notice/mail.py", line 46, in to_mail
    smtpObj.login(sender, password)
  File "/Applications/Xcode.app/Contents/Developer/Library/Frameworks/Python3.framework/Versions/3.8/lib/python3.8/smtplib.py", line 732, in login
    (code, resp) = self.auth(
  File "/Applications/Xcode.app/Contents/Developer/Library/Frameworks/Python3.framework/Versions/3.8/lib/python3.8/smtplib.py", line 645, in auth
    authobject(challenge).encode('ascii'), eol='')
AttributeError: 'NoneType' object has no attribute 'encode'
2022-02-19 01:55:47 [ERROR] : 获取 [信息安全漏洞门户] 威胁情报异常
Traceback (most recent call last):
  File "/Users/skill/Desktop/threat-broadcast/src/crawler/_base_crawler.py", line 62, in cves
    new_cves = self.get_cves()
  File "/Users/skill/Desktop/threat-broadcast/src/crawler/vulhub.py", line 55, in get_cves
    cve = self.to_cve(vul)
  File "/Users/skill/Desktop/threat-broadcast/src/crawler/vulhub.py", line 76, in to_cve
    cve.id = cve.url.split("=")[1]
IndexError: list index out of range
2022-02-19 01:55:47 [ERROR] : Traceback (most recent call last):
  File "/Users/skill/Desktop/threat-broadcast/src/crawler/_base_crawler.py", line 62, in cves
    new_cves = self.get_cves()
  File "/Users/skill/Desktop/threat-broadcast/src/crawler/vulhub.py", line 55, in get_cves
    cve = self.to_cve(vul)
  File "/Users/skill/Desktop/threat-broadcast/src/crawler/vulhub.py", line 76, in to_cve
    cve.id = cve.url.split("=")[1]
IndexError: list index out of range
Traceback (most recent call last):
  File "/Users/skill/Desktop/threat-broadcast/src/crawler/_base_crawler.py", line 62, in cves
    new_cves = self.get_cves()
  File "/Users/skill/Desktop/threat-broadcast/src/crawler/vulhub.py", line 55, in get_cves
    cve = self.to_cve(vul)
  File "/Users/skill/Desktop/threat-broadcast/src/crawler/vulhub.py", line 76, in to_cve
    cve.id = cve.url.split("=")[1]
IndexError: list index out of range
2022-02-19 01:55:53 [ERROR] : [邮件] 推送威胁情报失败
Traceback (most recent call last):
  File "/Users/skill/Desktop/threat-broadcast/src/notice/mail.py", line 46, in to_mail
    smtpObj.login(sender, password)
  File "/Applications/Xcode.app/Contents/Developer/Library/Frameworks/Python3.framework/Versions/3.8/lib/python3.8/smtplib.py", line 732, in login
    (code, resp) = self.auth(
  File "/Applications/Xcode.app/Contents/Developer/Library/Frameworks/Python3.framework/Versions/3.8/lib/python3.8/smtplib.py", line 645, in auth
    authobject(challenge).encode('ascii'), eol='')
AttributeError: 'NoneType' object has no attribute 'encode'
2022-02-19 01:55:53 [ERROR] : Traceback (most recent call last):
  File "/Users/skill/Desktop/threat-broadcast/src/notice/mail.py", line 46, in to_mail
    smtpObj.login(sender, password)
  File "/Applications/Xcode.app/Contents/Developer/Library/Frameworks/Python3.framework/Versions/3.8/lib/python3.8/smtplib.py", line 732, in login
    (code, resp) = self.auth(
  File "/Applications/Xcode.app/Contents/Developer/Library/Frameworks/Python3.framework/Versions/3.8/lib/python3.8/smtplib.py", line 645, in auth
    authobject(challenge).encode('ascii'), eol='')
AttributeError: 'NoneType' object has no attribute 'encode'
Traceback (most recent call last):
  File "/Users/skill/Desktop/threat-broadcast/src/notice/mail.py", line 46, in to_mail
    smtpObj.login(sender, password)
  File "/Applications/Xcode.app/Contents/Developer/Library/Frameworks/Python3.framework/Versions/3.8/lib/python3.8/smtplib.py", line 732, in login
    (code, resp) = self.auth(
  File "/Applications/Xcode.app/Contents/Developer/Library/Frameworks/Python3.framework/Versions/3.8/lib/python3.8/smtplib.py", line 645, in auth
    authobject(challenge).encode('ascii'), eol='')
AttributeError: 'NoneType' object has no attribute 'encode'
2022-02-19 01:57:10 [ERROR] : 获取 [信息安全漏洞门户] 威胁情报异常
Traceback (most recent call last):
  File "/Users/skill/Desktop/threat-broadcast/src/crawler/_base_crawler.py", line 62, in cves
    new_cves = self.get_cves()
  File "/Users/skill/Desktop/threat-broadcast/src/crawler/vulhub.py", line 55, in get_cves
    cve = self.to_cve(vul)
  File "/Users/skill/Desktop/threat-broadcast/src/crawler/vulhub.py", line 76, in to_cve
    cve.id = cve.url.split("=")[1]
IndexError: list index out of range
2022-02-19 01:57:10 [ERROR] : Traceback (most recent call last):
  File "/Users/skill/Desktop/threat-broadcast/src/crawler/_base_crawler.py", line 62, in cves
    new_cves = self.get_cves()
  File "/Users/skill/Desktop/threat-broadcast/src/crawler/vulhub.py", line 55, in get_cves
    cve = self.to_cve(vul)
  File "/Users/skill/Desktop/threat-broadcast/src/crawler/vulhub.py", line 76, in to_cve
    cve.id = cve.url.split("=")[1]
IndexError: list index out of range
Traceback (most recent call last):
  File "/Users/skill/Desktop/threat-broadcast/src/crawler/_base_crawler.py", line 62, in cves
    new_cves = self.get_cves()
  File "/Users/skill/Desktop/threat-broadcast/src/crawler/vulhub.py", line 55, in get_cves
    cve = self.to_cve(vul)
  File "/Users/skill/Desktop/threat-broadcast/src/crawler/vulhub.py", line 76, in to_cve
    cve.id = cve.url.split("=")[1]
IndexError: list index out of range
2022-02-19 01:58:08 [ERROR] : 获取 [信息安全漏洞门户] 威胁情报异常
Traceback (most recent call last):
  File "/Users/skill/Desktop/threat-broadcast/src/crawler/_base_crawler.py", line 62, in cves
    new_cves = self.get_cves()
  File "/Users/skill/Desktop/threat-broadcast/src/crawler/vulhub.py", line 56, in get_cves
    cve = self.to_cve(vul)
  File "/Users/skill/Desktop/threat-broadcast/src/crawler/vulhub.py", line 77, in to_cve
    cve.id = cve.url.split("=")[1]
IndexError: list index out of range
2022-02-19 01:58:08 [ERROR] : Traceback (most recent call last):
  File "/Users/skill/Desktop/threat-broadcast/src/crawler/_base_crawler.py", line 62, in cves
    new_cves = self.get_cves()
  File "/Users/skill/Desktop/threat-broadcast/src/crawler/vulhub.py", line 56, in get_cves
    cve = self.to_cve(vul)
  File "/Users/skill/Desktop/threat-broadcast/src/crawler/vulhub.py", line 77, in to_cve
    cve.id = cve.url.split("=")[1]
IndexError: list index out of range
Traceback (most recent call last):
  File "/Users/skill/Desktop/threat-broadcast/src/crawler/_base_crawler.py", line 62, in cves
    new_cves = self.get_cves()
  File "/Users/skill/Desktop/threat-broadcast/src/crawler/vulhub.py", line 56, in get_cves
    cve = self.to_cve(vul)
  File "/Users/skill/Desktop/threat-broadcast/src/crawler/vulhub.py", line 77, in to_cve
    cve.id = cve.url.split("=")[1]
IndexError: list index out of range
2022-02-19 01:58:59 [ERROR] : 获取 [信息安全漏洞门户] 威胁情报异常
Traceback (most recent call last):
  File "/Users/skill/Desktop/threat-broadcast/src/crawler/_base_crawler.py", line 62, in cves
    new_cves = self.get_cves()
  File "/Users/skill/Desktop/threat-broadcast/src/crawler/vulhub.py", line 55, in get_cves
    cve = self.to_cve(vul)
  File "/Users/skill/Desktop/threat-broadcast/src/crawler/vulhub.py", line 76, in to_cve
    cve.id = cve.url.split("=")[1]
IndexError: list index out of range
2022-02-19 01:58:59 [ERROR] : Traceback (most recent call last):
  File "/Users/skill/Desktop/threat-broadcast/src/crawler/_base_crawler.py", line 62, in cves
    new_cves = self.get_cves()
  File "/Users/skill/Desktop/threat-broadcast/src/crawler/vulhub.py", line 55, in get_cves
    cve = self.to_cve(vul)
  File "/Users/skill/Desktop/threat-broadcast/src/crawler/vulhub.py", line 76, in to_cve
    cve.id = cve.url.split("=")[1]
IndexError: list index out of range
Traceback (most recent call last):
  File "/Users/skill/Desktop/threat-broadcast/src/crawler/_base_crawler.py", line 62, in cves
    new_cves = self.get_cves()
  File "/Users/skill/Desktop/threat-broadcast/src/crawler/vulhub.py", line 55, in get_cves
    cve = self.to_cve(vul)
  File "/Users/skill/Desktop/threat-broadcast/src/crawler/vulhub.py", line 76, in to_cve
    cve.id = cve.url.split("=")[1]
IndexError: list index out of range
2022-02-19 01:59:28 [ERROR] : 获取 [信息安全漏洞门户] 威胁情报异常
Traceback (most recent call last):
  File "/Users/skill/Desktop/threat-broadcast/src/crawler/_base_crawler.py", line 62, in cves
    new_cves = self.get_cves()
  File "/Users/skill/Desktop/threat-broadcast/src/crawler/vulhub.py", line 55, in get_cves
    cve = self.to_cve(vul)
  File "/Users/skill/Desktop/threat-broadcast/src/crawler/vulhub.py", line 77, in to_cve
    cve.id = cve.url.split("=")[1]
IndexError: list index out of range
2022-02-19 01:59:28 [ERROR] : Traceback (most recent call last):
  File "/Users/skill/Desktop/threat-broadcast/src/crawler/_base_crawler.py", line 62, in cves
    new_cves = self.get_cves()
  File "/Users/skill/Desktop/threat-broadcast/src/crawler/vulhub.py", line 55, in get_cves
    cve = self.to_cve(vul)
  File "/Users/skill/Desktop/threat-broadcast/src/crawler/vulhub.py", line 77, in to_cve
    cve.id = cve.url.split("=")[1]
IndexError: list index out of range
Traceback (most recent call last):
  File "/Users/skill/Desktop/threat-broadcast/src/crawler/_base_crawler.py", line 62, in cves
    new_cves = self.get_cves()
  File "/Users/skill/Desktop/threat-broadcast/src/crawler/vulhub.py", line 55, in get_cves
    cve = self.to_cve(vul)
  File "/Users/skill/Desktop/threat-broadcast/src/crawler/vulhub.py", line 77, in to_cve
    cve.id = cve.url.split("=")[1]
IndexError: list index out of range
2022-02-19 01:59:41 [ERROR] : 获取 [信息安全漏洞门户] 威胁情报异常
Traceback (most recent call last):
  File "/Users/skill/Desktop/threat-broadcast/src/crawler/_base_crawler.py", line 62, in cves
    new_cves = self.get_cves()
  File "/Users/skill/Desktop/threat-broadcast/src/crawler/vulhub.py", line 55, in get_cves
    cve = self.to_cve(vul)
  File "/Users/skill/Desktop/threat-broadcast/src/crawler/vulhub.py", line 77, in to_cve
    cve.id = cve.url.split("=")[1]
IndexError: list index out of range
2022-02-19 01:59:41 [ERROR] : Traceback (most recent call last):
  File "/Users/skill/Desktop/threat-broadcast/src/crawler/_base_crawler.py", line 62, in cves
    new_cves = self.get_cves()
  File "/Users/skill/Desktop/threat-broadcast/src/crawler/vulhub.py", line 55, in get_cves
    cve = self.to_cve(vul)
  File "/Users/skill/Desktop/threat-broadcast/src/crawler/vulhub.py", line 77, in to_cve
    cve.id = cve.url.split("=")[1]
IndexError: list index out of range
Traceback (most recent call last):
  File "/Users/skill/Desktop/threat-broadcast/src/crawler/_base_crawler.py", line 62, in cves
    new_cves = self.get_cves()
  File "/Users/skill/Desktop/threat-broadcast/src/crawler/vulhub.py", line 55, in get_cves
    cve = self.to_cve(vul)
  File "/Users/skill/Desktop/threat-broadcast/src/crawler/vulhub.py", line 77, in to_cve
    cve.id = cve.url.split("=")[1]
IndexError: list index out of range
2022-02-19 02:00:03 [ERROR] : 获取 [信息安全漏洞门户] 威胁情报异常
Traceback (most recent call last):
  File "/Users/skill/Desktop/threat-broadcast/src/crawler/_base_crawler.py", line 62, in cves
    new_cves = self.get_cves()
  File "/Users/skill/Desktop/threat-broadcast/src/crawler/vulhub.py", line 55, in get_cves
    cve = self.to_cve(vul)
  File "/Users/skill/Desktop/threat-broadcast/src/crawler/vulhub.py", line 77, in to_cve
    cve.id = cve.url.split("=")[1]
IndexError: list index out of range
2022-02-19 02:00:03 [ERROR] : Traceback (most recent call last):
  File "/Users/skill/Desktop/threat-broadcast/src/crawler/_base_crawler.py", line 62, in cves
    new_cves = self.get_cves()
  File "/Users/skill/Desktop/threat-broadcast/src/crawler/vulhub.py", line 55, in get_cves
    cve = self.to_cve(vul)
  File "/Users/skill/Desktop/threat-broadcast/src/crawler/vulhub.py", line 77, in to_cve
    cve.id = cve.url.split("=")[1]
IndexError: list index out of range
Traceback (most recent call last):
  File "/Users/skill/Desktop/threat-broadcast/src/crawler/_base_crawler.py", line 62, in cves
    new_cves = self.get_cves()
  File "/Users/skill/Desktop/threat-broadcast/src/crawler/vulhub.py", line 55, in get_cves
    cve = self.to_cve(vul)
  File "/Users/skill/Desktop/threat-broadcast/src/crawler/vulhub.py", line 77, in to_cve
    cve.id = cve.url.split("=")[1]
IndexError: list index out of range
2022-02-19 02:00:25 [ERROR] : 获取 [信息安全漏洞门户] 威胁情报异常
Traceback (most recent call last):
  File "/Users/skill/Desktop/threat-broadcast/src/crawler/_base_crawler.py", line 62, in cves
    new_cves = self.get_cves()
  File "/Users/skill/Desktop/threat-broadcast/src/crawler/vulhub.py", line 55, in get_cves
    cve = self.to_cve(vul)
  File "/Users/skill/Desktop/threat-broadcast/src/crawler/vulhub.py", line 77, in to_cve
    cve.id = cve.url.split("=")[1]
IndexError: list index out of range
2022-02-19 02:00:25 [ERROR] : Traceback (most recent call last):
  File "/Users/skill/Desktop/threat-broadcast/src/crawler/_base_crawler.py", line 62, in cves
    new_cves = self.get_cves()
  File "/Users/skill/Desktop/threat-broadcast/src/crawler/vulhub.py", line 55, in get_cves
    cve = self.to_cve(vul)
  File "/Users/skill/Desktop/threat-broadcast/src/crawler/vulhub.py", line 77, in to_cve
    cve.id = cve.url.split("=")[1]
IndexError: list index out of range
Traceback (most recent call last):
  File "/Users/skill/Desktop/threat-broadcast/src/crawler/_base_crawler.py", line 62, in cves
    new_cves = self.get_cves()
  File "/Users/skill/Desktop/threat-broadcast/src/crawler/vulhub.py", line 55, in get_cves
    cve = self.to_cve(vul)
  File "/Users/skill/Desktop/threat-broadcast/src/crawler/vulhub.py", line 77, in to_cve
    cve.id = cve.url.split("=")[1]
IndexError: list index out of range
2022-02-19 02:01:45 [ERROR] : [邮件] 推送威胁情报失败
Traceback (most recent call last):
  File "/Users/skill/Desktop/threat-broadcast/src/notice/mail.py", line 46, in to_mail
    smtpObj.login(sender, password)
  File "/Applications/Xcode.app/Contents/Developer/Library/Frameworks/Python3.framework/Versions/3.8/lib/python3.8/smtplib.py", line 732, in login
    (code, resp) = self.auth(
  File "/Applications/Xcode.app/Contents/Developer/Library/Frameworks/Python3.framework/Versions/3.8/lib/python3.8/smtplib.py", line 645, in auth
    authobject(challenge).encode('ascii'), eol='')
AttributeError: 'NoneType' object has no attribute 'encode'
2022-02-19 02:01:45 [ERROR] : Traceback (most recent call last):
  File "/Users/skill/Desktop/threat-broadcast/src/notice/mail.py", line 46, in to_mail
    smtpObj.login(sender, password)
  File "/Applications/Xcode.app/Contents/Developer/Library/Frameworks/Python3.framework/Versions/3.8/lib/python3.8/smtplib.py", line 732, in login
    (code, resp) = self.auth(
  File "/Applications/Xcode.app/Contents/Developer/Library/Frameworks/Python3.framework/Versions/3.8/lib/python3.8/smtplib.py", line 645, in auth
    authobject(challenge).encode('ascii'), eol='')
AttributeError: 'NoneType' object has no attribute 'encode'
Traceback (most recent call last):
  File "/Users/skill/Desktop/threat-broadcast/src/notice/mail.py", line 46, in to_mail
    smtpObj.login(sender, password)
  File "/Applications/Xcode.app/Contents/Developer/Library/Frameworks/Python3.framework/Versions/3.8/lib/python3.8/smtplib.py", line 732, in login
    (code, resp) = self.auth(
  File "/Applications/Xcode.app/Contents/Developer/Library/Frameworks/Python3.framework/Versions/3.8/lib/python3.8/smtplib.py", line 645, in auth
    authobject(challenge).encode('ascii'), eol='')
AttributeError: 'NoneType' object has no attribute 'encode'
2022-02-19 02:05:51 [ERROR] : [邮件] 推送威胁情报失败
Traceback (most recent call last):
  File "/Users/skill/Desktop/threat-broadcast/src/notice/mail.py", line 46, in to_mail
    smtpObj.login(sender, password)
  File "/Applications/Xcode.app/Contents/Developer/Library/Frameworks/Python3.framework/Versions/3.8/lib/python3.8/smtplib.py", line 732, in login
    (code, resp) = self.auth(
  File "/Applications/Xcode.app/Contents/Developer/Library/Frameworks/Python3.framework/Versions/3.8/lib/python3.8/smtplib.py", line 645, in auth
    authobject(challenge).encode('ascii'), eol='')
AttributeError: 'NoneType' object has no attribute 'encode'
2022-02-19 02:05:51 [ERROR] : Traceback (most recent call last):
  File "/Users/skill/Desktop/threat-broadcast/src/notice/mail.py", line 46, in to_mail
    smtpObj.login(sender, password)
  File "/Applications/Xcode.app/Contents/Developer/Library/Frameworks/Python3.framework/Versions/3.8/lib/python3.8/smtplib.py", line 732, in login
    (code, resp) = self.auth(
  File "/Applications/Xcode.app/Contents/Developer/Library/Frameworks/Python3.framework/Versions/3.8/lib/python3.8/smtplib.py", line 645, in auth
    authobject(challenge).encode('ascii'), eol='')
AttributeError: 'NoneType' object has no attribute 'encode'
Traceback (most recent call last):
  File "/Users/skill/Desktop/threat-broadcast/src/notice/mail.py", line 46, in to_mail
    smtpObj.login(sender, password)
  File "/Applications/Xcode.app/Contents/Developer/Library/Frameworks/Python3.framework/Versions/3.8/lib/python3.8/smtplib.py", line 732, in login
    (code, resp) = self.auth(
  File "/Applications/Xcode.app/Contents/Developer/Library/Frameworks/Python3.framework/Versions/3.8/lib/python3.8/smtplib.py", line 645, in auth
    authobject(challenge).encode('ascii'), eol='')
AttributeError: 'NoneType' object has no attribute 'encode'
2022-02-19 02:07:31 [ERROR] : [邮件] 推送威胁情报失败
Traceback (most recent call last):
  File "/Users/skill/Desktop/threat-broadcast/src/notice/mail.py", line 46, in to_mail
    smtpObj.login(sender, password)
  File "/Applications/Xcode.app/Contents/Developer/Library/Frameworks/Python3.framework/Versions/3.8/lib/python3.8/smtplib.py", line 732, in login
    (code, resp) = self.auth(
  File "/Applications/Xcode.app/Contents/Developer/Library/Frameworks/Python3.framework/Versions/3.8/lib/python3.8/smtplib.py", line 645, in auth
    authobject(challenge).encode('ascii'), eol='')
AttributeError: 'NoneType' object has no attribute 'encode'
2022-02-19 02:07:31 [ERROR] : Traceback (most recent call last):
  File "/Users/skill/Desktop/threat-broadcast/src/notice/mail.py", line 46, in to_mail
    smtpObj.login(sender, password)
  File "/Applications/Xcode.app/Contents/Developer/Library/Frameworks/Python3.framework/Versions/3.8/lib/python3.8/smtplib.py", line 732, in login
    (code, resp) = self.auth(
  File "/Applications/Xcode.app/Contents/Developer/Library/Frameworks/Python3.framework/Versions/3.8/lib/python3.8/smtplib.py", line 645, in auth
    authobject(challenge).encode('ascii'), eol='')
AttributeError: 'NoneType' object has no attribute 'encode'
Traceback (most recent call last):
  File "/Users/skill/Desktop/threat-broadcast/src/notice/mail.py", line 46, in to_mail
    smtpObj.login(sender, password)
  File "/Applications/Xcode.app/Contents/Developer/Library/Frameworks/Python3.framework/Versions/3.8/lib/python3.8/smtplib.py", line 732, in login
    (code, resp) = self.auth(
  File "/Applications/Xcode.app/Contents/Developer/Library/Frameworks/Python3.framework/Versions/3.8/lib/python3.8/smtplib.py", line 645, in auth
    authobject(challenge).encode('ascii'), eol='')
AttributeError: 'NoneType' object has no attribute 'encode'
2022-02-19 02:14:39 [ERROR] : 获取 [国家信息安全漏洞共享平台（CNVD）] 威胁情报异常
Traceback (most recent call last):
  File "/Users/skill/Desktop/threat-broadcast/src/crawler/_base_crawler.py", line 62, in cves
    new_cves = self.get_cves()
  File "/Users/skill/Desktop/threat-broadcast/src/crawler/cnvd.py", line 85, in get_cves
    response = self.session.post(
  File "/Users/skill/Desktop/threat-broadcast/venv/lib/python3.8/site-packages/requests/sessions.py", line 581, in post
    return self.request('POST', url, data=data, json=json, **kwargs)
  File "/Users/skill/Desktop/threat-broadcast/venv/lib/python3.8/site-packages/requests/sessions.py", line 533, in request
    resp = self.send(prep, **send_kwargs)
  File "/Users/skill/Desktop/threat-broadcast/venv/lib/python3.8/site-packages/requests/sessions.py", line 646, in send
    r = adapter.send(request, **kwargs)
  File "/Users/skill/Desktop/threat-broadcast/venv/lib/python3.8/site-packages/requests/adapters.py", line 439, in send
    resp = conn.urlopen(
  File "/Users/skill/Desktop/threat-broadcast/venv/lib/python3.8/site-packages/urllib3/connectionpool.py", line 670, in urlopen
    httplib_response = self._make_request(
  File "/Users/skill/Desktop/threat-broadcast/venv/lib/python3.8/site-packages/urllib3/connectionpool.py", line 392, in _make_request
    conn.request(method, url, **httplib_request_kw)
  File "/Applications/Xcode.app/Contents/Developer/Library/Frameworks/Python3.framework/Versions/3.8/lib/python3.8/http/client.py", line 1252, in request
    self._send_request(method, url, body, headers, encode_chunked)
  File "/Applications/Xcode.app/Contents/Developer/Library/Frameworks/Python3.framework/Versions/3.8/lib/python3.8/http/client.py", line 1297, in _send_request
    body = _encode(body, 'body')
  File "/Applications/Xcode.app/Contents/Developer/Library/Frameworks/Python3.framework/Versions/3.8/lib/python3.8/http/client.py", line 164, in _encode
    raise UnicodeEncodeError(
UnicodeEncodeError: 'latin-1' codec can't encode characters in position 7-13: Body ('请输入精确编号') is not valid Latin-1. Use body.encode('utf-8') if you want to send it encoded in UTF-8.
2022-02-19 02:14:39 [ERROR] : Traceback (most recent call last):
  File "/Users/skill/Desktop/threat-broadcast/src/crawler/_base_crawler.py", line 62, in cves
    new_cves = self.get_cves()
  File "/Users/skill/Desktop/threat-broadcast/src/crawler/cnvd.py", line 85, in get_cves
    response = self.session.post(
  File "/Users/skill/Desktop/threat-broadcast/venv/lib/python3.8/site-packages/requests/sessions.py", line 581, in post
    return self.request('POST', url, data=data, json=json, **kwargs)
  File "/Users/skill/Desktop/threat-broadcast/venv/lib/python3.8/site-packages/requests/sessions.py", line 533, in request
    resp = self.send(prep, **send_kwargs)
  File "/Users/skill/Desktop/threat-broadcast/venv/lib/python3.8/site-packages/requests/sessions.py", line 646, in send
    r = adapter.send(request, **kwargs)
  File "/Users/skill/Desktop/threat-broadcast/venv/lib/python3.8/site-packages/requests/adapters.py", line 439, in send
    resp = conn.urlopen(
  File "/Users/skill/Desktop/threat-broadcast/venv/lib/python3.8/site-packages/urllib3/connectionpool.py", line 670, in urlopen
    httplib_response = self._make_request(
  File "/Users/skill/Desktop/threat-broadcast/venv/lib/python3.8/site-packages/urllib3/connectionpool.py", line 392, in _make_request
    conn.request(method, url, **httplib_request_kw)
  File "/Applications/Xcode.app/Contents/Developer/Library/Frameworks/Python3.framework/Versions/3.8/lib/python3.8/http/client.py", line 1252, in request
    self._send_request(method, url, body, headers, encode_chunked)
  File "/Applications/Xcode.app/Contents/Developer/Library/Frameworks/Python3.framework/Versions/3.8/lib/python3.8/http/client.py", line 1297, in _send_request
    body = _encode(body, 'body')
  File "/Applications/Xcode.app/Contents/Developer/Library/Frameworks/Python3.framework/Versions/3.8/lib/python3.8/http/client.py", line 164, in _encode
    raise UnicodeEncodeError(
UnicodeEncodeError: 'latin-1' codec can't encode characters in position 7-13: Body ('请输入精确编号') is not valid Latin-1. Use body.encode('utf-8') if you want to send it encoded in UTF-8.
Traceback (most recent call last):
  File "/Users/skill/Desktop/threat-broadcast/src/crawler/_base_crawler.py", line 62, in cves
    new_cves = self.get_cves()
  File "/Users/skill/Desktop/threat-broadcast/src/crawler/cnvd.py", line 85, in get_cves
    response = self.session.post(
  File "/Users/skill/Desktop/threat-broadcast/venv/lib/python3.8/site-packages/requests/sessions.py", line 581, in post
    return self.request('POST', url, data=data, json=json, **kwargs)
  File "/Users/skill/Desktop/threat-broadcast/venv/lib/python3.8/site-packages/requests/sessions.py", line 533, in request
    resp = self.send(prep, **send_kwargs)
  File "/Users/skill/Desktop/threat-broadcast/venv/lib/python3.8/site-packages/requests/sessions.py", line 646, in send
    r = adapter.send(request, **kwargs)
  File "/Users/skill/Desktop/threat-broadcast/venv/lib/python3.8/site-packages/requests/adapters.py", line 439, in send
    resp = conn.urlopen(
  File "/Users/skill/Desktop/threat-broadcast/venv/lib/python3.8/site-packages/urllib3/connectionpool.py", line 670, in urlopen
    httplib_response = self._make_request(
  File "/Users/skill/Desktop/threat-broadcast/venv/lib/python3.8/site-packages/urllib3/connectionpool.py", line 392, in _make_request
    conn.request(method, url, **httplib_request_kw)
  File "/Applications/Xcode.app/Contents/Developer/Library/Frameworks/Python3.framework/Versions/3.8/lib/python3.8/http/client.py", line 1252, in request
    self._send_request(method, url, body, headers, encode_chunked)
  File "/Applications/Xcode.app/Contents/Developer/Library/Frameworks/Python3.framework/Versions/3.8/lib/python3.8/http/client.py", line 1297, in _send_request
    body = _encode(body, 'body')
  File "/Applications/Xcode.app/Contents/Developer/Library/Frameworks/Python3.framework/Versions/3.8/lib/python3.8/http/client.py", line 164, in _encode
    raise UnicodeEncodeError(
UnicodeEncodeError: 'latin-1' codec can't encode characters in position 7-13: Body ('请输入精确编号') is not valid Latin-1. Use body.encode('utf-8') if you want to send it encoded in UTF-8.
2022-02-19 02:17:22 [ERROR] : [邮件] 推送威胁情报失败
Traceback (most recent call last):
  File "/Users/skill/Desktop/threat-broadcast/src/notice/mail.py", line 46, in to_mail
    smtpObj.login(sender, password)
  File "/Applications/Xcode.app/Contents/Developer/Library/Frameworks/Python3.framework/Versions/3.8/lib/python3.8/smtplib.py", line 732, in login
    (code, resp) = self.auth(
  File "/Applications/Xcode.app/Contents/Developer/Library/Frameworks/Python3.framework/Versions/3.8/lib/python3.8/smtplib.py", line 645, in auth
    authobject(challenge).encode('ascii'), eol='')
AttributeError: 'NoneType' object has no attribute 'encode'
2022-02-19 02:17:22 [ERROR] : Traceback (most recent call last):
  File "/Users/skill/Desktop/threat-broadcast/src/notice/mail.py", line 46, in to_mail
    smtpObj.login(sender, password)
  File "/Applications/Xcode.app/Contents/Developer/Library/Frameworks/Python3.framework/Versions/3.8/lib/python3.8/smtplib.py", line 732, in login
    (code, resp) = self.auth(
  File "/Applications/Xcode.app/Contents/Developer/Library/Frameworks/Python3.framework/Versions/3.8/lib/python3.8/smtplib.py", line 645, in auth
    authobject(challenge).encode('ascii'), eol='')
AttributeError: 'NoneType' object has no attribute 'encode'
Traceback (most recent call last):
  File "/Users/skill/Desktop/threat-broadcast/src/notice/mail.py", line 46, in to_mail
    smtpObj.login(sender, password)
  File "/Applications/Xcode.app/Contents/Developer/Library/Frameworks/Python3.framework/Versions/3.8/lib/python3.8/smtplib.py", line 732, in login
    (code, resp) = self.auth(
  File "/Applications/Xcode.app/Contents/Developer/Library/Frameworks/Python3.framework/Versions/3.8/lib/python3.8/smtplib.py", line 645, in auth
    authobject(challenge).encode('ascii'), eol='')
AttributeError: 'NoneType' object has no attribute 'encode'
2022-02-19 02:21:06 [ERROR] : [邮件] 推送威胁情报失败
Traceback (most recent call last):
  File "/Users/skill/Desktop/threat-broadcast/src/notice/mail.py", line 46, in to_mail
    smtpObj.login(sender, password)
  File "/Applications/Xcode.app/Contents/Developer/Library/Frameworks/Python3.framework/Versions/3.8/lib/python3.8/smtplib.py", line 732, in login
    (code, resp) = self.auth(
  File "/Applications/Xcode.app/Contents/Developer/Library/Frameworks/Python3.framework/Versions/3.8/lib/python3.8/smtplib.py", line 645, in auth
    authobject(challenge).encode('ascii'), eol='')
AttributeError: 'NoneType' object has no attribute 'encode'
2022-02-19 02:21:06 [ERROR] : Traceback (most recent call last):
  File "/Users/skill/Desktop/threat-broadcast/src/notice/mail.py", line 46, in to_mail
    smtpObj.login(sender, password)
  File "/Applications/Xcode.app/Contents/Developer/Library/Frameworks/Python3.framework/Versions/3.8/lib/python3.8/smtplib.py", line 732, in login
    (code, resp) = self.auth(
  File "/Applications/Xcode.app/Contents/Developer/Library/Frameworks/Python3.framework/Versions/3.8/lib/python3.8/smtplib.py", line 645, in auth
    authobject(challenge).encode('ascii'), eol='')
AttributeError: 'NoneType' object has no attribute 'encode'
Traceback (most recent call last):
  File "/Users/skill/Desktop/threat-broadcast/src/notice/mail.py", line 46, in to_mail
    smtpObj.login(sender, password)
  File "/Applications/Xcode.app/Contents/Developer/Library/Frameworks/Python3.framework/Versions/3.8/lib/python3.8/smtplib.py", line 732, in login
    (code, resp) = self.auth(
  File "/Applications/Xcode.app/Contents/Developer/Library/Frameworks/Python3.framework/Versions/3.8/lib/python3.8/smtplib.py", line 645, in auth
    authobject(challenge).encode('ascii'), eol='')
AttributeError: 'NoneType' object has no attribute 'encode'
2022-02-19 02:24:56 [ERROR] : [邮件] 推送威胁情报失败
Traceback (most recent call last):
  File "/Users/skill/Desktop/threat-broadcast/src/notice/mail.py", line 46, in to_mail
    smtpObj.login(sender, password)
  File "/Applications/Xcode.app/Contents/Developer/Library/Frameworks/Python3.framework/Versions/3.8/lib/python3.8/smtplib.py", line 732, in login
    (code, resp) = self.auth(
  File "/Applications/Xcode.app/Contents/Developer/Library/Frameworks/Python3.framework/Versions/3.8/lib/python3.8/smtplib.py", line 645, in auth
    authobject(challenge).encode('ascii'), eol='')
AttributeError: 'NoneType' object has no attribute 'encode'
2022-02-19 02:24:56 [ERROR] : Traceback (most recent call last):
  File "/Users/skill/Desktop/threat-broadcast/src/notice/mail.py", line 46, in to_mail
    smtpObj.login(sender, password)
  File "/Applications/Xcode.app/Contents/Developer/Library/Frameworks/Python3.framework/Versions/3.8/lib/python3.8/smtplib.py", line 732, in login
    (code, resp) = self.auth(
  File "/Applications/Xcode.app/Contents/Developer/Library/Frameworks/Python3.framework/Versions/3.8/lib/python3.8/smtplib.py", line 645, in auth
    authobject(challenge).encode('ascii'), eol='')
AttributeError: 'NoneType' object has no attribute 'encode'
Traceback (most recent call last):
  File "/Users/skill/Desktop/threat-broadcast/src/notice/mail.py", line 46, in to_mail
    smtpObj.login(sender, password)
  File "/Applications/Xcode.app/Contents/Developer/Library/Frameworks/Python3.framework/Versions/3.8/lib/python3.8/smtplib.py", line 732, in login
    (code, resp) = self.auth(
  File "/Applications/Xcode.app/Contents/Developer/Library/Frameworks/Python3.framework/Versions/3.8/lib/python3.8/smtplib.py", line 645, in auth
    authobject(challenge).encode('ascii'), eol='')
AttributeError: 'NoneType' object has no attribute 'encode'
2022-02-19 02:31:30 [ERROR] : [邮件] 推送威胁情报失败
Traceback (most recent call last):
  File "/Users/skill/Desktop/threat-broadcast/src/notice/mail.py", line 46, in to_mail
    smtpObj.login(sender, password)
  File "/Applications/Xcode.app/Contents/Developer/Library/Frameworks/Python3.framework/Versions/3.8/lib/python3.8/smtplib.py", line 732, in login
    (code, resp) = self.auth(
  File "/Applications/Xcode.app/Contents/Developer/Library/Frameworks/Python3.framework/Versions/3.8/lib/python3.8/smtplib.py", line 645, in auth
    authobject(challenge).encode('ascii'), eol='')
AttributeError: 'NoneType' object has no attribute 'encode'
2022-02-19 02:31:30 [ERROR] : Traceback (most recent call last):
  File "/Users/skill/Desktop/threat-broadcast/src/notice/mail.py", line 46, in to_mail
    smtpObj.login(sender, password)
  File "/Applications/Xcode.app/Contents/Developer/Library/Frameworks/Python3.framework/Versions/3.8/lib/python3.8/smtplib.py", line 732, in login
    (code, resp) = self.auth(
  File "/Applications/Xcode.app/Contents/Developer/Library/Frameworks/Python3.framework/Versions/3.8/lib/python3.8/smtplib.py", line 645, in auth
    authobject(challenge).encode('ascii'), eol='')
AttributeError: 'NoneType' object has no attribute 'encode'
Traceback (most recent call last):
  File "/Users/skill/Desktop/threat-broadcast/src/notice/mail.py", line 46, in to_mail
    smtpObj.login(sender, password)
  File "/Applications/Xcode.app/Contents/Developer/Library/Frameworks/Python3.framework/Versions/3.8/lib/python3.8/smtplib.py", line 732, in login
    (code, resp) = self.auth(
  File "/Applications/Xcode.app/Contents/Developer/Library/Frameworks/Python3.framework/Versions/3.8/lib/python3.8/smtplib.py", line 645, in auth
    authobject(challenge).encode('ascii'), eol='')
AttributeError: 'NoneType' object has no attribute 'encode'
