2022-02-18 14:46:22 [ERROR] : 获取 [数字观星POC++] 威胁情报异常
Traceback (most recent call last):
  File "/Users/skill/Desktop/threat-broadcast/src/crawler/_base_crawler.py", line 62, in cves
    new_cves = self.get_cves()
  File "/Users/skill/Desktop/threat-broadcast/src/crawler/datastarpocplus.py", line 57, in get_cves
    cve = self.to_cve(obj)
  File "/Users/skill/Desktop/threat-broadcast/src/crawler/datastarpocplus.py", line 68, in to_cve
    html = etree.HTML(xml)
  File "src/lxml/etree.pyx", line 3185, in lxml.etree.HTML
  File "src/lxml/parser.pxi", line 1895, in lxml.etree._parseMemoryDocument
ValueError: can only parse strings
2022-02-18 14:46:22 [ERROR] : Traceback (most recent call last):
  File "/Users/skill/Desktop/threat-broadcast/src/crawler/_base_crawler.py", line 62, in cves
    new_cves = self.get_cves()
  File "/Users/skill/Desktop/threat-broadcast/src/crawler/datastarpocplus.py", line 57, in get_cves
    cve = self.to_cve(obj)
  File "/Users/skill/Desktop/threat-broadcast/src/crawler/datastarpocplus.py", line 68, in to_cve
    html = etree.HTML(xml)
  File "src/lxml/etree.pyx", line 3185, in lxml.etree.HTML
  File "src/lxml/parser.pxi", line 1895, in lxml.etree._parseMemoryDocument
ValueError: can only parse strings
Traceback (most recent call last):
  File "/Users/skill/Desktop/threat-broadcast/src/crawler/_base_crawler.py", line 62, in cves
    new_cves = self.get_cves()
  File "/Users/skill/Desktop/threat-broadcast/src/crawler/datastarpocplus.py", line 57, in get_cves
    cve = self.to_cve(obj)
  File "/Users/skill/Desktop/threat-broadcast/src/crawler/datastarpocplus.py", line 68, in to_cve
    html = etree.HTML(xml)
  File "src/lxml/etree.pyx", line 3185, in lxml.etree.HTML
  File "src/lxml/parser.pxi", line 1895, in lxml.etree._parseMemoryDocument
ValueError: can only parse strings
2022-02-18 14:54:43 [ERROR] : [邮件] 推送威胁情报失败
Traceback (most recent call last):
  File "/Users/skill/Desktop/threat-broadcast/src/notice/mail.py", line 46, in to_mail
    smtpObj.login(sender, password)
  File "/Applications/Xcode.app/Contents/Developer/Library/Frameworks/Python3.framework/Versions/3.8/lib/python3.8/smtplib.py", line 732, in login
    (code, resp) = self.auth(
  File "/Applications/Xcode.app/Contents/Developer/Library/Frameworks/Python3.framework/Versions/3.8/lib/python3.8/smtplib.py", line 645, in auth
    authobject(challenge).encode('ascii'), eol='')
AttributeError: 'NoneType' object has no attribute 'encode'
2022-02-18 14:54:43 [ERROR] : Traceback (most recent call last):
  File "/Users/skill/Desktop/threat-broadcast/src/notice/mail.py", line 46, in to_mail
    smtpObj.login(sender, password)
  File "/Applications/Xcode.app/Contents/Developer/Library/Frameworks/Python3.framework/Versions/3.8/lib/python3.8/smtplib.py", line 732, in login
    (code, resp) = self.auth(
  File "/Applications/Xcode.app/Contents/Developer/Library/Frameworks/Python3.framework/Versions/3.8/lib/python3.8/smtplib.py", line 645, in auth
    authobject(challenge).encode('ascii'), eol='')
AttributeError: 'NoneType' object has no attribute 'encode'
Traceback (most recent call last):
  File "/Users/skill/Desktop/threat-broadcast/src/notice/mail.py", line 46, in to_mail
    smtpObj.login(sender, password)
  File "/Applications/Xcode.app/Contents/Developer/Library/Frameworks/Python3.framework/Versions/3.8/lib/python3.8/smtplib.py", line 732, in login
    (code, resp) = self.auth(
  File "/Applications/Xcode.app/Contents/Developer/Library/Frameworks/Python3.framework/Versions/3.8/lib/python3.8/smtplib.py", line 645, in auth
    authobject(challenge).encode('ascii'), eol='')
AttributeError: 'NoneType' object has no attribute 'encode'
2022-02-18 14:56:54 [ERROR] : [邮件] 推送威胁情报失败
Traceback (most recent call last):
  File "/Users/skill/Desktop/threat-broadcast/src/notice/mail.py", line 46, in to_mail
    smtpObj.login(sender, password)
  File "/Applications/Xcode.app/Contents/Developer/Library/Frameworks/Python3.framework/Versions/3.8/lib/python3.8/smtplib.py", line 732, in login
    (code, resp) = self.auth(
  File "/Applications/Xcode.app/Contents/Developer/Library/Frameworks/Python3.framework/Versions/3.8/lib/python3.8/smtplib.py", line 645, in auth
    authobject(challenge).encode('ascii'), eol='')
AttributeError: 'NoneType' object has no attribute 'encode'
2022-02-18 14:56:54 [ERROR] : Traceback (most recent call last):
  File "/Users/skill/Desktop/threat-broadcast/src/notice/mail.py", line 46, in to_mail
    smtpObj.login(sender, password)
  File "/Applications/Xcode.app/Contents/Developer/Library/Frameworks/Python3.framework/Versions/3.8/lib/python3.8/smtplib.py", line 732, in login
    (code, resp) = self.auth(
  File "/Applications/Xcode.app/Contents/Developer/Library/Frameworks/Python3.framework/Versions/3.8/lib/python3.8/smtplib.py", line 645, in auth
    authobject(challenge).encode('ascii'), eol='')
AttributeError: 'NoneType' object has no attribute 'encode'
Traceback (most recent call last):
  File "/Users/skill/Desktop/threat-broadcast/src/notice/mail.py", line 46, in to_mail
    smtpObj.login(sender, password)
  File "/Applications/Xcode.app/Contents/Developer/Library/Frameworks/Python3.framework/Versions/3.8/lib/python3.8/smtplib.py", line 732, in login
    (code, resp) = self.auth(
  File "/Applications/Xcode.app/Contents/Developer/Library/Frameworks/Python3.framework/Versions/3.8/lib/python3.8/smtplib.py", line 645, in auth
    authobject(challenge).encode('ascii'), eol='')
AttributeError: 'NoneType' object has no attribute 'encode'
2022-02-18 17:27:07 [ERROR] : 获取 [360 网络安全响应中心] 威胁情报异常
Traceback (most recent call last):
  File "/opt/hostedtoolcache/Python/3.8.12/x64/lib/python3.8/site-packages/urllib3/connectionpool.py", line 670, in urlopen
    httplib_response = self._make_request(
  File "/opt/hostedtoolcache/Python/3.8.12/x64/lib/python3.8/site-packages/urllib3/connectionpool.py", line 426, in _make_request
    six.raise_from(e, None)
  File "<string>", line 3, in raise_from
  File "/opt/hostedtoolcache/Python/3.8.12/x64/lib/python3.8/site-packages/urllib3/connectionpool.py", line 421, in _make_request
    httplib_response = conn.getresponse()
  File "/opt/hostedtoolcache/Python/3.8.12/x64/lib/python3.8/http/client.py", line 1348, in getresponse
    response.begin()
  File "/opt/hostedtoolcache/Python/3.8.12/x64/lib/python3.8/http/client.py", line 316, in begin
    version, status, reason = self._read_status()
  File "/opt/hostedtoolcache/Python/3.8.12/x64/lib/python3.8/http/client.py", line 285, in _read_status
    raise RemoteDisconnected("Remote end closed connection without"
http.client.RemoteDisconnected: Remote end closed connection without response

During handling of the above exception, another exception occurred:

Traceback (most recent call last):
  File "/opt/hostedtoolcache/Python/3.8.12/x64/lib/python3.8/site-packages/requests/adapters.py", line 439, in send
    resp = conn.urlopen(
  File "/opt/hostedtoolcache/Python/3.8.12/x64/lib/python3.8/site-packages/urllib3/connectionpool.py", line 726, in urlopen
    retries = retries.increment(
  File "/opt/hostedtoolcache/Python/3.8.12/x64/lib/python3.8/site-packages/urllib3/util/retry.py", line 410, in increment
    raise six.reraise(type(error), error, _stacktrace)
  File "/opt/hostedtoolcache/Python/3.8.12/x64/lib/python3.8/site-packages/urllib3/packages/six.py", line 734, in reraise
    raise value.with_traceback(tb)
  File "/opt/hostedtoolcache/Python/3.8.12/x64/lib/python3.8/site-packages/urllib3/connectionpool.py", line 670, in urlopen
    httplib_response = self._make_request(
  File "/opt/hostedtoolcache/Python/3.8.12/x64/lib/python3.8/site-packages/urllib3/connectionpool.py", line 426, in _make_request
    six.raise_from(e, None)
  File "<string>", line 3, in raise_from
  File "/opt/hostedtoolcache/Python/3.8.12/x64/lib/python3.8/site-packages/urllib3/connectionpool.py", line 421, in _make_request
    httplib_response = conn.getresponse()
  File "/opt/hostedtoolcache/Python/3.8.12/x64/lib/python3.8/http/client.py", line 1348, in getresponse
    response.begin()
  File "/opt/hostedtoolcache/Python/3.8.12/x64/lib/python3.8/http/client.py", line 316, in begin
    version, status, reason = self._read_status()
  File "/opt/hostedtoolcache/Python/3.8.12/x64/lib/python3.8/http/client.py", line 285, in _read_status
    raise RemoteDisconnected("Remote end closed connection without"
urllib3.exceptions.ProtocolError: ('Connection aborted.', RemoteDisconnected('Remote end closed connection without response'))

During handling of the above exception, another exception occurred:

Traceback (most recent call last):
  File "/home/runner/work/threat-broadcast/threat-broadcast/src/crawler/_base_crawler.py", line 62, in cves
    new_cves = self.get_cves()
  File "/home/runner/work/threat-broadcast/threat-broadcast/src/crawler/cert360.py", line 48, in get_cves
    response = requests.get(
  File "/opt/hostedtoolcache/Python/3.8.12/x64/lib/python3.8/site-packages/requests/api.py", line 75, in get
    return request('get', url, params=params, **kwargs)
  File "/opt/hostedtoolcache/Python/3.8.12/x64/lib/python3.8/site-packages/requests/api.py", line 60, in request
    return session.request(method=method, url=url, **kwargs)
  File "/opt/hostedtoolcache/Python/3.8.12/x64/lib/python3.8/site-packages/requests/sessions.py", line 533, in request
    resp = self.send(prep, **send_kwargs)
  File "/opt/hostedtoolcache/Python/3.8.12/x64/lib/python3.8/site-packages/requests/sessions.py", line 646, in send
    r = adapter.send(request, **kwargs)
  File "/opt/hostedtoolcache/Python/3.8.12/x64/lib/python3.8/site-packages/requests/adapters.py", line 498, in send
    raise ConnectionError(err, request=request)
requests.exceptions.ConnectionError: ('Connection aborted.', RemoteDisconnected('Remote end closed connection without response'))
2022-02-18 17:27:07 [ERROR] : Traceback (most recent call last):
  File "/opt/hostedtoolcache/Python/3.8.12/x64/lib/python3.8/site-packages/urllib3/connectionpool.py", line 670, in urlopen
    httplib_response = self._make_request(
  File "/opt/hostedtoolcache/Python/3.8.12/x64/lib/python3.8/site-packages/urllib3/connectionpool.py", line 426, in _make_request
    six.raise_from(e, None)
  File "<string>", line 3, in raise_from
  File "/opt/hostedtoolcache/Python/3.8.12/x64/lib/python3.8/site-packages/urllib3/connectionpool.py", line 421, in _make_request
    httplib_response = conn.getresponse()
  File "/opt/hostedtoolcache/Python/3.8.12/x64/lib/python3.8/http/client.py", line 1348, in getresponse
    response.begin()
  File "/opt/hostedtoolcache/Python/3.8.12/x64/lib/python3.8/http/client.py", line 316, in begin
    version, status, reason = self._read_status()
  File "/opt/hostedtoolcache/Python/3.8.12/x64/lib/python3.8/http/client.py", line 285, in _read_status
    raise RemoteDisconnected("Remote end closed connection without"
http.client.RemoteDisconnected: Remote end closed connection without response

During handling of the above exception, another exception occurred:

Traceback (most recent call last):
  File "/opt/hostedtoolcache/Python/3.8.12/x64/lib/python3.8/site-packages/requests/adapters.py", line 439, in send
    resp = conn.urlopen(
  File "/opt/hostedtoolcache/Python/3.8.12/x64/lib/python3.8/site-packages/urllib3/connectionpool.py", line 726, in urlopen
    retries = retries.increment(
  File "/opt/hostedtoolcache/Python/3.8.12/x64/lib/python3.8/site-packages/urllib3/util/retry.py", line 410, in increment
    raise six.reraise(type(error), error, _stacktrace)
  File "/opt/hostedtoolcache/Python/3.8.12/x64/lib/python3.8/site-packages/urllib3/packages/six.py", line 734, in reraise
    raise value.with_traceback(tb)
  File "/opt/hostedtoolcache/Python/3.8.12/x64/lib/python3.8/site-packages/urllib3/connectionpool.py", line 670, in urlopen
    httplib_response = self._make_request(
  File "/opt/hostedtoolcache/Python/3.8.12/x64/lib/python3.8/site-packages/urllib3/connectionpool.py", line 426, in _make_request
    six.raise_from(e, None)
  File "<string>", line 3, in raise_from
  File "/opt/hostedtoolcache/Python/3.8.12/x64/lib/python3.8/site-packages/urllib3/connectionpool.py", line 421, in _make_request
    httplib_response = conn.getresponse()
  File "/opt/hostedtoolcache/Python/3.8.12/x64/lib/python3.8/http/client.py", line 1348, in getresponse
    response.begin()
  File "/opt/hostedtoolcache/Python/3.8.12/x64/lib/python3.8/http/client.py", line 316, in begin
    version, status, reason = self._read_status()
  File "/opt/hostedtoolcache/Python/3.8.12/x64/lib/python3.8/http/client.py", line 285, in _read_status
    raise RemoteDisconnected("Remote end closed connection without"
urllib3.exceptions.ProtocolError: ('Connection aborted.', RemoteDisconnected('Remote end closed connection without response'))

During handling of the above exception, another exception occurred:

Traceback (most recent call last):
  File "/home/runner/work/threat-broadcast/threat-broadcast/src/crawler/_base_crawler.py", line 62, in cves
    new_cves = self.get_cves()
  File "/home/runner/work/threat-broadcast/threat-broadcast/src/crawler/cert360.py", line 48, in get_cves
    response = requests.get(
  File "/opt/hostedtoolcache/Python/3.8.12/x64/lib/python3.8/site-packages/requests/api.py", line 75, in get
    return request('get', url, params=params, **kwargs)
  File "/opt/hostedtoolcache/Python/3.8.12/x64/lib/python3.8/site-packages/requests/api.py", line 60, in request
    return session.request(method=method, url=url, **kwargs)
  File "/opt/hostedtoolcache/Python/3.8.12/x64/lib/python3.8/site-packages/requests/sessions.py", line 533, in request
    resp = self.send(prep, **send_kwargs)
  File "/opt/hostedtoolcache/Python/3.8.12/x64/lib/python3.8/site-packages/requests/sessions.py", line 646, in send
    r = adapter.send(request, **kwargs)
  File "/opt/hostedtoolcache/Python/3.8.12/x64/lib/python3.8/site-packages/requests/adapters.py", line 498, in send
    raise ConnectionError(err, request=request)
requests.exceptions.ConnectionError: ('Connection aborted.', RemoteDisconnected('Remote end closed connection without response'))
Traceback (most recent call last):
  File "/opt/hostedtoolcache/Python/3.8.12/x64/lib/python3.8/site-packages/urllib3/connectionpool.py", line 670, in urlopen
    httplib_response = self._make_request(
  File "/opt/hostedtoolcache/Python/3.8.12/x64/lib/python3.8/site-packages/urllib3/connectionpool.py", line 426, in _make_request
    six.raise_from(e, None)
  File "<string>", line 3, in raise_from
  File "/opt/hostedtoolcache/Python/3.8.12/x64/lib/python3.8/site-packages/urllib3/connectionpool.py", line 421, in _make_request
    httplib_response = conn.getresponse()
  File "/opt/hostedtoolcache/Python/3.8.12/x64/lib/python3.8/http/client.py", line 1348, in getresponse
    response.begin()
  File "/opt/hostedtoolcache/Python/3.8.12/x64/lib/python3.8/http/client.py", line 316, in begin
    version, status, reason = self._read_status()
  File "/opt/hostedtoolcache/Python/3.8.12/x64/lib/python3.8/http/client.py", line 285, in _read_status
    raise RemoteDisconnected("Remote end closed connection without"
http.client.RemoteDisconnected: Remote end closed connection without response

During handling of the above exception, another exception occurred:

Traceback (most recent call last):
  File "/opt/hostedtoolcache/Python/3.8.12/x64/lib/python3.8/site-packages/requests/adapters.py", line 439, in send
    resp = conn.urlopen(
  File "/opt/hostedtoolcache/Python/3.8.12/x64/lib/python3.8/site-packages/urllib3/connectionpool.py", line 726, in urlopen
    retries = retries.increment(
  File "/opt/hostedtoolcache/Python/3.8.12/x64/lib/python3.8/site-packages/urllib3/util/retry.py", line 410, in increment
    raise six.reraise(type(error), error, _stacktrace)
  File "/opt/hostedtoolcache/Python/3.8.12/x64/lib/python3.8/site-packages/urllib3/packages/six.py", line 734, in reraise
    raise value.with_traceback(tb)
  File "/opt/hostedtoolcache/Python/3.8.12/x64/lib/python3.8/site-packages/urllib3/connectionpool.py", line 670, in urlopen
    httplib_response = self._make_request(
  File "/opt/hostedtoolcache/Python/3.8.12/x64/lib/python3.8/site-packages/urllib3/connectionpool.py", line 426, in _make_request
    six.raise_from(e, None)
  File "<string>", line 3, in raise_from
  File "/opt/hostedtoolcache/Python/3.8.12/x64/lib/python3.8/site-packages/urllib3/connectionpool.py", line 421, in _make_request
    httplib_response = conn.getresponse()
  File "/opt/hostedtoolcache/Python/3.8.12/x64/lib/python3.8/http/client.py", line 1348, in getresponse
    response.begin()
  File "/opt/hostedtoolcache/Python/3.8.12/x64/lib/python3.8/http/client.py", line 316, in begin
    version, status, reason = self._read_status()
  File "/opt/hostedtoolcache/Python/3.8.12/x64/lib/python3.8/http/client.py", line 285, in _read_status
    raise RemoteDisconnected("Remote end closed connection without"
urllib3.exceptions.ProtocolError: ('Connection aborted.', RemoteDisconnected('Remote end closed connection without response'))

During handling of the above exception, another exception occurred:

Traceback (most recent call last):
  File "/home/runner/work/threat-broadcast/threat-broadcast/src/crawler/_base_crawler.py", line 62, in cves
    new_cves = self.get_cves()
  File "/home/runner/work/threat-broadcast/threat-broadcast/src/crawler/cert360.py", line 48, in get_cves
    response = requests.get(
  File "/opt/hostedtoolcache/Python/3.8.12/x64/lib/python3.8/site-packages/requests/api.py", line 75, in get
    return request('get', url, params=params, **kwargs)
  File "/opt/hostedtoolcache/Python/3.8.12/x64/lib/python3.8/site-packages/requests/api.py", line 60, in request
    return session.request(method=method, url=url, **kwargs)
  File "/opt/hostedtoolcache/Python/3.8.12/x64/lib/python3.8/site-packages/requests/sessions.py", line 533, in request
    resp = self.send(prep, **send_kwargs)
  File "/opt/hostedtoolcache/Python/3.8.12/x64/lib/python3.8/site-packages/requests/sessions.py", line 646, in send
    r = adapter.send(request, **kwargs)
  File "/opt/hostedtoolcache/Python/3.8.12/x64/lib/python3.8/site-packages/requests/adapters.py", line 498, in send
    raise ConnectionError(err, request=request)
requests.exceptions.ConnectionError: ('Connection aborted.', RemoteDisconnected('Remote end closed connection without response'))
