2023-08-29 00:00:11 [ERROR] : 获取 [国家信息安全漏洞库（CNNVD）] 威胁情报异常
Traceback (most recent call last):
  File "/opt/hostedtoolcache/Python/3.8.17/x64/lib/python3.8/site-packages/urllib3/connection.py", line 159, in _new_conn
    conn = connection.create_connection(
  File "/opt/hostedtoolcache/Python/3.8.17/x64/lib/python3.8/site-packages/urllib3/util/connection.py", line 84, in create_connection
    raise err
  File "/opt/hostedtoolcache/Python/3.8.17/x64/lib/python3.8/site-packages/urllib3/util/connection.py", line 74, in create_connection
    sock.connect(sa)
socket.timeout: timed out

During handling of the above exception, another exception occurred:

Traceback (most recent call last):
  File "/opt/hostedtoolcache/Python/3.8.17/x64/lib/python3.8/site-packages/urllib3/connectionpool.py", line 670, in urlopen
    httplib_response = self._make_request(
  File "/opt/hostedtoolcache/Python/3.8.17/x64/lib/python3.8/site-packages/urllib3/connectionpool.py", line 392, in _make_request
    conn.request(method, url, **httplib_request_kw)
  File "/opt/hostedtoolcache/Python/3.8.17/x64/lib/python3.8/http/client.py", line 1256, in request
    self._send_request(method, url, body, headers, encode_chunked)
  File "/opt/hostedtoolcache/Python/3.8.17/x64/lib/python3.8/http/client.py", line 1302, in _send_request
    self.endheaders(body, encode_chunked=encode_chunked)
  File "/opt/hostedtoolcache/Python/3.8.17/x64/lib/python3.8/http/client.py", line 1251, in endheaders
    self._send_output(message_body, encode_chunked=encode_chunked)
  File "/opt/hostedtoolcache/Python/3.8.17/x64/lib/python3.8/http/client.py", line 1011, in _send_output
    self.send(msg)
  File "/opt/hostedtoolcache/Python/3.8.17/x64/lib/python3.8/http/client.py", line 951, in send
    self.connect()
  File "/opt/hostedtoolcache/Python/3.8.17/x64/lib/python3.8/site-packages/urllib3/connection.py", line 187, in connect
    conn = self._new_conn()
  File "/opt/hostedtoolcache/Python/3.8.17/x64/lib/python3.8/site-packages/urllib3/connection.py", line 164, in _new_conn
    raise ConnectTimeoutError(
urllib3.exceptions.ConnectTimeoutError: (<urllib3.connection.HTTPConnection object at 0x7fdc68a14820>, 'Connection to www.cnnvd.org.cn timed out. (connect timeout=60)')

During handling of the above exception, another exception occurred:

Traceback (most recent call last):
  File "/opt/hostedtoolcache/Python/3.8.17/x64/lib/python3.8/site-packages/requests/adapters.py", line 439, in send
    resp = conn.urlopen(
  File "/opt/hostedtoolcache/Python/3.8.17/x64/lib/python3.8/site-packages/urllib3/connectionpool.py", line 726, in urlopen
    retries = retries.increment(
  File "/opt/hostedtoolcache/Python/3.8.17/x64/lib/python3.8/site-packages/urllib3/util/retry.py", line 446, in increment
    raise MaxRetryError(_pool, url, error or ResponseError(cause))
urllib3.exceptions.MaxRetryError: HTTPConnectionPool(host='www.cnnvd.org.cn', port=80): Max retries exceeded with url: /web/vulnerability/querylist.tag (Caused by ConnectTimeoutError(<urllib3.connection.HTTPConnection object at 0x7fdc68a14820>, 'Connection to www.cnnvd.org.cn timed out. (connect timeout=60)'))

During handling of the above exception, another exception occurred:

Traceback (most recent call last):
  File "/home/runner/work/threat-broadcast/threat-broadcast/src/crawler/_base_crawler.py", line 62, in cves
    new_cves = self.get_cves()
  File "/home/runner/work/threat-broadcast/threat-broadcast/src/crawler/cnnvd.py", line 43, in get_cves
    response = requests.get(
  File "/opt/hostedtoolcache/Python/3.8.17/x64/lib/python3.8/site-packages/requests/api.py", line 75, in get
    return request('get', url, params=params, **kwargs)
  File "/opt/hostedtoolcache/Python/3.8.17/x64/lib/python3.8/site-packages/requests/api.py", line 60, in request
    return session.request(method=method, url=url, **kwargs)
  File "/opt/hostedtoolcache/Python/3.8.17/x64/lib/python3.8/site-packages/requests/sessions.py", line 533, in request
    resp = self.send(prep, **send_kwargs)
  File "/opt/hostedtoolcache/Python/3.8.17/x64/lib/python3.8/site-packages/requests/sessions.py", line 646, in send
    r = adapter.send(request, **kwargs)
  File "/opt/hostedtoolcache/Python/3.8.17/x64/lib/python3.8/site-packages/requests/adapters.py", line 504, in send
    raise ConnectTimeout(e, request=request)
requests.exceptions.ConnectTimeout: HTTPConnectionPool(host='www.cnnvd.org.cn', port=80): Max retries exceeded with url: /web/vulnerability/querylist.tag (Caused by ConnectTimeoutError(<urllib3.connection.HTTPConnection object at 0x7fdc68a14820>, 'Connection to www.cnnvd.org.cn timed out. (connect timeout=60)'))
2023-08-29 00:00:11 [ERROR] : Traceback (most recent call last):
  File "/opt/hostedtoolcache/Python/3.8.17/x64/lib/python3.8/site-packages/urllib3/connection.py", line 159, in _new_conn
    conn = connection.create_connection(
  File "/opt/hostedtoolcache/Python/3.8.17/x64/lib/python3.8/site-packages/urllib3/util/connection.py", line 84, in create_connection
    raise err
  File "/opt/hostedtoolcache/Python/3.8.17/x64/lib/python3.8/site-packages/urllib3/util/connection.py", line 74, in create_connection
    sock.connect(sa)
socket.timeout: timed out

During handling of the above exception, another exception occurred:

Traceback (most recent call last):
  File "/opt/hostedtoolcache/Python/3.8.17/x64/lib/python3.8/site-packages/urllib3/connectionpool.py", line 670, in urlopen
    httplib_response = self._make_request(
  File "/opt/hostedtoolcache/Python/3.8.17/x64/lib/python3.8/site-packages/urllib3/connectionpool.py", line 392, in _make_request
    conn.request(method, url, **httplib_request_kw)
  File "/opt/hostedtoolcache/Python/3.8.17/x64/lib/python3.8/http/client.py", line 1256, in request
    self._send_request(method, url, body, headers, encode_chunked)
  File "/opt/hostedtoolcache/Python/3.8.17/x64/lib/python3.8/http/client.py", line 1302, in _send_request
    self.endheaders(body, encode_chunked=encode_chunked)
  File "/opt/hostedtoolcache/Python/3.8.17/x64/lib/python3.8/http/client.py", line 1251, in endheaders
    self._send_output(message_body, encode_chunked=encode_chunked)
  File "/opt/hostedtoolcache/Python/3.8.17/x64/lib/python3.8/http/client.py", line 1011, in _send_output
    self.send(msg)
  File "/opt/hostedtoolcache/Python/3.8.17/x64/lib/python3.8/http/client.py", line 951, in send
    self.connect()
  File "/opt/hostedtoolcache/Python/3.8.17/x64/lib/python3.8/site-packages/urllib3/connection.py", line 187, in connect
    conn = self._new_conn()
  File "/opt/hostedtoolcache/Python/3.8.17/x64/lib/python3.8/site-packages/urllib3/connection.py", line 164, in _new_conn
    raise ConnectTimeoutError(
urllib3.exceptions.ConnectTimeoutError: (<urllib3.connection.HTTPConnection object at 0x7fdc68a14820>, 'Connection to www.cnnvd.org.cn timed out. (connect timeout=60)')

During handling of the above exception, another exception occurred:

Traceback (most recent call last):
  File "/opt/hostedtoolcache/Python/3.8.17/x64/lib/python3.8/site-packages/requests/adapters.py", line 439, in send
    resp = conn.urlopen(
  File "/opt/hostedtoolcache/Python/3.8.17/x64/lib/python3.8/site-packages/urllib3/connectionpool.py", line 726, in urlopen
    retries = retries.increment(
  File "/opt/hostedtoolcache/Python/3.8.17/x64/lib/python3.8/site-packages/urllib3/util/retry.py", line 446, in increment
    raise MaxRetryError(_pool, url, error or ResponseError(cause))
urllib3.exceptions.MaxRetryError: HTTPConnectionPool(host='www.cnnvd.org.cn', port=80): Max retries exceeded with url: /web/vulnerability/querylist.tag (Caused by ConnectTimeoutError(<urllib3.connection.HTTPConnection object at 0x7fdc68a14820>, 'Connection to www.cnnvd.org.cn timed out. (connect timeout=60)'))

During handling of the above exception, another exception occurred:

Traceback (most recent call last):
  File "/home/runner/work/threat-broadcast/threat-broadcast/src/crawler/_base_crawler.py", line 62, in cves
    new_cves = self.get_cves()
  File "/home/runner/work/threat-broadcast/threat-broadcast/src/crawler/cnnvd.py", line 43, in get_cves
    response = requests.get(
  File "/opt/hostedtoolcache/Python/3.8.17/x64/lib/python3.8/site-packages/requests/api.py", line 75, in get
    return request('get', url, params=params, **kwargs)
  File "/opt/hostedtoolcache/Python/3.8.17/x64/lib/python3.8/site-packages/requests/api.py", line 60, in request
    return session.request(method=method, url=url, **kwargs)
  File "/opt/hostedtoolcache/Python/3.8.17/x64/lib/python3.8/site-packages/requests/sessions.py", line 533, in request
    resp = self.send(prep, **send_kwargs)
  File "/opt/hostedtoolcache/Python/3.8.17/x64/lib/python3.8/site-packages/requests/sessions.py", line 646, in send
    r = adapter.send(request, **kwargs)
  File "/opt/hostedtoolcache/Python/3.8.17/x64/lib/python3.8/site-packages/requests/adapters.py", line 504, in send
    raise ConnectTimeout(e, request=request)
requests.exceptions.ConnectTimeout: HTTPConnectionPool(host='www.cnnvd.org.cn', port=80): Max retries exceeded with url: /web/vulnerability/querylist.tag (Caused by ConnectTimeoutError(<urllib3.connection.HTTPConnection object at 0x7fdc68a14820>, 'Connection to www.cnnvd.org.cn timed out. (connect timeout=60)'))
Traceback (most recent call last):
  File "/opt/hostedtoolcache/Python/3.8.17/x64/lib/python3.8/site-packages/urllib3/connection.py", line 159, in _new_conn
    conn = connection.create_connection(
  File "/opt/hostedtoolcache/Python/3.8.17/x64/lib/python3.8/site-packages/urllib3/util/connection.py", line 84, in create_connection
    raise err
  File "/opt/hostedtoolcache/Python/3.8.17/x64/lib/python3.8/site-packages/urllib3/util/connection.py", line 74, in create_connection
    sock.connect(sa)
socket.timeout: timed out

During handling of the above exception, another exception occurred:

Traceback (most recent call last):
  File "/opt/hostedtoolcache/Python/3.8.17/x64/lib/python3.8/site-packages/urllib3/connectionpool.py", line 670, in urlopen
    httplib_response = self._make_request(
  File "/opt/hostedtoolcache/Python/3.8.17/x64/lib/python3.8/site-packages/urllib3/connectionpool.py", line 392, in _make_request
    conn.request(method, url, **httplib_request_kw)
  File "/opt/hostedtoolcache/Python/3.8.17/x64/lib/python3.8/http/client.py", line 1256, in request
    self._send_request(method, url, body, headers, encode_chunked)
  File "/opt/hostedtoolcache/Python/3.8.17/x64/lib/python3.8/http/client.py", line 1302, in _send_request
    self.endheaders(body, encode_chunked=encode_chunked)
  File "/opt/hostedtoolcache/Python/3.8.17/x64/lib/python3.8/http/client.py", line 1251, in endheaders
    self._send_output(message_body, encode_chunked=encode_chunked)
  File "/opt/hostedtoolcache/Python/3.8.17/x64/lib/python3.8/http/client.py", line 1011, in _send_output
    self.send(msg)
  File "/opt/hostedtoolcache/Python/3.8.17/x64/lib/python3.8/http/client.py", line 951, in send
    self.connect()
  File "/opt/hostedtoolcache/Python/3.8.17/x64/lib/python3.8/site-packages/urllib3/connection.py", line 187, in connect
    conn = self._new_conn()
  File "/opt/hostedtoolcache/Python/3.8.17/x64/lib/python3.8/site-packages/urllib3/connection.py", line 164, in _new_conn
    raise ConnectTimeoutError(
urllib3.exceptions.ConnectTimeoutError: (<urllib3.connection.HTTPConnection object at 0x7fdc68a14820>, 'Connection to www.cnnvd.org.cn timed out. (connect timeout=60)')

During handling of the above exception, another exception occurred:

Traceback (most recent call last):
  File "/opt/hostedtoolcache/Python/3.8.17/x64/lib/python3.8/site-packages/requests/adapters.py", line 439, in send
    resp = conn.urlopen(
  File "/opt/hostedtoolcache/Python/3.8.17/x64/lib/python3.8/site-packages/urllib3/connectionpool.py", line 726, in urlopen
    retries = retries.increment(
  File "/opt/hostedtoolcache/Python/3.8.17/x64/lib/python3.8/site-packages/urllib3/util/retry.py", line 446, in increment
    raise MaxRetryError(_pool, url, error or ResponseError(cause))
urllib3.exceptions.MaxRetryError: HTTPConnectionPool(host='www.cnnvd.org.cn', port=80): Max retries exceeded with url: /web/vulnerability/querylist.tag (Caused by ConnectTimeoutError(<urllib3.connection.HTTPConnection object at 0x7fdc68a14820>, 'Connection to www.cnnvd.org.cn timed out. (connect timeout=60)'))

During handling of the above exception, another exception occurred:

Traceback (most recent call last):
  File "/home/runner/work/threat-broadcast/threat-broadcast/src/crawler/_base_crawler.py", line 62, in cves
    new_cves = self.get_cves()
  File "/home/runner/work/threat-broadcast/threat-broadcast/src/crawler/cnnvd.py", line 43, in get_cves
    response = requests.get(
  File "/opt/hostedtoolcache/Python/3.8.17/x64/lib/python3.8/site-packages/requests/api.py", line 75, in get
    return request('get', url, params=params, **kwargs)
  File "/opt/hostedtoolcache/Python/3.8.17/x64/lib/python3.8/site-packages/requests/api.py", line 60, in request
    return session.request(method=method, url=url, **kwargs)
  File "/opt/hostedtoolcache/Python/3.8.17/x64/lib/python3.8/site-packages/requests/sessions.py", line 533, in request
    resp = self.send(prep, **send_kwargs)
  File "/opt/hostedtoolcache/Python/3.8.17/x64/lib/python3.8/site-packages/requests/sessions.py", line 646, in send
    r = adapter.send(request, **kwargs)
  File "/opt/hostedtoolcache/Python/3.8.17/x64/lib/python3.8/site-packages/requests/adapters.py", line 504, in send
    raise ConnectTimeout(e, request=request)
requests.exceptions.ConnectTimeout: HTTPConnectionPool(host='www.cnnvd.org.cn', port=80): Max retries exceeded with url: /web/vulnerability/querylist.tag (Caused by ConnectTimeoutError(<urllib3.connection.HTTPConnection object at 0x7fdc68a14820>, 'Connection to www.cnnvd.org.cn timed out. (connect timeout=60)'))
2023-08-29 00:00:11 [INFO] : 得到 [国家信息安全漏洞库（CNNVD）] 最新威胁情报 [0] 条
2023-08-29 00:00:11 [INFO] : --------------------------------------------
2023-08-29 00:00:11 [INFO] : ++++++++++++++++++++++++++++++++++++++++++++
2023-08-29 00:00:11 [INFO] : 正在获取 [360 网络安全响应中心] 威胁情报...
2023-08-29 00:00:18 [INFO] : 得到 [360 网络安全响应中心] 最新威胁情报 [0] 条
2023-08-29 00:00:18 [INFO] : --------------------------------------------
2023-08-29 00:00:18 [INFO] : ++++++++++++++++++++++++++++++++++++++++++++
2023-08-29 00:00:18 [INFO] : 正在获取 [美国国家漏洞数据库（NVD）] 威胁情报...
2023-08-29 00:00:19 [INFO] : 得到 [美国国家漏洞数据库（NVD）] 最新威胁情报 [0] 条
2023-08-29 00:00:19 [INFO] : --------------------------------------------
2023-08-29 00:00:19 [INFO] : ++++++++++++++++++++++++++++++++++++++++++++
2023-08-29 00:00:19 [INFO] : 正在获取 [信息安全漏洞门户] 威胁情报...
2023-08-29 00:00:20 [WARNING] : 获取 [信息安全漏洞门户] 威胁情报失败： [HTTP Error 404]
2023-08-29 00:00:20 [INFO] : 得到 [信息安全漏洞门户] 最新威胁情报 [0] 条
2023-08-29 00:00:20 [INFO] : --------------------------------------------
2023-08-29 00:00:20 [INFO] : ++++++++++++++++++++++++++++++++++++++++++++
2023-08-29 00:00:20 [INFO] : 正在获取 [绿盟] 威胁情报...
2023-08-29 00:00:21 [INFO] : 得到 [绿盟] 最新威胁情报 [0] 条
2023-08-29 00:00:21 [INFO] : --------------------------------------------
2023-08-29 00:00:21 [INFO] : ++++++++++++++++++++++++++++++++++++++++++++
2023-08-29 00:00:21 [INFO] : 正在获取 [奇安信] 威胁情报...
2023-08-29 00:00:23 [INFO] : 得到 [奇安信] 最新威胁情报 [0] 条
2023-08-29 00:00:23 [INFO] : --------------------------------------------
2023-08-29 00:00:23 [INFO] : ++++++++++++++++++++++++++++++++++++++++++++
2023-08-29 00:00:23 [INFO] : 正在获取 [红后] 威胁情报...
2023-08-29 00:00:24 [INFO] : 得到 [红后] 最新威胁情报 [0] 条
2023-08-29 00:00:24 [INFO] : --------------------------------------------
2023-08-29 00:00:24 [INFO] : ++++++++++++++++++++++++++++++++++++++++++++
2023-08-29 00:00:24 [INFO] : 正在获取 [斗象] 威胁情报...
2023-08-29 00:00:28 [ERROR] : 获取 [斗象] 威胁情报异常
Traceback (most recent call last):
  File "/home/runner/work/threat-broadcast/threat-broadcast/src/crawler/_base_crawler.py", line 62, in cves
    new_cves = self.get_cves()
  File "/home/runner/work/threat-broadcast/threat-broadcast/src/crawler/vas.py", line 67, in get_cves
    for obj in json_obj.get('data').get('items'):
AttributeError: 'bool' object has no attribute 'get'
2023-08-29 00:00:28 [ERROR] : Traceback (most recent call last):
  File "/home/runner/work/threat-broadcast/threat-broadcast/src/crawler/_base_crawler.py", line 62, in cves
    new_cves = self.get_cves()
  File "/home/runner/work/threat-broadcast/threat-broadcast/src/crawler/vas.py", line 67, in get_cves
    for obj in json_obj.get('data').get('items'):
AttributeError: 'bool' object has no attribute 'get'
Traceback (most recent call last):
  File "/home/runner/work/threat-broadcast/threat-broadcast/src/crawler/_base_crawler.py", line 62, in cves
    new_cves = self.get_cves()
  File "/home/runner/work/threat-broadcast/threat-broadcast/src/crawler/vas.py", line 67, in get_cves
    for obj in json_obj.get('data').get('items'):
AttributeError: 'bool' object has no attribute 'get'
2023-08-29 00:00:28 [INFO] : 得到 [斗象] 最新威胁情报 [0] 条
2023-08-29 00:00:28 [INFO] : --------------------------------------------
2023-08-29 00:00:28 [INFO] : ++++++++++++++++++++++++++++++++++++++++++++
2023-08-29 00:00:28 [INFO] : 正在获取 [Tenable (Nessus)] 威胁情报...
2023-08-29 00:00:29 [INFO] : 得到 [Tenable (Nessus)] 最新威胁情报 [9] 条
2023-08-29 00:00:29 [INFO] : --------------------------------------------
2023-08-29 00:00:29 [INFO] : 
==============================================
[ TITLE ] jupyter-server is the backend for Jupyter web applications. Improper cross-site credential checks on `/files/` URLs could allow exposure of certain file contents, or accessing files when opening untrusted files via  "Open image in new tab". This issue has been addressed in commit `87a49272728` which has been included in release `2.7.2`. Users are advised to upgrade. Users unable to upgrade may use the lower performance `--ContentsManager.files_handler_class=jupyter_server.files.handlers.FilesHandler`, which implements the correct checks.
[ TIME  ] 2023-08-28 21:15:00
[ CVE   ] CVE-2023-40170
[ SRC   ] Tenable (Nessus)
[ URL   ] https://www.tenable.com/cve/CVE-2023-40170
2023-08-29 00:00:29 [INFO] : 
==============================================
[ TITLE ] jupyter-server is the backend for Jupyter web applications. Open Redirect Vulnerability. Maliciously crafted login links to known Jupyter Servers can cause successful login or an already logged-in session to be redirected to arbitrary sites, which should be restricted to Jupyter Server-served URLs. This issue has been addressed in commit `29036259` which is included in release 2.7.2. Users are advised to upgrade. There are no known workarounds for this vulnerability.
[ TIME  ] 2023-08-28 21:15:00
[ CVE   ] CVE-2023-39968
[ SRC   ] Tenable (Nessus)
[ URL   ] https://www.tenable.com/cve/CVE-2023-39968
2023-08-29 00:00:29 [INFO] : 
==============================================
[ TITLE ] theme volty tvcmsvideotab up to v4.0.0 was discovered to contain a SQL injection vulnerability via the component TvcmsVideoTabConfirmDeleteModuleFrontController::run().
[ TIME  ] 2023-08-28 21:15:00
[ CVE   ] CVE-2023-39652
[ SRC   ] Tenable (Nessus)
[ URL   ] https://www.tenable.com/cve/CVE-2023-39652
2023-08-29 00:00:29 [INFO] : 
==============================================
[ TITLE ] Cross Site Scripting vulnerabiltiy in Badaso v.2.9.7 allows a remote attacker to execute arbitrary code via a crafted payload to the title parameter in the new book and edit book function.
[ TIME  ] 2023-08-28 21:15:00
[ CVE   ] CVE-2023-38969
[ SRC   ] Tenable (Nessus)
[ URL   ] https://www.tenable.com/cve/CVE-2023-38969
2023-08-29 00:00:29 [INFO] : 
==============================================
[ TITLE ] An issue was discovered in TCG Accelerator in QEMU 4.2.0, allows local attackers to execute arbitrary code, escalate privileges, and cause a denial of service (DoS).
[ TIME  ] 2023-08-28 21:15:00
[ CVE   ] CVE-2020-24165
[ SRC   ] Tenable (Nessus)
[ URL   ] https://www.tenable.com/cve/CVE-2020-24165
2023-08-29 00:00:29 [INFO] : 
==============================================
[ TITLE ] SmartNode SN200 (aka SN200) 3.21.2-23021 allows unauthenticated OS Command Injection.
[ TIME  ] 2023-08-28 20:15:00
[ CVE   ] CVE-2023-41109
[ SRC   ] Tenable (Nessus)
[ URL   ] https://www.tenable.com/cve/CVE-2023-41109
2023-08-29 00:00:29 [INFO] : 
==============================================
[ TITLE ] A stored cross-site scripting (XSS) vulnerability in the Create function of Zenario CMS v9.4 allows attackers to execute arbitrary web scripts or HTML via a crafted payload injected into the Menu navigation text field.
[ TIME  ] 2023-08-28 20:15:00
[ CVE   ] CVE-2023-39578
[ SRC   ] Tenable (Nessus)
[ URL   ] https://www.tenable.com/cve/CVE-2023-39578
2023-08-29 00:00:29 [INFO] : 
==============================================
[ TITLE ] Spinnaker is an open source, multi-cloud continuous delivery platform. Log output when updating GitHub status is improperly set to FULL always.  It's recommended to apply the patch and rotate the GitHub token used for github status notifications.  Given that this would output github tokens to a log system, the risk is slightly higher than a "low" since token exposure could grant elevated access to repositories outside of control.  If using READ restricted tokens, the exposure is such that the token itself could be used to access resources otherwise restricted from reads. This only affects users of GitHub Status Notifications. This issue has been addressed in pull request 1316. Users are advised to upgrade. Users unable to upgrade should disable GH Status Notifications, Filter their logs for Echo log data and use read-only tokens that are limited in scope.
[ TIME  ] 2023-08-28 20:15:00
[ CVE   ] CVE-2023-39348
[ SRC   ] Tenable (Nessus)
[ URL   ] https://www.tenable.com/cve/CVE-2023-39348
2023-08-29 00:00:29 [INFO] : 
==============================================
[ TITLE ] Zoho ManageEngine ADManager Plus through 7186 is vulnerable to 2FA bypass.
[ TIME  ] 2023-08-28 20:15:00
[ CVE   ] CVE-2023-35785
[ SRC   ] Tenable (Nessus)
[ URL   ] https://www.tenable.com/cve/CVE-2023-35785
2023-08-29 00:00:29 [INFO] : [邮件] 正在通过 Github Actions 推送威胁情报...
2023-08-29 01:32:21 [INFO] : ++++++++++++++++++++++++++++++++++++++++++++
2023-08-29 01:32:21 [INFO] : 正在获取 [数字观星POC++] 威胁情报...
2023-08-29 01:32:23 [INFO] : 得到 [数字观星POC++] 最新威胁情报 [0] 条
2023-08-29 01:32:23 [INFO] : --------------------------------------------
2023-08-29 01:32:23 [INFO] : ++++++++++++++++++++++++++++++++++++++++++++
2023-08-29 01:32:23 [INFO] : 正在获取 [阿里云] 威胁情报...
2023-08-29 01:32:25 [INFO] : 得到 [阿里云] 最新威胁情报 [0] 条
2023-08-29 01:32:25 [INFO] : --------------------------------------------
2023-08-29 01:32:25 [INFO] : ++++++++++++++++++++++++++++++++++++++++++++
2023-08-29 01:32:25 [INFO] : 正在获取 [国家信息安全漏洞共享平台（CNVD）] 威胁情报...
2023-08-29 01:32:58 [INFO] : 得到 [国家信息安全漏洞共享平台（CNVD）] 最新威胁情报 [0] 条
2023-08-29 01:32:58 [INFO] : --------------------------------------------
2023-08-29 01:32:58 [INFO] : ++++++++++++++++++++++++++++++++++++++++++++
2023-08-29 01:32:58 [INFO] : 正在获取 [国家信息安全漏洞库（CNNVD）] 威胁情报...
2023-08-29 01:34:58 [ERROR] : 获取 [国家信息安全漏洞库（CNNVD）] 威胁情报异常
Traceback (most recent call last):
  File "/opt/hostedtoolcache/Python/3.8.17/x64/lib/python3.8/site-packages/urllib3/connection.py", line 159, in _new_conn
    conn = connection.create_connection(
  File "/opt/hostedtoolcache/Python/3.8.17/x64/lib/python3.8/site-packages/urllib3/util/connection.py", line 84, in create_connection
    raise err
  File "/opt/hostedtoolcache/Python/3.8.17/x64/lib/python3.8/site-packages/urllib3/util/connection.py", line 74, in create_connection
    sock.connect(sa)
socket.timeout: timed out

During handling of the above exception, another exception occurred:

Traceback (most recent call last):
  File "/opt/hostedtoolcache/Python/3.8.17/x64/lib/python3.8/site-packages/urllib3/connectionpool.py", line 670, in urlopen
    httplib_response = self._make_request(
  File "/opt/hostedtoolcache/Python/3.8.17/x64/lib/python3.8/site-packages/urllib3/connectionpool.py", line 392, in _make_request
    conn.request(method, url, **httplib_request_kw)
  File "/opt/hostedtoolcache/Python/3.8.17/x64/lib/python3.8/http/client.py", line 1256, in request
    self._send_request(method, url, body, headers, encode_chunked)
  File "/opt/hostedtoolcache/Python/3.8.17/x64/lib/python3.8/http/client.py", line 1302, in _send_request
    self.endheaders(body, encode_chunked=encode_chunked)
  File "/opt/hostedtoolcache/Python/3.8.17/x64/lib/python3.8/http/client.py", line 1251, in endheaders
    self._send_output(message_body, encode_chunked=encode_chunked)
  File "/opt/hostedtoolcache/Python/3.8.17/x64/lib/python3.8/http/client.py", line 1011, in _send_output
    self.send(msg)
  File "/opt/hostedtoolcache/Python/3.8.17/x64/lib/python3.8/http/client.py", line 951, in send
    self.connect()
  File "/opt/hostedtoolcache/Python/3.8.17/x64/lib/python3.8/site-packages/urllib3/connection.py", line 187, in connect
    conn = self._new_conn()
  File "/opt/hostedtoolcache/Python/3.8.17/x64/lib/python3.8/site-packages/urllib3/connection.py", line 164, in _new_conn
    raise ConnectTimeoutError(
urllib3.exceptions.ConnectTimeoutError: (<urllib3.connection.HTTPConnection object at 0x7eff4a7c17c0>, 'Connection to www.cnnvd.org.cn timed out. (connect timeout=60)')

During handling of the above exception, another exception occurred:

Traceback (most recent call last):
  File "/opt/hostedtoolcache/Python/3.8.17/x64/lib/python3.8/site-packages/requests/adapters.py", line 439, in send
    resp = conn.urlopen(
  File "/opt/hostedtoolcache/Python/3.8.17/x64/lib/python3.8/site-packages/urllib3/connectionpool.py", line 726, in urlopen
    retries = retries.increment(
  File "/opt/hostedtoolcache/Python/3.8.17/x64/lib/python3.8/site-packages/urllib3/util/retry.py", line 446, in increment
    raise MaxRetryError(_pool, url, error or ResponseError(cause))
urllib3.exceptions.MaxRetryError: HTTPConnectionPool(host='www.cnnvd.org.cn', port=80): Max retries exceeded with url: /web/vulnerability/querylist.tag (Caused by ConnectTimeoutError(<urllib3.connection.HTTPConnection object at 0x7eff4a7c17c0>, 'Connection to www.cnnvd.org.cn timed out. (connect timeout=60)'))

During handling of the above exception, another exception occurred:

Traceback (most recent call last):
  File "/home/runner/work/threat-broadcast/threat-broadcast/src/crawler/_base_crawler.py", line 62, in cves
    new_cves = self.get_cves()
  File "/home/runner/work/threat-broadcast/threat-broadcast/src/crawler/cnnvd.py", line 43, in get_cves
    response = requests.get(
  File "/opt/hostedtoolcache/Python/3.8.17/x64/lib/python3.8/site-packages/requests/api.py", line 75, in get
    return request('get', url, params=params, **kwargs)
  File "/opt/hostedtoolcache/Python/3.8.17/x64/lib/python3.8/site-packages/requests/api.py", line 60, in request
    return session.request(method=method, url=url, **kwargs)
  File "/opt/hostedtoolcache/Python/3.8.17/x64/lib/python3.8/site-packages/requests/sessions.py", line 533, in request
    resp = self.send(prep, **send_kwargs)
  File "/opt/hostedtoolcache/Python/3.8.17/x64/lib/python3.8/site-packages/requests/sessions.py", line 646, in send
    r = adapter.send(request, **kwargs)
  File "/opt/hostedtoolcache/Python/3.8.17/x64/lib/python3.8/site-packages/requests/adapters.py", line 504, in send
    raise ConnectTimeout(e, request=request)
requests.exceptions.ConnectTimeout: HTTPConnectionPool(host='www.cnnvd.org.cn', port=80): Max retries exceeded with url: /web/vulnerability/querylist.tag (Caused by ConnectTimeoutError(<urllib3.connection.HTTPConnection object at 0x7eff4a7c17c0>, 'Connection to www.cnnvd.org.cn timed out. (connect timeout=60)'))
2023-08-29 01:34:58 [ERROR] : Traceback (most recent call last):
  File "/opt/hostedtoolcache/Python/3.8.17/x64/lib/python3.8/site-packages/urllib3/connection.py", line 159, in _new_conn
    conn = connection.create_connection(
  File "/opt/hostedtoolcache/Python/3.8.17/x64/lib/python3.8/site-packages/urllib3/util/connection.py", line 84, in create_connection
    raise err
  File "/opt/hostedtoolcache/Python/3.8.17/x64/lib/python3.8/site-packages/urllib3/util/connection.py", line 74, in create_connection
    sock.connect(sa)
socket.timeout: timed out

During handling of the above exception, another exception occurred:

Traceback (most recent call last):
  File "/opt/hostedtoolcache/Python/3.8.17/x64/lib/python3.8/site-packages/urllib3/connectionpool.py", line 670, in urlopen
    httplib_response = self._make_request(
  File "/opt/hostedtoolcache/Python/3.8.17/x64/lib/python3.8/site-packages/urllib3/connectionpool.py", line 392, in _make_request
    conn.request(method, url, **httplib_request_kw)
  File "/opt/hostedtoolcache/Python/3.8.17/x64/lib/python3.8/http/client.py", line 1256, in request
    self._send_request(method, url, body, headers, encode_chunked)
  File "/opt/hostedtoolcache/Python/3.8.17/x64/lib/python3.8/http/client.py", line 1302, in _send_request
    self.endheaders(body, encode_chunked=encode_chunked)
  File "/opt/hostedtoolcache/Python/3.8.17/x64/lib/python3.8/http/client.py", line 1251, in endheaders
    self._send_output(message_body, encode_chunked=encode_chunked)
  File "/opt/hostedtoolcache/Python/3.8.17/x64/lib/python3.8/http/client.py", line 1011, in _send_output
    self.send(msg)
  File "/opt/hostedtoolcache/Python/3.8.17/x64/lib/python3.8/http/client.py", line 951, in send
    self.connect()
  File "/opt/hostedtoolcache/Python/3.8.17/x64/lib/python3.8/site-packages/urllib3/connection.py", line 187, in connect
    conn = self._new_conn()
  File "/opt/hostedtoolcache/Python/3.8.17/x64/lib/python3.8/site-packages/urllib3/connection.py", line 164, in _new_conn
    raise ConnectTimeoutError(
urllib3.exceptions.ConnectTimeoutError: (<urllib3.connection.HTTPConnection object at 0x7eff4a7c17c0>, 'Connection to www.cnnvd.org.cn timed out. (connect timeout=60)')

During handling of the above exception, another exception occurred:

Traceback (most recent call last):
  File "/opt/hostedtoolcache/Python/3.8.17/x64/lib/python3.8/site-packages/requests/adapters.py", line 439, in send
    resp = conn.urlopen(
  File "/opt/hostedtoolcache/Python/3.8.17/x64/lib/python3.8/site-packages/urllib3/connectionpool.py", line 726, in urlopen
    retries = retries.increment(
  File "/opt/hostedtoolcache/Python/3.8.17/x64/lib/python3.8/site-packages/urllib3/util/retry.py", line 446, in increment
    raise MaxRetryError(_pool, url, error or ResponseError(cause))
urllib3.exceptions.MaxRetryError: HTTPConnectionPool(host='www.cnnvd.org.cn', port=80): Max retries exceeded with url: /web/vulnerability/querylist.tag (Caused by ConnectTimeoutError(<urllib3.connection.HTTPConnection object at 0x7eff4a7c17c0>, 'Connection to www.cnnvd.org.cn timed out. (connect timeout=60)'))

During handling of the above exception, another exception occurred:

Traceback (most recent call last):
  File "/home/runner/work/threat-broadcast/threat-broadcast/src/crawler/_base_crawler.py", line 62, in cves
    new_cves = self.get_cves()
  File "/home/runner/work/threat-broadcast/threat-broadcast/src/crawler/cnnvd.py", line 43, in get_cves
    response = requests.get(
  File "/opt/hostedtoolcache/Python/3.8.17/x64/lib/python3.8/site-packages/requests/api.py", line 75, in get
    return request('get', url, params=params, **kwargs)
  File "/opt/hostedtoolcache/Python/3.8.17/x64/lib/python3.8/site-packages/requests/api.py", line 60, in request
    return session.request(method=method, url=url, **kwargs)
  File "/opt/hostedtoolcache/Python/3.8.17/x64/lib/python3.8/site-packages/requests/sessions.py", line 533, in request
    resp = self.send(prep, **send_kwargs)
  File "/opt/hostedtoolcache/Python/3.8.17/x64/lib/python3.8/site-packages/requests/sessions.py", line 646, in send
    r = adapter.send(request, **kwargs)
  File "/opt/hostedtoolcache/Python/3.8.17/x64/lib/python3.8/site-packages/requests/adapters.py", line 504, in send
    raise ConnectTimeout(e, request=request)
requests.exceptions.ConnectTimeout: HTTPConnectionPool(host='www.cnnvd.org.cn', port=80): Max retries exceeded with url: /web/vulnerability/querylist.tag (Caused by ConnectTimeoutError(<urllib3.connection.HTTPConnection object at 0x7eff4a7c17c0>, 'Connection to www.cnnvd.org.cn timed out. (connect timeout=60)'))
Traceback (most recent call last):
  File "/opt/hostedtoolcache/Python/3.8.17/x64/lib/python3.8/site-packages/urllib3/connection.py", line 159, in _new_conn
    conn = connection.create_connection(
  File "/opt/hostedtoolcache/Python/3.8.17/x64/lib/python3.8/site-packages/urllib3/util/connection.py", line 84, in create_connection
    raise err
  File "/opt/hostedtoolcache/Python/3.8.17/x64/lib/python3.8/site-packages/urllib3/util/connection.py", line 74, in create_connection
    sock.connect(sa)
socket.timeout: timed out

During handling of the above exception, another exception occurred:

Traceback (most recent call last):
  File "/opt/hostedtoolcache/Python/3.8.17/x64/lib/python3.8/site-packages/urllib3/connectionpool.py", line 670, in urlopen
    httplib_response = self._make_request(
  File "/opt/hostedtoolcache/Python/3.8.17/x64/lib/python3.8/site-packages/urllib3/connectionpool.py", line 392, in _make_request
    conn.request(method, url, **httplib_request_kw)
  File "/opt/hostedtoolcache/Python/3.8.17/x64/lib/python3.8/http/client.py", line 1256, in request
    self._send_request(method, url, body, headers, encode_chunked)
  File "/opt/hostedtoolcache/Python/3.8.17/x64/lib/python3.8/http/client.py", line 1302, in _send_request
    self.endheaders(body, encode_chunked=encode_chunked)
  File "/opt/hostedtoolcache/Python/3.8.17/x64/lib/python3.8/http/client.py", line 1251, in endheaders
    self._send_output(message_body, encode_chunked=encode_chunked)
  File "/opt/hostedtoolcache/Python/3.8.17/x64/lib/python3.8/http/client.py", line 1011, in _send_output
    self.send(msg)
  File "/opt/hostedtoolcache/Python/3.8.17/x64/lib/python3.8/http/client.py", line 951, in send
    self.connect()
  File "/opt/hostedtoolcache/Python/3.8.17/x64/lib/python3.8/site-packages/urllib3/connection.py", line 187, in connect
    conn = self._new_conn()
  File "/opt/hostedtoolcache/Python/3.8.17/x64/lib/python3.8/site-packages/urllib3/connection.py", line 164, in _new_conn
    raise ConnectTimeoutError(
urllib3.exceptions.ConnectTimeoutError: (<urllib3.connection.HTTPConnection object at 0x7eff4a7c17c0>, 'Connection to www.cnnvd.org.cn timed out. (connect timeout=60)')

During handling of the above exception, another exception occurred:

Traceback (most recent call last):
  File "/opt/hostedtoolcache/Python/3.8.17/x64/lib/python3.8/site-packages/requests/adapters.py", line 439, in send
    resp = conn.urlopen(
  File "/opt/hostedtoolcache/Python/3.8.17/x64/lib/python3.8/site-packages/urllib3/connectionpool.py", line 726, in urlopen
    retries = retries.increment(
  File "/opt/hostedtoolcache/Python/3.8.17/x64/lib/python3.8/site-packages/urllib3/util/retry.py", line 446, in increment
    raise MaxRetryError(_pool, url, error or ResponseError(cause))
urllib3.exceptions.MaxRetryError: HTTPConnectionPool(host='www.cnnvd.org.cn', port=80): Max retries exceeded with url: /web/vulnerability/querylist.tag (Caused by ConnectTimeoutError(<urllib3.connection.HTTPConnection object at 0x7eff4a7c17c0>, 'Connection to www.cnnvd.org.cn timed out. (connect timeout=60)'))

During handling of the above exception, another exception occurred:

Traceback (most recent call last):
  File "/home/runner/work/threat-broadcast/threat-broadcast/src/crawler/_base_crawler.py", line 62, in cves
    new_cves = self.get_cves()
  File "/home/runner/work/threat-broadcast/threat-broadcast/src/crawler/cnnvd.py", line 43, in get_cves
    response = requests.get(
  File "/opt/hostedtoolcache/Python/3.8.17/x64/lib/python3.8/site-packages/requests/api.py", line 75, in get
    return request('get', url, params=params, **kwargs)
  File "/opt/hostedtoolcache/Python/3.8.17/x64/lib/python3.8/site-packages/requests/api.py", line 60, in request
    return session.request(method=method, url=url, **kwargs)
  File "/opt/hostedtoolcache/Python/3.8.17/x64/lib/python3.8/site-packages/requests/sessions.py", line 533, in request
    resp = self.send(prep, **send_kwargs)
  File "/opt/hostedtoolcache/Python/3.8.17/x64/lib/python3.8/site-packages/requests/sessions.py", line 646, in send
    r = adapter.send(request, **kwargs)
  File "/opt/hostedtoolcache/Python/3.8.17/x64/lib/python3.8/site-packages/requests/adapters.py", line 504, in send
    raise ConnectTimeout(e, request=request)
requests.exceptions.ConnectTimeout: HTTPConnectionPool(host='www.cnnvd.org.cn', port=80): Max retries exceeded with url: /web/vulnerability/querylist.tag (Caused by ConnectTimeoutError(<urllib3.connection.HTTPConnection object at 0x7eff4a7c17c0>, 'Connection to www.cnnvd.org.cn timed out. (connect timeout=60)'))
2023-08-29 01:34:58 [INFO] : 得到 [国家信息安全漏洞库（CNNVD）] 最新威胁情报 [0] 条
2023-08-29 01:34:58 [INFO] : --------------------------------------------
2023-08-29 01:34:58 [INFO] : ++++++++++++++++++++++++++++++++++++++++++++
2023-08-29 01:34:58 [INFO] : 正在获取 [360 网络安全响应中心] 威胁情报...
2023-08-29 01:35:10 [INFO] : 得到 [360 网络安全响应中心] 最新威胁情报 [0] 条
2023-08-29 01:35:10 [INFO] : --------------------------------------------
2023-08-29 01:35:10 [INFO] : ++++++++++++++++++++++++++++++++++++++++++++
2023-08-29 01:35:10 [INFO] : 正在获取 [美国国家漏洞数据库（NVD）] 威胁情报...
2023-08-29 01:35:10 [INFO] : 得到 [美国国家漏洞数据库（NVD）] 最新威胁情报 [0] 条
2023-08-29 01:35:10 [INFO] : --------------------------------------------
2023-08-29 01:35:10 [INFO] : ++++++++++++++++++++++++++++++++++++++++++++
2023-08-29 01:35:10 [INFO] : 正在获取 [信息安全漏洞门户] 威胁情报...
2023-08-29 01:35:13 [WARNING] : 获取 [信息安全漏洞门户] 威胁情报失败： [HTTP Error 404]
2023-08-29 01:35:13 [INFO] : 得到 [信息安全漏洞门户] 最新威胁情报 [0] 条
2023-08-29 01:35:13 [INFO] : --------------------------------------------
2023-08-29 01:35:13 [INFO] : ++++++++++++++++++++++++++++++++++++++++++++
2023-08-29 01:35:13 [INFO] : 正在获取 [绿盟] 威胁情报...
2023-08-29 01:35:14 [INFO] : 得到 [绿盟] 最新威胁情报 [0] 条
2023-08-29 01:35:14 [INFO] : --------------------------------------------
2023-08-29 01:35:14 [INFO] : ++++++++++++++++++++++++++++++++++++++++++++
2023-08-29 01:35:14 [INFO] : 正在获取 [奇安信] 威胁情报...
2023-08-29 01:35:16 [INFO] : 得到 [奇安信] 最新威胁情报 [0] 条
2023-08-29 01:35:16 [INFO] : --------------------------------------------
2023-08-29 01:35:16 [INFO] : ++++++++++++++++++++++++++++++++++++++++++++
2023-08-29 01:35:16 [INFO] : 正在获取 [红后] 威胁情报...
2023-08-29 01:35:18 [INFO] : 得到 [红后] 最新威胁情报 [0] 条
2023-08-29 01:35:18 [INFO] : --------------------------------------------
2023-08-29 01:35:18 [INFO] : ++++++++++++++++++++++++++++++++++++++++++++
2023-08-29 01:35:18 [INFO] : 正在获取 [斗象] 威胁情报...
2023-08-29 01:35:20 [ERROR] : 获取 [斗象] 威胁情报异常
Traceback (most recent call last):
  File "/home/runner/work/threat-broadcast/threat-broadcast/src/crawler/_base_crawler.py", line 62, in cves
    new_cves = self.get_cves()
  File "/home/runner/work/threat-broadcast/threat-broadcast/src/crawler/vas.py", line 67, in get_cves
    for obj in json_obj.get('data').get('items'):
AttributeError: 'bool' object has no attribute 'get'
2023-08-29 01:35:20 [ERROR] : Traceback (most recent call last):
  File "/home/runner/work/threat-broadcast/threat-broadcast/src/crawler/_base_crawler.py", line 62, in cves
    new_cves = self.get_cves()
  File "/home/runner/work/threat-broadcast/threat-broadcast/src/crawler/vas.py", line 67, in get_cves
    for obj in json_obj.get('data').get('items'):
AttributeError: 'bool' object has no attribute 'get'
Traceback (most recent call last):
  File "/home/runner/work/threat-broadcast/threat-broadcast/src/crawler/_base_crawler.py", line 62, in cves
    new_cves = self.get_cves()
  File "/home/runner/work/threat-broadcast/threat-broadcast/src/crawler/vas.py", line 67, in get_cves
    for obj in json_obj.get('data').get('items'):
AttributeError: 'bool' object has no attribute 'get'
2023-08-29 01:35:20 [INFO] : 得到 [斗象] 最新威胁情报 [0] 条
2023-08-29 01:35:20 [INFO] : --------------------------------------------
2023-08-29 01:35:20 [INFO] : ++++++++++++++++++++++++++++++++++++++++++++
2023-08-29 01:35:20 [INFO] : 正在获取 [Tenable (Nessus)] 威胁情报...
2023-08-29 01:35:20 [INFO] : 得到 [Tenable (Nessus)] 最新威胁情报 [10] 条
2023-08-29 01:35:20 [INFO] : --------------------------------------------
2023-08-29 01:35:20 [INFO] : 
==============================================
[ TITLE ] Theme Volty CMS Blog up to version v4.0.1 was discovered to contain a SQL injection vulnerability via the id parameter at /tvcmsblog/single.
[ TIME  ] 2023-08-28 23:15:00
[ CVE   ] CVE-2023-39650
[ SRC   ] Tenable (Nessus)
[ URL   ] https://www.tenable.com/cve/CVE-2023-39650
2023-08-29 01:35:20 [INFO] : 
==============================================
[ TITLE ] A memory leak flaw was found in nft_set_catchall_flush in net/netfilter/nf_tables_api.c in the Linux Kernel. This issue may allow a local attacker to cause a double-deactivations of catchall elements, which results in a memory leak.
[ TIME  ] 2023-08-28 22:15:00
[ CVE   ] CVE-2023-4569
[ SRC   ] Tenable (Nessus)
[ URL   ] https://www.tenable.com/cve/CVE-2023-4569
2023-08-29 01:35:20 [INFO] : 
==============================================
[ TITLE ] An issue in Pagekit pagekit v.1.0.18 alows a remote attacker to execute arbitrary code via thedownloadAction and updateAction functions in UpdateController.php
[ TIME  ] 2023-08-28 22:15:00
[ CVE   ] CVE-2023-41005
[ SRC   ] Tenable (Nessus)
[ URL   ] https://www.tenable.com/cve/CVE-2023-41005
2023-08-29 01:35:20 [INFO] : 
==============================================
[ TITLE ] Buffer Overflow vulnerability in O-RAN Software Community ric-plt-lib-rmr v.4.9.0 allows a remote attacker to cause a denial of service via the packet size component.
[ TIME  ] 2023-08-28 22:15:00
[ CVE   ] CVE-2023-40998
[ SRC   ] Tenable (Nessus)
[ URL   ] https://www.tenable.com/cve/CVE-2023-40998
2023-08-29 01:35:20 [INFO] : 
==============================================
[ TITLE ] Buffer Overflow vulnerability in O-RAN Software Community ric-plt-lib-rmr v.4.9.0 allows a remote attacker to cause a denial of service via a crafted packet.
[ TIME  ] 2023-08-28 22:15:00
[ CVE   ] CVE-2023-40997
[ SRC   ] Tenable (Nessus)
[ URL   ] https://www.tenable.com/cve/CVE-2023-40997
2023-08-29 01:35:20 [INFO] : 
==============================================
[ TITLE ] Buffer Overflow vulnerability in VirusTotal yara v.4.3.2 allows a remote attacker to execute arbtirary code via the yr_execute_cod function in the exe.c component.
[ TIME  ] 2023-08-28 22:15:00
[ CVE   ] CVE-2023-40857
[ SRC   ] Tenable (Nessus)
[ URL   ] https://www.tenable.com/cve/CVE-2023-40857
2023-08-29 01:35:20 [INFO] : 
==============================================
[ TITLE ] An issue in pf4j pf4j v.3.9.0 and before allows a remote attacker to obtain sensitive information and execute arbitrary code via the expandIfZip method in the extract function.
[ TIME  ] 2023-08-28 22:15:00
[ CVE   ] CVE-2023-40828
[ SRC   ] Tenable (Nessus)
[ URL   ] https://www.tenable.com/cve/CVE-2023-40828
2023-08-29 01:35:20 [INFO] : 
==============================================
[ TITLE ] An issue in pf4j pf4j v.3.9.0 and before allows a remote attacker to obtain sensitive information and execute arbitrary code via the loadpluginPath parameter.
[ TIME  ] 2023-08-28 22:15:00
[ CVE   ] CVE-2023-40827
[ SRC   ] Tenable (Nessus)
[ URL   ] https://www.tenable.com/cve/CVE-2023-40827
2023-08-29 01:35:20 [INFO] : 
==============================================
[ TITLE ] An issue in pf4j pf4j v.3.9.0 and before allows a remote attacker to obtain sensitive information and execute arbitrary code via the zippluginPath parameter.
[ TIME  ] 2023-08-28 22:15:00
[ CVE   ] CVE-2023-40826
[ SRC   ] Tenable (Nessus)
[ URL   ] https://www.tenable.com/cve/CVE-2023-40826
2023-08-29 01:35:20 [INFO] : 
==============================================
[ TITLE ] An issue in Perfree PerfreeBlog v.3.1.2 allows a remote attacker to execute arbitrary code via crafted plugin listed in admin/plugin/access/list.
[ TIME  ] 2023-08-28 22:15:00
[ CVE   ] CVE-2023-40825
[ SRC   ] Tenable (Nessus)
[ URL   ] https://www.tenable.com/cve/CVE-2023-40825
2023-08-29 01:35:20 [INFO] : [邮件] 正在通过 Github Actions 推送威胁情报...
2023-08-29 02:58:48 [INFO] : ++++++++++++++++++++++++++++++++++++++++++++
2023-08-29 02:58:48 [INFO] : 正在获取 [数字观星POC++] 威胁情报...
2023-08-29 02:58:50 [INFO] : 得到 [数字观星POC++] 最新威胁情报 [0] 条
2023-08-29 02:58:50 [INFO] : --------------------------------------------
2023-08-29 02:58:50 [INFO] : ++++++++++++++++++++++++++++++++++++++++++++
2023-08-29 02:58:50 [INFO] : 正在获取 [阿里云] 威胁情报...
2023-08-29 02:58:51 [INFO] : 得到 [阿里云] 最新威胁情报 [0] 条
2023-08-29 02:58:51 [INFO] : --------------------------------------------
2023-08-29 02:58:51 [INFO] : ++++++++++++++++++++++++++++++++++++++++++++
2023-08-29 02:58:51 [INFO] : 正在获取 [国家信息安全漏洞共享平台（CNVD）] 威胁情报...
2023-08-29 02:59:14 [INFO] : 得到 [国家信息安全漏洞共享平台（CNVD）] 最新威胁情报 [0] 条
2023-08-29 02:59:14 [INFO] : --------------------------------------------
2023-08-29 02:59:14 [INFO] : ++++++++++++++++++++++++++++++++++++++++++++
2023-08-29 02:59:14 [INFO] : 正在获取 [国家信息安全漏洞库（CNNVD）] 威胁情报...
2023-08-29 03:01:15 [ERROR] : 获取 [国家信息安全漏洞库（CNNVD）] 威胁情报异常
Traceback (most recent call last):
  File "/opt/hostedtoolcache/Python/3.8.17/x64/lib/python3.8/site-packages/urllib3/connection.py", line 159, in _new_conn
    conn = connection.create_connection(
  File "/opt/hostedtoolcache/Python/3.8.17/x64/lib/python3.8/site-packages/urllib3/util/connection.py", line 84, in create_connection
    raise err
  File "/opt/hostedtoolcache/Python/3.8.17/x64/lib/python3.8/site-packages/urllib3/util/connection.py", line 74, in create_connection
    sock.connect(sa)
socket.timeout: timed out

During handling of the above exception, another exception occurred:

Traceback (most recent call last):
  File "/opt/hostedtoolcache/Python/3.8.17/x64/lib/python3.8/site-packages/urllib3/connectionpool.py", line 670, in urlopen
    httplib_response = self._make_request(
  File "/opt/hostedtoolcache/Python/3.8.17/x64/lib/python3.8/site-packages/urllib3/connectionpool.py", line 392, in _make_request
    conn.request(method, url, **httplib_request_kw)
  File "/opt/hostedtoolcache/Python/3.8.17/x64/lib/python3.8/http/client.py", line 1256, in request
    self._send_request(method, url, body, headers, encode_chunked)
  File "/opt/hostedtoolcache/Python/3.8.17/x64/lib/python3.8/http/client.py", line 1302, in _send_request
    self.endheaders(body, encode_chunked=encode_chunked)
  File "/opt/hostedtoolcache/Python/3.8.17/x64/lib/python3.8/http/client.py", line 1251, in endheaders
    self._send_output(message_body, encode_chunked=encode_chunked)
  File "/opt/hostedtoolcache/Python/3.8.17/x64/lib/python3.8/http/client.py", line 1011, in _send_output
    self.send(msg)
  File "/opt/hostedtoolcache/Python/3.8.17/x64/lib/python3.8/http/client.py", line 951, in send
    self.connect()
  File "/opt/hostedtoolcache/Python/3.8.17/x64/lib/python3.8/site-packages/urllib3/connection.py", line 187, in connect
    conn = self._new_conn()
  File "/opt/hostedtoolcache/Python/3.8.17/x64/lib/python3.8/site-packages/urllib3/connection.py", line 164, in _new_conn
    raise ConnectTimeoutError(
urllib3.exceptions.ConnectTimeoutError: (<urllib3.connection.HTTPConnection object at 0x7fe36c8918e0>, 'Connection to www.cnnvd.org.cn timed out. (connect timeout=60)')

During handling of the above exception, another exception occurred:

Traceback (most recent call last):
  File "/opt/hostedtoolcache/Python/3.8.17/x64/lib/python3.8/site-packages/requests/adapters.py", line 439, in send
    resp = conn.urlopen(
  File "/opt/hostedtoolcache/Python/3.8.17/x64/lib/python3.8/site-packages/urllib3/connectionpool.py", line 726, in urlopen
    retries = retries.increment(
  File "/opt/hostedtoolcache/Python/3.8.17/x64/lib/python3.8/site-packages/urllib3/util/retry.py", line 446, in increment
    raise MaxRetryError(_pool, url, error or ResponseError(cause))
urllib3.exceptions.MaxRetryError: HTTPConnectionPool(host='www.cnnvd.org.cn', port=80): Max retries exceeded with url: /web/vulnerability/querylist.tag (Caused by ConnectTimeoutError(<urllib3.connection.HTTPConnection object at 0x7fe36c8918e0>, 'Connection to www.cnnvd.org.cn timed out. (connect timeout=60)'))

During handling of the above exception, another exception occurred:

Traceback (most recent call last):
  File "/home/runner/work/threat-broadcast/threat-broadcast/src/crawler/_base_crawler.py", line 62, in cves
    new_cves = self.get_cves()
  File "/home/runner/work/threat-broadcast/threat-broadcast/src/crawler/cnnvd.py", line 43, in get_cves
    response = requests.get(
  File "/opt/hostedtoolcache/Python/3.8.17/x64/lib/python3.8/site-packages/requests/api.py", line 75, in get
    return request('get', url, params=params, **kwargs)
  File "/opt/hostedtoolcache/Python/3.8.17/x64/lib/python3.8/site-packages/requests/api.py", line 60, in request
    return session.request(method=method, url=url, **kwargs)
  File "/opt/hostedtoolcache/Python/3.8.17/x64/lib/python3.8/site-packages/requests/sessions.py", line 533, in request
    resp = self.send(prep, **send_kwargs)
  File "/opt/hostedtoolcache/Python/3.8.17/x64/lib/python3.8/site-packages/requests/sessions.py", line 646, in send
    r = adapter.send(request, **kwargs)
  File "/opt/hostedtoolcache/Python/3.8.17/x64/lib/python3.8/site-packages/requests/adapters.py", line 504, in send
    raise ConnectTimeout(e, request=request)
requests.exceptions.ConnectTimeout: HTTPConnectionPool(host='www.cnnvd.org.cn', port=80): Max retries exceeded with url: /web/vulnerability/querylist.tag (Caused by ConnectTimeoutError(<urllib3.connection.HTTPConnection object at 0x7fe36c8918e0>, 'Connection to www.cnnvd.org.cn timed out. (connect timeout=60)'))
2023-08-29 03:01:15 [ERROR] : Traceback (most recent call last):
  File "/opt/hostedtoolcache/Python/3.8.17/x64/lib/python3.8/site-packages/urllib3/connection.py", line 159, in _new_conn
    conn = connection.create_connection(
  File "/opt/hostedtoolcache/Python/3.8.17/x64/lib/python3.8/site-packages/urllib3/util/connection.py", line 84, in create_connection
    raise err
  File "/opt/hostedtoolcache/Python/3.8.17/x64/lib/python3.8/site-packages/urllib3/util/connection.py", line 74, in create_connection
    sock.connect(sa)
socket.timeout: timed out

During handling of the above exception, another exception occurred:

Traceback (most recent call last):
  File "/opt/hostedtoolcache/Python/3.8.17/x64/lib/python3.8/site-packages/urllib3/connectionpool.py", line 670, in urlopen
    httplib_response = self._make_request(
  File "/opt/hostedtoolcache/Python/3.8.17/x64/lib/python3.8/site-packages/urllib3/connectionpool.py", line 392, in _make_request
    conn.request(method, url, **httplib_request_kw)
  File "/opt/hostedtoolcache/Python/3.8.17/x64/lib/python3.8/http/client.py", line 1256, in request
    self._send_request(method, url, body, headers, encode_chunked)
  File "/opt/hostedtoolcache/Python/3.8.17/x64/lib/python3.8/http/client.py", line 1302, in _send_request
    self.endheaders(body, encode_chunked=encode_chunked)
  File "/opt/hostedtoolcache/Python/3.8.17/x64/lib/python3.8/http/client.py", line 1251, in endheaders
    self._send_output(message_body, encode_chunked=encode_chunked)
  File "/opt/hostedtoolcache/Python/3.8.17/x64/lib/python3.8/http/client.py", line 1011, in _send_output
    self.send(msg)
  File "/opt/hostedtoolcache/Python/3.8.17/x64/lib/python3.8/http/client.py", line 951, in send
    self.connect()
  File "/opt/hostedtoolcache/Python/3.8.17/x64/lib/python3.8/site-packages/urllib3/connection.py", line 187, in connect
    conn = self._new_conn()
  File "/opt/hostedtoolcache/Python/3.8.17/x64/lib/python3.8/site-packages/urllib3/connection.py", line 164, in _new_conn
    raise ConnectTimeoutError(
urllib3.exceptions.ConnectTimeoutError: (<urllib3.connection.HTTPConnection object at 0x7fe36c8918e0>, 'Connection to www.cnnvd.org.cn timed out. (connect timeout=60)')

During handling of the above exception, another exception occurred:

Traceback (most recent call last):
  File "/opt/hostedtoolcache/Python/3.8.17/x64/lib/python3.8/site-packages/requests/adapters.py", line 439, in send
    resp = conn.urlopen(
  File "/opt/hostedtoolcache/Python/3.8.17/x64/lib/python3.8/site-packages/urllib3/connectionpool.py", line 726, in urlopen
    retries = retries.increment(
  File "/opt/hostedtoolcache/Python/3.8.17/x64/lib/python3.8/site-packages/urllib3/util/retry.py", line 446, in increment
    raise MaxRetryError(_pool, url, error or ResponseError(cause))
urllib3.exceptions.MaxRetryError: HTTPConnectionPool(host='www.cnnvd.org.cn', port=80): Max retries exceeded with url: /web/vulnerability/querylist.tag (Caused by ConnectTimeoutError(<urllib3.connection.HTTPConnection object at 0x7fe36c8918e0>, 'Connection to www.cnnvd.org.cn timed out. (connect timeout=60)'))

During handling of the above exception, another exception occurred:

Traceback (most recent call last):
  File "/home/runner/work/threat-broadcast/threat-broadcast/src/crawler/_base_crawler.py", line 62, in cves
    new_cves = self.get_cves()
  File "/home/runner/work/threat-broadcast/threat-broadcast/src/crawler/cnnvd.py", line 43, in get_cves
    response = requests.get(
  File "/opt/hostedtoolcache/Python/3.8.17/x64/lib/python3.8/site-packages/requests/api.py", line 75, in get
    return request('get', url, params=params, **kwargs)
  File "/opt/hostedtoolcache/Python/3.8.17/x64/lib/python3.8/site-packages/requests/api.py", line 60, in request
    return session.request(method=method, url=url, **kwargs)
  File "/opt/hostedtoolcache/Python/3.8.17/x64/lib/python3.8/site-packages/requests/sessions.py", line 533, in request
    resp = self.send(prep, **send_kwargs)
  File "/opt/hostedtoolcache/Python/3.8.17/x64/lib/python3.8/site-packages/requests/sessions.py", line 646, in send
    r = adapter.send(request, **kwargs)
  File "/opt/hostedtoolcache/Python/3.8.17/x64/lib/python3.8/site-packages/requests/adapters.py", line 504, in send
    raise ConnectTimeout(e, request=request)
requests.exceptions.ConnectTimeout: HTTPConnectionPool(host='www.cnnvd.org.cn', port=80): Max retries exceeded with url: /web/vulnerability/querylist.tag (Caused by ConnectTimeoutError(<urllib3.connection.HTTPConnection object at 0x7fe36c8918e0>, 'Connection to www.cnnvd.org.cn timed out. (connect timeout=60)'))
Traceback (most recent call last):
  File "/opt/hostedtoolcache/Python/3.8.17/x64/lib/python3.8/site-packages/urllib3/connection.py", line 159, in _new_conn
    conn = connection.create_connection(
  File "/opt/hostedtoolcache/Python/3.8.17/x64/lib/python3.8/site-packages/urllib3/util/connection.py", line 84, in create_connection
    raise err
  File "/opt/hostedtoolcache/Python/3.8.17/x64/lib/python3.8/site-packages/urllib3/util/connection.py", line 74, in create_connection
    sock.connect(sa)
socket.timeout: timed out

During handling of the above exception, another exception occurred:

Traceback (most recent call last):
  File "/opt/hostedtoolcache/Python/3.8.17/x64/lib/python3.8/site-packages/urllib3/connectionpool.py", line 670, in urlopen
    httplib_response = self._make_request(
  File "/opt/hostedtoolcache/Python/3.8.17/x64/lib/python3.8/site-packages/urllib3/connectionpool.py", line 392, in _make_request
    conn.request(method, url, **httplib_request_kw)
  File "/opt/hostedtoolcache/Python/3.8.17/x64/lib/python3.8/http/client.py", line 1256, in request
    self._send_request(method, url, body, headers, encode_chunked)
  File "/opt/hostedtoolcache/Python/3.8.17/x64/lib/python3.8/http/client.py", line 1302, in _send_request
    self.endheaders(body, encode_chunked=encode_chunked)
  File "/opt/hostedtoolcache/Python/3.8.17/x64/lib/python3.8/http/client.py", line 1251, in endheaders
    self._send_output(message_body, encode_chunked=encode_chunked)
  File "/opt/hostedtoolcache/Python/3.8.17/x64/lib/python3.8/http/client.py", line 1011, in _send_output
    self.send(msg)
  File "/opt/hostedtoolcache/Python/3.8.17/x64/lib/python3.8/http/client.py", line 951, in send
    self.connect()
  File "/opt/hostedtoolcache/Python/3.8.17/x64/lib/python3.8/site-packages/urllib3/connection.py", line 187, in connect
    conn = self._new_conn()
  File "/opt/hostedtoolcache/Python/3.8.17/x64/lib/python3.8/site-packages/urllib3/connection.py", line 164, in _new_conn
    raise ConnectTimeoutError(
urllib3.exceptions.ConnectTimeoutError: (<urllib3.connection.HTTPConnection object at 0x7fe36c8918e0>, 'Connection to www.cnnvd.org.cn timed out. (connect timeout=60)')

During handling of the above exception, another exception occurred:

Traceback (most recent call last):
  File "/opt/hostedtoolcache/Python/3.8.17/x64/lib/python3.8/site-packages/requests/adapters.py", line 439, in send
    resp = conn.urlopen(
  File "/opt/hostedtoolcache/Python/3.8.17/x64/lib/python3.8/site-packages/urllib3/connectionpool.py", line 726, in urlopen
    retries = retries.increment(
  File "/opt/hostedtoolcache/Python/3.8.17/x64/lib/python3.8/site-packages/urllib3/util/retry.py", line 446, in increment
    raise MaxRetryError(_pool, url, error or ResponseError(cause))
urllib3.exceptions.MaxRetryError: HTTPConnectionPool(host='www.cnnvd.org.cn', port=80): Max retries exceeded with url: /web/vulnerability/querylist.tag (Caused by ConnectTimeoutError(<urllib3.connection.HTTPConnection object at 0x7fe36c8918e0>, 'Connection to www.cnnvd.org.cn timed out. (connect timeout=60)'))

During handling of the above exception, another exception occurred:

Traceback (most recent call last):
  File "/home/runner/work/threat-broadcast/threat-broadcast/src/crawler/_base_crawler.py", line 62, in cves
    new_cves = self.get_cves()
  File "/home/runner/work/threat-broadcast/threat-broadcast/src/crawler/cnnvd.py", line 43, in get_cves
    response = requests.get(
  File "/opt/hostedtoolcache/Python/3.8.17/x64/lib/python3.8/site-packages/requests/api.py", line 75, in get
    return request('get', url, params=params, **kwargs)
  File "/opt/hostedtoolcache/Python/3.8.17/x64/lib/python3.8/site-packages/requests/api.py", line 60, in request
    return session.request(method=method, url=url, **kwargs)
  File "/opt/hostedtoolcache/Python/3.8.17/x64/lib/python3.8/site-packages/requests/sessions.py", line 533, in request
    resp = self.send(prep, **send_kwargs)
  File "/opt/hostedtoolcache/Python/3.8.17/x64/lib/python3.8/site-packages/requests/sessions.py", line 646, in send
    r = adapter.send(request, **kwargs)
  File "/opt/hostedtoolcache/Python/3.8.17/x64/lib/python3.8/site-packages/requests/adapters.py", line 504, in send
    raise ConnectTimeout(e, request=request)
requests.exceptions.ConnectTimeout: HTTPConnectionPool(host='www.cnnvd.org.cn', port=80): Max retries exceeded with url: /web/vulnerability/querylist.tag (Caused by ConnectTimeoutError(<urllib3.connection.HTTPConnection object at 0x7fe36c8918e0>, 'Connection to www.cnnvd.org.cn timed out. (connect timeout=60)'))
2023-08-29 03:01:15 [INFO] : 得到 [国家信息安全漏洞库（CNNVD）] 最新威胁情报 [0] 条
2023-08-29 03:01:15 [INFO] : --------------------------------------------
2023-08-29 03:01:15 [INFO] : ++++++++++++++++++++++++++++++++++++++++++++
2023-08-29 03:01:15 [INFO] : 正在获取 [360 网络安全响应中心] 威胁情报...
2023-08-29 03:01:22 [INFO] : 得到 [360 网络安全响应中心] 最新威胁情报 [0] 条
2023-08-29 03:01:22 [INFO] : --------------------------------------------
2023-08-29 03:01:22 [INFO] : ++++++++++++++++++++++++++++++++++++++++++++
2023-08-29 03:01:22 [INFO] : 正在获取 [美国国家漏洞数据库（NVD）] 威胁情报...
2023-08-29 03:01:22 [INFO] : 得到 [美国国家漏洞数据库（NVD）] 最新威胁情报 [0] 条
2023-08-29 03:01:22 [INFO] : --------------------------------------------
2023-08-29 03:01:22 [INFO] : ++++++++++++++++++++++++++++++++++++++++++++
2023-08-29 03:01:22 [INFO] : 正在获取 [信息安全漏洞门户] 威胁情报...
2023-08-29 03:01:24 [WARNING] : 获取 [信息安全漏洞门户] 威胁情报失败： [HTTP Error 404]
2023-08-29 03:01:24 [INFO] : 得到 [信息安全漏洞门户] 最新威胁情报 [0] 条
2023-08-29 03:01:24 [INFO] : --------------------------------------------
2023-08-29 03:01:24 [INFO] : ++++++++++++++++++++++++++++++++++++++++++++
2023-08-29 03:01:24 [INFO] : 正在获取 [绿盟] 威胁情报...
2023-08-29 03:01:25 [INFO] : 得到 [绿盟] 最新威胁情报 [0] 条
2023-08-29 03:01:25 [INFO] : --------------------------------------------
2023-08-29 03:01:25 [INFO] : ++++++++++++++++++++++++++++++++++++++++++++
2023-08-29 03:01:25 [INFO] : 正在获取 [奇安信] 威胁情报...
2023-08-29 03:01:31 [INFO] : 得到 [奇安信] 最新威胁情报 [0] 条
2023-08-29 03:01:31 [INFO] : --------------------------------------------
2023-08-29 03:01:31 [INFO] : ++++++++++++++++++++++++++++++++++++++++++++
2023-08-29 03:01:31 [INFO] : 正在获取 [红后] 威胁情报...
2023-08-29 03:01:33 [INFO] : 得到 [红后] 最新威胁情报 [0] 条
2023-08-29 03:01:33 [INFO] : --------------------------------------------
2023-08-29 03:01:33 [INFO] : ++++++++++++++++++++++++++++++++++++++++++++
2023-08-29 03:01:33 [INFO] : 正在获取 [斗象] 威胁情报...
2023-08-29 03:01:37 [ERROR] : 获取 [斗象] 威胁情报异常
Traceback (most recent call last):
  File "/home/runner/work/threat-broadcast/threat-broadcast/src/crawler/_base_crawler.py", line 62, in cves
    new_cves = self.get_cves()
  File "/home/runner/work/threat-broadcast/threat-broadcast/src/crawler/vas.py", line 67, in get_cves
    for obj in json_obj.get('data').get('items'):
AttributeError: 'bool' object has no attribute 'get'
2023-08-29 03:01:37 [ERROR] : Traceback (most recent call last):
  File "/home/runner/work/threat-broadcast/threat-broadcast/src/crawler/_base_crawler.py", line 62, in cves
    new_cves = self.get_cves()
  File "/home/runner/work/threat-broadcast/threat-broadcast/src/crawler/vas.py", line 67, in get_cves
    for obj in json_obj.get('data').get('items'):
AttributeError: 'bool' object has no attribute 'get'
Traceback (most recent call last):
  File "/home/runner/work/threat-broadcast/threat-broadcast/src/crawler/_base_crawler.py", line 62, in cves
    new_cves = self.get_cves()
  File "/home/runner/work/threat-broadcast/threat-broadcast/src/crawler/vas.py", line 67, in get_cves
    for obj in json_obj.get('data').get('items'):
AttributeError: 'bool' object has no attribute 'get'
2023-08-29 03:01:37 [INFO] : 得到 [斗象] 最新威胁情报 [0] 条
2023-08-29 03:01:37 [INFO] : --------------------------------------------
2023-08-29 03:01:37 [INFO] : ++++++++++++++++++++++++++++++++++++++++++++
2023-08-29 03:01:37 [INFO] : 正在获取 [Tenable (Nessus)] 威胁情报...
2023-08-29 03:01:38 [INFO] : 得到 [Tenable (Nessus)] 最新威胁情报 [0] 条
2023-08-29 03:01:38 [INFO] : --------------------------------------------
